File: cal_and_test_data/calibration/Pd_std.rw.dat
[Header]
; DC Raw Data File (default extension .raw)
; Copyright 2012, Quantum Design, Inc. All rights reserved.
TITLE,Pd_std
FILEOPENTIME,3751797142.68777,11/19/2018,12:53 pm
BYAPP,SQUID AC,0.9.1.0
INFO,MPMS3 Option Release 1.1.16 Build 399, Release 2.3.4.15,APPNAME
INFO,TCI166,COIL_SERIAL_NUMBER
INFO,0,MOMENT_UNITS
INFO,Pd_std,SAMPLE_MATERIAL
INFO,,SAMPLE_COMMENT
INFO,260.4,SAMPLE_MASS
INFO,,SAMPLE_VOLUME
INFO,,SAMPLE_MOLECULAR_WEIGHT
INFO,,SAMPLE_SIZE
INFO,,SAMPLE_SHAPE
INFO,Quartz,SAMPLE_HOLDER
INFO,Standard,SAMPLE_HOLDER_DETAIL
INFO,66.53,SAMPLE_OFFSET
DATATYPE,COMMENT,1
DATATYPE,TIME,2
STARTUPAXIS,X,3
STARTUPAXIS,Y1,4
STARTUPAXIS,Y2,5
STARTUPAXIS,Y2,6
STARTUPAXIS,Y2,7
STARTUPAXIS,Y3,8
STARTUPAXIS,Y3,9
RECORDS,FROM_TO_RECORDS,1,604
[Data]
Comment,Time Stamp (sec),Raw Position (mm),Raw Voltage (V),Processed Voltage (V),Fixed C Fitted (V),Free C Fitted (V)
;low temp = 299.994964599609 K;high temp = 300.013000488281 K;avg. temp = 300.005639648438 K;low field = 49.9507675170898 Oe;high field = 49.9507675170898 Oe;drift = 0.00163246728334343 V/s;slope = 0.000186567689524963 V/mm;squid range = 1;given center = 31.6996879577637 mm;calculated center = 31.6996879577637 mm;amp fixed = -3.42022085189819 V;amp free =-3.4202082157135 V
,3751797133.29984,14.2768173217773,-0.0727851912379265,0.0449415445327759
,3751797133.31984,14.4515151977539,-0.0715460404753685,0.0461481027305126
,3751797133.33984,14.6254539489746,-0.0699691772460937,0.0476925112307072
,3751797133.35984,14.8001518249512,-0.0685872882604599,0.0490418076515198
,3751797133.37984,14.9745454788208,-0.06706852465868,0.0505280345678329
,3751797133.39984,15.1484851837158,-0.0657857954502106,0.0517783127725124
,3751797133.41984,15.3227272033691,-0.0642204135656357,0.053311187773943
,3751797133.43984,15.4974241256714,-0.0626555606722832,0.0548434481024742
,3751797133.45984,15.6715145111084,-0.0612335726618767,0.0562329553067684
,3751797133.47984,15.846212387085,-0.059521060436964,0.0579128749668598
,3751797133.49984,16.0196971893311,-0.0578563921153545,0.0595451779663563
,3751797133.51984,16.1937885284424,-0.0561856180429459,0.0611834712326527
,3751797133.53984,16.3669700622559,-0.054444819688797,0.062891960144043
,3751797133.55984,16.5396976470947,-0.0525330081582069,0.0647715479135513
,3751797133.57984,16.7137870788574,-0.05064906924963,0.0666230022907257
,3751797133.59984,16.8874244689941,-0.0487529002130032,0.0684867799282074
,3751797133.61984,17.0598487854004,-0.0470309406518936,0.0701765716075897
,3751797133.63984,17.2330303192139,-0.0450051240622997,0.072170078754425
,3751797133.65984,17.40651512146,-0.0431923270225525,0.0739505067467689
,3751797133.67984,17.5796966552734,-0.0413172394037247,0.0757932811975479
,3751797133.69984,17.7530288696289,-0.0397570617496967,0.0773211270570755
,3751797133.71984,17.926061630249,-0.0377042405307293,0.0793416649103165
,3751797133.73984,18.0996971130371,-0.0357129015028477,0.0813006088137627
,3751797133.75984,18.2731819152832,-0.0338197872042656,0.0831613540649414
,3751797133.77984,18.4463634490967,-0.0318209528923035,0.0851278826594353
,3751797133.79984,18.6200008392334,-0.0298271253705025,0.0870893150568008
,3751797133.81984,18.7933330535889,-0.0277225915342569,0.0891615077853203
,3751797133.83984,18.9665145874023,-0.0259093642234802,0.0909424275159836
,3751797133.85984,19.1406059265137,-0.0241496898233891,0.0926696211099625
,3751797133.87984,19.3136367797852,-0.0222790259867907,0.0945079997181892
,3751797133.89984,19.4862117767334,-0.020485071465373,0.0962697565555572
,3751797133.91984,19.6603031158447,-0.0189908910542727,0.0977314561605453
,3751797133.93984,19.8333339691162,-0.0173287522047758,0.099361315369606
,3751797133.95984,20.0071220397949,-0.0159862209111452,0.100671425461769
,3751797133.97984,20.1798477172852,-0.0146865323185921,0.101938888430595
,3751797133.99984,20.3537883758545,-0.0134673630818725,0.103125602006912
,3751797134.01984,20.5271224975586,-0.0123829199001193,0.104177713394165
,3751797134.03984,20.6998481750488,-0.0114178666844964,0.105110540986061
,3751797134.05984,20.8730297088623,-0.0106968674808741,0.105799227952957
,3751797134.07984,21.0468196868896,-0.0102178622037172,0.106245808303356
,3751797134.09984,21.2187881469727,-0.00995030999183655,0.106481276452541
,3751797134.11984,21.3918190002441,-0.0100245447829366,0.106374762952328
,3751797134.13984,21.5653018951416,-0.0102321496233344,0.106134787201881
,3751797134.15984,21.7381820678711,-0.0109124556183815,0.105422228574753
,3751797134.17984,21.9107570648193,-0.0117153115570545,0.10458717495203
,3751797134.19984,22.084545135498,-0.0126884030178189,0.103581659495831
,3751797134.21984,22.2566680908203,-0.014026490971446,0.102211460471153
,3751797134.23984,22.4293937683105,-0.0158199965953827,0.10038573294878
,3751797134.25984,22.6027278900146,-0.0178155768662691,0.0983578115701675
,3751797134.27984,22.7753028869629,-0.0199277494102716,0.0962134450674057
,3751797134.29984,22.9487895965576,-0.0226709712296724,0.0934378504753113
,3751797134.31984,23.1218185424805,-0.0256517101079226,0.0904248356819153
,3751797134.33984,23.2957572937012,-0.0291371569037437,0.0869069322943687
,3751797134.35984,23.4693946838379,-0.0329812057316303,0.083030492067337
,3751797134.37984,23.643030166626,-0.0372421070933342,0.0787371918559074
,3751797134.39984,23.8163642883301,-0.0421455278992653,0.0738014355301857
,3751797134.41984,23.9901504516602,-0.0473370924592018,0.0685774460434914
,3751797134.43984,24.1639404296875,-0.0527298115193844,0.0631523057818413
,3751797134.45984,24.337121963501,-0.0585135631263256,0.0573362447321415
,3751797134.47984,24.5118179321289,-0.064490981400013,0.0513262338936329
,3751797134.49984,24.6849994659424,-0.0709394440054893,0.044845461845398
,3751797134.51984,24.8590927124023,-0.0776708200573921,0.0380816049873829
,3751797134.53984,25.033483505249,-0.0848549380898476,0.0308649502694607
,3751797134.55984,25.2071208953857,-0.0925187543034553,0.0231687389314175
,3751797134.57984,25.3810596466064,-0.100348077714443,0.0153069635853171
,3751797134.59984,25.5550003051758,-0.108540892601013,0.00708169722929597
,3751797134.61984,25.7284832000732,-0.117085859179497,-0.0014956354862079
,3751797134.63984,25.9016666412354,-0.12585636973381,-0.0102984560653567
,3751797134.65984,26.0753021240234,-0.134845495223999,-0.0193199757486582
,3751797134.67984,26.2487888336182,-0.143962025642395,-0.0284688733518124
,3751797134.69984,26.4218196868896,-0.153240323066711,-0.0377794541418552
,3751797134.71984,26.5956058502197,-0.162894666194916,-0.0474662184715271
,3751797134.73984,26.7686347961426,-0.172517657279968,-0.0571214929223061
,3751797134.75984,26.9424247741699,-0.182064443826675,-0.066700704395771
,3751797134.77984,27.1153030395508,-0.191913366317749,-0.0765818804502487
,3751797134.79984,27.287878036499,-0.201711803674698,-0.0864125117659569
,3751797134.81984,27.4618186950684,-0.211635366082191,-0.0963685289025307
,3751797134.83984,27.6350002288818,-0.221690893173218,-0.106456361711025
,3751797134.85984,27.8086357116699,-0.231499016284943,-0.116296879947186
,3751797134.87984,27.9822731018066,-0.241290047764778,-0.126120314002037
,3751797134.89984,28.1553020477295,-0.25080132484436,-0.135663866996765
,3751797134.91984,28.3289413452148,-0.260447114706039,-0.14534205198288
,3751797134.93984,28.5016670227051,-0.269798576831818,-0.15472574532032
,3751797134.95984,28.6737899780273,-0.278704404830933,-0.163663685321808
,3751797134.97984,28.8469696044922,-0.28721022605896,-0.172201812267303
,3751797134.99984,29.0201511383057,-0.295198082923889,-0.180221974849701
,3751797135.01984,29.1925754547119,-0.302905678749084,-0.187961742281914
,3751797135.03984,29.3662109375,-0.310195356607437,-0.195283815264702
,3751797135.05984,29.5389404296875,-0.316559016704559,-0.201679706573486
,3751797135.07984,29.7116680145264,-0.322685539722443,-0.207838445901871
,3751797135.09984,29.8846969604492,-0.328597575426102,-0.213782772421837
,3751797135.11984,30.0580291748047,-0.333986759185791,-0.219204291701317
,3751797135.13984,30.231969833374,-0.338976502418518,-0.224226489663124
,3751797135.15984,30.4050006866455,-0.343385636806488,-0.22866789996624
,3751797135.17984,30.5786361694336,-0.347257226705551,-0.232571884989738
,3751797135.19984,30.7521209716797,-0.35082483291626,-0.23617185652256
,3751797135.21984,30.9249992370605,-0.353487491607666,-0.238866776227951
,3751797135.23984,31.0983333587646,-0.355799823999405,-0.241211444139481
,3751797135.25984,31.272575378418,-0.357517808675766,-0.242961928248405
,3751797135.27984,31.4449996948242,-0.358764171600342,-0.244240462779999
,3751797135.29984,31.6192436218262,-0.359298557043076,-0.244807362556458
,3751797135.31984,31.7924251556396,-0.359234005212784,-0.244775116443634
,3751797135.33984,31.9668197631836,-0.358579576015472,-0.24415323138237
,3751797135.35984,32.1398468017578,-0.357342451810837,-0.24294838309288
,3751797135.37984,32.3128776550293,-0.355341106653214,-0.240979313850403
,3751797135.39984,32.4869689941406,-0.352762788534164,-0.238433480262756
,3751797135.41984,32.6604537963867,-0.349549978971481,-0.235253036022186
,3751797135.43984,32.834545135498,-0.345727622509003,-0.23146316409111
,3751797135.45984,33.0078773498535,-0.341108202934265,-0.226876080036163
,3751797135.47984,33.1815147399902,-0.336269676685333,-0.222069948911667
,3751797135.49984,33.3557586669922,-0.330609709024429,-0.216442495584488
,3751797135.51984,33.5292434692383,-0.324585109949112,-0.210450261831284
,3751797135.53984,33.7027282714844,-0.318103134632111,-0.204000651836395
,3751797135.55984,33.8757553100586,-0.3112653195858,-0.197195112705231
,3751797135.57984,34.0489387512207,-0.303907871246338,-0.189869970083237
,3751797135.59984,34.2224235534668,-0.296095043420792,-0.182089507579803
,3751797135.61984,34.3960609436035,-0.287841379642487,-0.173868238925934
,3751797135.63984,34.5689392089844,-0.279638200998306,-0.165697321295738
,3751797135.65984,34.7422714233398,-0.27084669470787,-0.156938150525093
,3751797135.67984,34.9159088134766,-0.26183557510376,-0.147959426045418
,3751797135.69984,35.0900001525879,-0.252241790294647,-0.138398125767708
,3751797135.71984,35.2636337280273,-0.242727488279343,-0.128916218876839
,3751797135.73984,35.4365158081055,-0.233098268508911,-0.119319252669811
,3751797135.75984,35.609546661377,-0.223504811525345,-0.109758071601391
,3751797135.77984,35.783031463623,-0.213552221655846,-0.0998378545045853
,3751797135.79984,35.9568176269531,-0.203637897968292,-0.0899559482932091
,3751797135.81984,36.1307563781738,-0.193863198161125,-0.0802137032151222
,3751797135.83984,36.3046989440918,-0.184047073125839,-0.0704300329089165
,3751797135.85984,36.4775772094727,-0.174216091632843,-0.060631301254034
,3751797135.87984,36.6515159606934,-0.164446666836739,-0.0508943274617195
,3751797135.89984,36.8243942260742,-0.154649302363396,-0.0411292165517807
,3751797135.91984,36.9978790283203,-0.145129024982452,-0.0316413082182407
,3751797135.93984,37.171516418457,-0.135746702551842,-0.0222913790494204
,3751797135.95984,37.3446960449219,-0.126818552613258,-0.0133955385535955
,3751797135.97984,37.5180282592773,-0.117931865155697,-0.00454118940979242
,3751797135.99984,37.6915168762207,-0.109119385480881,0.00423892261460423
,3751797136.01984,37.8651504516602,-0.100689828395844,0.0126360850408673
,3751797136.03984,38.0381813049316,-0.0923866480588913,0.0209069829434156
,3751797136.05984,38.2118186950684,-0.0845170095562935,0.028744226321578
,3751797136.07984,38.3849983215332,-0.077124647796154,0.0361042805016041
,3751797136.09984,38.5581817626953,-0.069747306406498,0.0434493087232113
,3751797136.11984,38.7316665649414,-0.0629928857088089,0.0501713640987873
,3751797136.13984,38.9057579040527,-0.0566802099347115,0.0564515590667725
,3751797136.15984,39.0783309936523,-0.050830464810133,0.0622691102325916
,3751797136.17984,39.2522735595703,-0.0449705868959427,0.0680965334177017
,3751797136.19984,39.4253044128418,-0.0395706407725811,0.0734641999006271
,3751797136.21984,39.5986366271973,-0.0345338322222233,0.0784686654806137
,3751797136.23984,39.7718200683594,-0.0299720373004675,0.0829981565475464
,3751797136.25984,39.9454536437988,-0.0257463175803423,0.0871914774179459
,3751797136.27984,40.1187896728516,-0.0218506138771772,0.09105484187603
,3751797136.29984,40.2922744750977,-0.0185075700283051,0.0943655222654343
,3751797136.31984,40.4654541015625,-0.0153138255700469,0.097526952624321
,3751797136.33984,40.6387901306152,-0.0126527845859528,0.100155659019947
,3751797136.35984,40.8122711181641,-0.0103122005239129,0.102463878691196
,3751797136.37984,40.9860610961914,-0.00802336446940899,0.104720287024975
,3751797136.39984,41.1593933105469,-0.00635699834674597,0.10635431855917
,3751797136.41984,41.3324203491211,-0.00496620545163751,0.10771282762289
,3751797136.43984,41.5059089660645,-0.00395177025347948,0.108694896101952
,3751797136.45984,41.6792449951172,-0.00314205000177026,0.109472274780273
,3751797136.47984,41.8525772094727,-0.00259605352766812,0.109985932707787
,3751797136.49984,42.0265121459961,-0.00232766987755895,0.110221870243549
,3751797136.51984,42.1995468139648,-0.00228419480845332,0.110233061015606
,3751797136.53984,42.3728790283203,-0.00240457803010941,0.11008033901453
,3751797136.55984,42.5460586547852,-0.00286458129994571,0.109588027000427
,3751797136.57984,42.7196960449219,-0.00354132894426584,0.108878880739212
,3751797136.59984,42.8934860229492,-0.0043809600174427,0.108006827533245
,3751797136.61984,43.0674209594727,-0.00512218894436955,0.10723315179348
,3751797136.63984,43.2404556274414,-0.00634917756542563,0.10597387701273
,3751797136.65984,43.4133338928223,-0.00765592837706208,0.104634873569012
,3751797136.67984,43.5866661071777,-0.00906902831047773,0.103189438581467
,3751797136.69984,43.7596969604492,-0.0105090942233801,0.101717084646225
,3751797136.71984,43.933032989502,-0.0122246602550149,0.0999691858887672
,3751797136.73984,44.1068153381348,-0.014107751660049,0.0980536714196205
,3751797136.75984,44.2798500061035,-0.0158095732331276,0.0963195636868477
,3751797136.77984,44.4537887573242,-0.0176163539290428,0.0944803357124329
,3751797136.79984,44.6269683837891,-0.0194007903337479,0.092663586139679
,3751797136.81984,44.8004531860352,-0.0213561467826366,0.0906758606433868
,3751797136.83984,44.9739418029785,-0.0231219623237848,0.0888776779174805
,3751797136.85984,45.1468162536621,-0.0249920133501291,0.0869753733277321
,3751797136.87984,45.3203010559082,-0.0270301662385464,0.084904856979847
,3751797136.89984,45.4936370849609,-0.0289204474538565,0.0829822346568108
,3751797136.91984,45.667423248291,-0.0306827947497368,0.0811874642968178
,3751797136.93984,45.8416633605957,-0.0327679477632046,0.0790698081254959
,3751797136.95984,46.0140914916992,-0.0346558056771755,0.0771497786045074
,3751797136.97984,46.1880340576172,-0.036486029624939,0.0752871036529541
,3751797136.99984,46.3610610961914,-0.0383404195308685,0.0734004303812981
,3751797137.01984,46.5353012084961,-0.0401394329965115,0.071568913757801
,3751797137.03984,46.7078819274902,-0.0419883318245411,0.0696878135204315
,3751797137.05984,46.8815155029297,-0.0438234694302082,0.067820280790329
,3751797137.07984,47.0546989440918,-0.0453670844435692,0.0662443563342094
,3751797137.09984,47.2280311584473,-0.0471023768186569,0.0644767284393311
,3751797137.11984,47.4021186828613,-0.0487257167696953,0.0628209039568901
,3751797137.13984,47.575756072998,-0.0504232943058014,0.0610909350216389
,3751797137.15984,47.7493934631348,-0.0520335584878922,0.0594482757151127
,3751797137.17984,47.9230308532715,-0.0534713491797447,0.0579780898988247
,3751797137.19984,48.0966644287109,-0.0552566535770893,0.0561603903770447
,3751797137.21984,48.269847869873,-0.0567210651934147,0.0546636693179607
,3751797137.23984,48.443790435791,-0.0580721087753773,0.053280171006918
,3751797137.25984,48.6171188354492,-0.0594248995184898,0.0518950447440147
,3751797137.27984,48.7903022766113,-0.0608567595481873,0.0504308752715588
,3751797137.29984,48.9637908935547,-0.0621838495135307,0.0490714162588119
;low temp = 299.994964599609 K;high temp = 300.013000488281 K;avg. temp = 300.005639648438 K;low field = 49.9507675170898 Oe;high field = 49.9507675170898 Oe;drift = 0.00163246728334343 V/s;slope = -0.000186567689524963 V/mm;squid range = 1;given center = 31.6996879577637 mm;calculated center = 31.6996879577637 mm;amp fixed = -3.42022085189819 V;amp free =-3.4202082157135 V
,3751797138.08114,49.0983352661133,-0.0620305016636849,0.0498242415487766
,3751797138.10114,48.9231834411621,-0.0607875101268291,0.0510345548391342
,3751797138.12114,48.7475776672363,-0.059457790106535,0.0523315109312534
,3751797138.14114,48.5721206665039,-0.0580592826008797,0.0536972843110561
,3751797138.16114,48.3968162536621,-0.0566778630018234,0.0550459995865822
,3751797138.18114,48.2216644287109,-0.0552861653268337,0.0564050190150738
,3751797138.20114,48.0469665527344,-0.0541189275681972,0.057539664208889
,3751797138.22114,47.8731842041016,-0.0526002533733845,0.059025913476944
,3751797138.24114,47.6992416381836,-0.050986610352993,0.0606071054935455
,3751797138.26114,47.5256042480469,-0.0493750832974911,0.062186237424612
,3751797138.28114,47.3525772094727,-0.0476830154657364,0.0638460218906403
,3751797138.30114,47.178638458252,-0.0459391809999943,0.0655574053525925
,3751797138.32114,47.0059089660645,-0.0441384166479111,0.0673259496688843
,3751797138.34114,46.8331832885742,-0.042255163192749,0.069176971912384
,3751797138.36114,46.6589393615723,-0.0405820049345493,0.0708176270127296
,3751797138.38114,46.486515045166,-0.0387367568910122,0.0726307034492493
,3751797138.40114,46.3136367797852,-0.0368038304150105,0.0745313763618469
,3751797138.42114,46.1398468017578,-0.0348830074071884,0.0764197781682014
,3751797138.44114,45.9666633605957,-0.0328516997396946,0.0784187763929367
,3751797138.46114,45.7936363220215,-0.0309088043868542,0.0803293883800507
,3751797138.48114,45.62060546875,-0.0289210621267557,0.0822848454117775
,3751797138.50114,45.4477310180664,-0.0270256865769625,0.0841479673981667
,3751797138.52114,45.2745475769043,-0.0252302326261997,0.0859111174941063
,3751797138.54114,45.1012115478516,-0.0230183396488428,0.0880906656384468
,3751797138.56114,44.9280319213867,-0.0211098901927471,0.0899668112397194
,3751797138.58114,44.7556037902832,-0.0191954243928194,0.0918491035699844
,3751797138.60114,44.5821189880371,-0.0172391645610332,0.0937729999423027
,3751797138.62114,44.4093933105469,-0.0154027631506324,0.095577172935009
,3751797138.64114,44.2363624572754,-0.0136580979451537,0.0972895547747612
,3751797138.66114,44.0639419555664,-0.0120058758184314,0.0989096090197563
,3751797138.68114,43.8909072875977,-0.0103069804608822,0.100576221942902
,3751797138.70114,43.7175788879395,-0.00870153866708279,0.102149330079556
,3751797138.72114,43.5443954467773,-0.00719050643965602,0.103628046810627
,3751797138.74114,43.3713607788086,-0.00572625501081347,0.105060018599033
,3751797138.76114,43.1978797912598,-0.00443913787603378,0.106314770877361
,3751797138.78114,43.0246963500977,-0.0031500153709203,0.107571579515934
,3751797138.80114,42.8518180847168,-0.00214027659967542,0.108549065887928
,3751797138.82114,42.6793937683105,-0.00129004335030913,0.10936713218689
,3751797138.84114,42.5059089660645,-0.000694376125466078,0.10993043333292
,3751797138.86114,42.3331832885742,-0.00021085595653858,0.110381729900837
,3751797138.88114,42.1598472595215,2.30110072152456E-5,0.110583253204823
,3751797138.90114,41.9866638183594,-0.000218261382542551,0.110309675335884
,3751797138.92114,41.8127288818359,-0.000535665196366608,0.109959818422794
,3751797138.94114,41.6387901306152,-0.0010158980730921,0.109447136521339
,3751797138.96114,41.4659080505371,-0.00188486161641777,0.108545914292336
,3751797138.98114,41.292423248291,-0.00305405189283192,0.10734435915947
,3751797139.00114,41.1187896728516,-0.00452133780345321,0.105844676494598
,3751797139.02114,40.9453010559082,-0.00605169637128711,0.104281954467297
,3751797139.04114,40.7721214294434,-0.00798684265464544,0.102314494550228
,3751797139.06114,40.5984840393066,-0.0104973539710045,0.0997715890407562
,3751797139.08114,40.4251518249512,-0.0133331445977092,0.096903458237648
,3751797139.10114,40.2522735595703,-0.0165231321007013,0.0936812236905098
,3751797139.12114,40.0789413452148,-0.0199647396802902,0.0902072712779045
,3751797139.14114,39.9053039550781,-0.0238348878920078,0.0863047316670418
,3751797139.16114,39.7322731018066,-0.0282479971647263,0.0818593427538872
,3751797139.18114,39.5587882995605,-0.0328856930136681,0.0771892741322517
,3751797139.20114,39.3854522705078,-0.0378983691334724,0.0721442624926567
,3751797139.22114,39.2113647460937,-0.0433119535446167,0.0666982010006905
,3751797139.24114,39.0384826660156,-0.0490737557411194,0.0609041415154934
,3751797139.26114,38.8650016784668,-0.0553336702287197,0.05461186170578
,3751797139.28114,38.6913642883301,-0.061757642775774,0.0481554940342903
,3751797139.30114,38.5177268981934,-0.0685131251811981,0.0413676165044308
,3751797139.32114,38.3442420959473,-0.0756834372878075,0.0341649390757084
,3751797139.34114,38.1712112426758,-0.0831584930419922,0.0266575999557972
,3751797139.36114,37.9974250793457,-0.0911584496498108,0.0186252221465111
,3751797139.38114,37.8239402770996,-0.0995571985840797,0.0101941060274839
,3751797139.40114,37.6507568359375,-0.108120396733284,0.00159859715495259
,3751797139.42114,37.4772720336914,-0.116738237440586,-0.00705161038786173
,3751797139.44114,37.3042449951172,-0.125552460551262,-0.0158981140702963
,3751797139.46114,37.1309089660645,-0.13479620218277,-0.0251741949468851
,3751797139.48114,36.9580307006836,-0.144301846623421,-0.0347120948135853
,3751797139.50114,36.7845458984375,-0.153718739748001,-0.0441613532602787
,3751797139.52114,36.611515045166,-0.163169786334038,-0.0536446832120419
,3751797139.54114,36.4383316040039,-0.172884181141853,-0.063391387462616
,3751797139.56114,36.2643928527832,-0.182982340455055,-0.0735219940543175
,3751797139.58114,36.0915145874023,-0.192948654294014,-0.0835205614566803
,3751797139.60114,35.9181823730469,-0.202791556715965,-0.0933958068490028
,3751797139.62114,35.7445449829102,-0.212417453527451,-0.103054098784924
,3751797139.64114,35.5713653564453,-0.222304001450539,-0.11297295242548
,3751797139.66114,35.397876739502,-0.23212032020092,-0.122821643948555
,3751797139.68114,35.2245445251465,-0.241858601570129,-0.132592260837555
,3751797139.70114,35.0513648986816,-0.2511106133461,-0.141876578330994
,3751797139.72114,34.8781814575195,-0.260271728038788,-0.151070013642311
,3751797139.74114,34.7043952941895,-0.26938071846962,-0.16021141409874
,3751797139.76114,34.531665802002,-0.278025448322296,-0.168888375163078
,3751797139.78114,34.359546661377,-0.28636971116066,-0.177264750003815
,3751797139.80114,34.1862106323242,-0.294414967298508,-0.185342341661453
,3751797139.82114,34.0125770568848,-0.302094459533691,-0.193054229021072
,3751797139.84114,33.8390922546387,-0.309461355209351,-0.200453490018845
,3751797139.86114,33.6663665771484,-0.316500782966614,-0.20752514898777
,3751797139.88114,33.4925765991211,-0.323123067617416,-0.21417985856533
,3751797139.90114,33.3189392089844,-0.329129874706268,-0.220219060778618
,3751797139.92114,33.1453018188477,-0.334495931863785,-0.22561751306057
,3751797139.94114,32.9724235534668,-0.33947965502739,-0.230633482336998
,3751797139.96114,32.7989387512207,-0.343709915876389,-0.23489610850811
,3751797139.98114,32.6254539489746,-0.347363144159317,-0.238581702113152
,3751797140.00114,32.4528770446777,-0.350253283977509,-0.241504043340683
,3751797140.02114,32.278636932373,-0.352766275405884,-0.244049549102783
,3751797140.04114,32.1059074401855,-0.354733228683472,-0.246048718690872
,3751797140.06114,31.9319705963135,-0.35597437620163,-0.24732232093811
,3751797140.08114,31.7586345672607,-0.356447368860245,-0.247827649116516
,3751797140.10114,31.5856056213379,-0.356516003608704,-0.247928574681282
,3751797140.12114,31.4124240875244,-0.355770856142044,-0.247215732932091
,3751797140.14114,31.2386360168457,-0.354343503713608,-0.245820805430412
,3751797140.16114,31.0651512145996,-0.352368474006653,-0.24387814104557
,3751797140.18114,30.8919696807861,-0.349735826253891,-0.241277799010277
,3751797140.20114,30.7189407348633,-0.346355348825455,-0.237929612398148
,3751797140.22114,30.5451507568359,-0.342271417379379,-0.23387810587883
,3751797140.24114,30.3719711303711,-0.337729871273041,-0.22936886548996
,3751797140.26114,30.1984844207764,-0.332709521055222,-0.224380880594254
,3751797140.28114,30.0246963500977,-0.327178031206131,-0.218881815671921
,3751797140.30114,29.8513641357422,-0.321162313222885,-0.212898433208466
,3751797140.32114,29.6775760650635,-0.314454644918442,-0.20622318983078
,3751797140.34114,29.5049991607666,-0.307569682598114,-0.199370428919792
,3751797140.36114,29.3313655853271,-0.30000302195549,-0.191836163401604
,3751797140.38114,29.1578788757324,-0.292303562164307,-0.184169068932533
,3751797140.40114,28.9846973419189,-0.284084916114807,-0.175982728600502
,3751797140.42114,28.8118190765381,-0.275530338287354,-0.167460411787033
,3751797140.44114,28.6384830474854,-0.266798257827759,-0.158760666847229
,3751797140.46114,28.4651508331299,-0.257394075393677,-0.149388819932938
,3751797140.48114,28.292121887207,-0.248203560709953,-0.14023058116436
,3751797140.50114,28.1181812286377,-0.238685593008995,-0.130745068192482
,3751797140.52114,27.9443950653076,-0.228831321001053,-0.120923221111298
,3751797140.54114,27.7709083557129,-0.218929812312126,-0.111054077744484
,3751797140.56114,27.5971221923828,-0.208999693393707,-0.101156383752823
,3751797140.58114,27.424243927002,-0.19961841404438,-0.0918073579668999
,3751797140.60114,27.2510604858398,-0.189882338047028,-0.0821035951375961
,3751797140.62114,27.0775756835938,-0.180135652422905,-0.0723892748355865
,3751797140.64114,26.9039402008057,-0.170138597488403,-0.06242461130023
,3751797140.66114,26.7312107086182,-0.16024361550808,-0.0525618568062782
,3751797140.68114,26.5575752258301,-0.150669753551483,-0.0430203899741173
,3751797140.70114,26.383939743042,-0.141111359000206,-0.0334943905472755
,3751797140.72114,26.2115154266357,-0.131560131907463,-0.0239753313362598
,3751797140.74114,26.0375747680664,-0.122474655508995,-0.0149223059415817
,3751797140.76114,25.8637886047363,-0.113651223480701,-0.00613129697740078
,3751797140.78114,25.6909084320068,-0.105037681758404,0.00244999071583152
,3751797140.80114,25.5172729492187,-0.0966804400086403,0.0107748378068209
,3751797140.82114,25.3440914154053,-0.0886297523975372,0.0187932159751654
,3751797140.84114,25.1706047058105,-0.0808777138590813,0.0265128873288631
,3751797140.86114,24.9972724914551,-0.0732622593641281,0.0340960025787354
,3751797140.88114,24.8239402770996,-0.0661389976739883,0.0411869250237942
,3751797140.90114,24.6506061553955,-0.0594907179474831,0.0478028692305088
,3751797140.92114,24.4771213531494,-0.0529208369553089,0.0543403811752796
,3751797140.94114,24.3037891387939,-0.0467480719089508,0.0604808107018471
,3751797140.96114,24.1303024291992,-0.0411067083477974,0.0660898089408874
,3751797140.98114,23.9571208953857,-0.0358117036521435,0.0713524967432022
,3751797141.00114,23.7839412689209,-0.0308717228472233,0.0762601718306541
,3751797141.02114,23.6107559204102,-0.0262421388179064,0.080857440829277
,3751797141.04114,23.4365158081055,-0.0220263916999102,0.0850406810641289
,3751797141.06114,23.2634830474854,-0.0184493009001017,0.0885854959487915
,3751797141.08114,23.0901508331299,-0.0152583215385675,0.0917441323399544
,3751797141.10114,22.9169692993164,-0.0122491167858243,0.0947210267186165
,3751797141.12114,22.7439403533936,-0.00962215941399336,0.0973157063126564
,3751797141.14114,22.5706062316895,-0.00728932395577431,0.0996161997318268
,3751797141.16114,22.3968181610107,-0.00531915528699756,0.101553946733475
,3751797141.18114,22.2233333587646,-0.00347876199521124,0.10336197167635
,3751797141.20114,22.0503025054932,-0.00210543489083648,0.104703016579151
,3751797141.22114,21.8762111663818,-0.00111588940490037,0.105660080909729
,3751797141.24114,21.703332901001,-0.000379771925508976,0.106363944709301
,3751797141.26114,21.5296974182129,0.000136350150569342,0.106847673654556
,3751797141.28114,21.3565158843994,0.000264933652943,0.10694395005703
,3751797141.30114,21.1831817626953,0.000107324493001215,0.106753997504711
,3751797141.32114,21.0096969604492,-0.000283013709122315,0.106331296265125
,3751797141.34114,20.8363647460938,-0.000745599973015487,0.105836369097233
,3751797141.36114,20.662727355957,-0.00147104274947196,0.105078533291817
,3751797141.38114,20.4890918731689,-0.00238732877187431,0.10412985086441
,3751797141.40114,20.3157577514648,-0.00333966664038599,0.10314517468214
,3751797141.42114,20.1425762176514,-0.00441049132496119,0.10204204171896
,3751797141.44114,19.9690914154053,-0.0057284040376544,0.100691765546799
,3751797141.46114,19.7956047058105,-0.00716773048043251,0.0992200672626495
,3751797141.48114,19.6222724914551,-0.00874387566000223,0.0976115837693214
,3751797141.50114,19.448787689209,-0.010371751151979,0.0959513410925865
,3751797141.52114,19.2753028869629,-0.0120617048814893,0.094229020178318
,3751797141.54114,19.1016654968262,-0.0140327587723732,0.0922255739569664
,3751797141.56114,18.9284858703613,-0.0160772521048784,0.0901487693190575
,3751797141.58114,18.7551517486572,-0.0177331790328026,0.0884605050086975
,3751797141.60114,18.5824241638184,-0.0197640527039766,0.0863974094390869
,3751797141.62114,18.4086360931396,-0.0217832773923874,0.0843457579612732
,3751797141.64114,18.2348480224609,-0.0236674528568983,0.0824291631579399
,3751797141.66114,18.0610599517822,-0.0253413505852222,0.080722838640213
,3751797141.68114,17.888635635376,-0.0274312514811754,0.0786007717251778
,3751797141.70114,17.71409034729,-0.0294428747147322,0.0765565782785416
,3751797141.72114,17.5419692993164,-0.0312729887664318,0.0746943578124046
,3751797141.74114,17.3681831359863,-0.0332698188722134,0.0726651027798653
,3751797141.76114,17.1946964263916,-0.035276472568512,0.0706260800361633
,3751797141.78114,17.0215148925781,-0.0374870263040066,0.0683832168579102
,3751797141.80114,16.8475761413574,-0.0392342731356621,0.0666035190224648
,3751797141.82114,16.6748485565186,-0.0412773564457893,0.0645282119512558
,3751797141.84114,16.5009098052979,-0.0430161692202091,0.0627569481730461
,3751797141.86114,16.328182220459,-0.0447670295834541,0.0609738603234291
,3751797141.88114,16.1546974182129,-0.0464380383491516,0.0592704862356186
,3751797141.90114,15.9807577133179,-0.0481616593897343,0.057514414191246
,3751797141.92114,15.8078784942627,-0.0496563985943794,0.0559874214231968
,3751797141.94114,15.6334848403931,-0.0512127839028835,0.0543984994292259
,3751797141.96114,15.4604539871216,-0.0529228039085865,0.0526561960577965
,3751797141.98114,15.2871217727661,-0.0544716753065586,0.0510749854147434
,3751797142.00114,15.1136360168457,-0.0560702905058861,0.0494440048933029
,3751797142.02114,14.9407577514648,-0.0577769391238689,0.047705102711916
,3751797142.04114,14.7668180465698,-0.0591685250401497,0.0462810657918453
,3751797142.06114,14.5942420959473,-0.0605731196701527,0.0448442734777927
,3751797142.08114,14.4207582473755,-0.0618377104401588,0.0435473173856735
,3751797142.67196,14.1996879577637,,,0.0441903881728649,0.0443669632077217
,3751797142.69196,14.3746881484985,,,0.0454002320766449,0.0455829091370106
,3751797142.71196,14.5496883392334,,,0.0466516986489296,0.046840600669384
,3751797142.73196,14.7246875762939,,,0.0479455478489399,0.0481407754123211
,3751797142.75196,14.8996877670288,,,0.0492824427783489,0.0494840890169144
,3751797142.77196,15.0746879577637,,,0.0506629571318626,0.050871092826128
,3751797142.79196,15.2496881484985,,,0.0520875379443169,0.0523022226989269
,3751797142.81196,15.4246883392334,,,0.0535564906895161,0.0537777580320835
,3751797142.83196,15.5996875762939,,,0.0550699904561043,0.0552978515625
,3751797142.85196,15.7746877670288,,,0.0566279962658882,0.0568624325096607
,3751797142.87196,15.9496879577637,,,0.0582302883267403,0.0584712438285351
,3751797142.89196,16.1246871948242,,,0.0598763972520828,0.0601237863302231
,3751797142.91196,16.2996883392334,,,0.0615656152367592,0.0618193075060844
,3751797142.93196,16.4746875762939,,,0.0632968991994858,0.0635567232966423
,3751797142.95196,16.6496887207031,,,0.0650689303874969,0.0653346553444862
,3751797142.97196,16.8246879577637,,,0.0668800324201584,0.0671513751149178
,3751797142.99196,16.9996871948242,,,0.0687280744314194,0.069004699587822
,3751797143.01196,17.1746883392334,,,0.0706105753779411,0.0708920732140541
,3751797143.03196,17.3496875762939,,,0.0725244954228401,0.0728103816509247
,3751797143.05196,17.5246887207031,,,0.0744663700461388,0.0747560784220696
,3751797143.07196,17.6996879577637,,,0.076432079076767,0.076724961400032
,3751797143.09196,17.8746871948242,,,0.0784170106053352,0.0787123292684555
,3751797143.11196,18.0496883392334,,,0.0804158002138138,0.0807127207517624
,3751797143.13196,18.2246875762939,,,0.0824225246906281,0.0827201008796692
,3751797143.15196,18.3996887207031,,,0.0844304114580154,0.0847275927662849
,3751797143.17196,18.5746879577637,,,0.0864320397377014,0.0867276638746262
,3751797143.19196,18.7496871948242,,,0.0884191170334816,0.0887118950486183
,3751797143.21196,18.9246883392334,,,0.0903825610876083,0.0906710848212242
,3751797143.23196,19.0996875762939,,,0.0923124775290489,0.092595212161541
,3751797143.25196,19.2746887207031,,,0.0941980108618736,0.0944732949137688
,3751797143.27196,19.4496879577637,,,0.0960275381803513,0.096293568611145
,3751797143.29196,19.6246871948242,,,0.0977884754538536,0.098043330013752
,3751797143.31196,19.7996883392334,,,0.099467433989048,0.0997090712189674
,3751797143.33196,19.9746875762939,,,0.101050116121769,0.101276367902756
,3751797143.35196,20.1496887207031,,,0.102521501481533,0.102730073034763
,3751797143.37196,20.3246879577637,,,0.103865720331669,0.104054220020771
,3751797143.39196,20.4996871948242,,,0.105066277086735,0.105232208967209
,3751797143.41196,20.6746883392334,,,0.106106005609035,0.106246799230576
,3751797143.43196,20.8496875762939,,,0.106967248022556,0.107080265879631
,3751797143.45196,21.0246887207031,,,0.107631914317608,0.107714459300041
,3751797143.47196,21.1996879577637,,,0.108081661164761,0.108131006360054
,3751797143.49196,21.3746871948242,,,0.108297981321812,0.108311399817467
,3751797143.51196,21.5496883392334,,,0.108262374997139,0.108237147331238
,3751797143.53196,21.7246875762939,,,0.107956543564796,0.107889994978905
,3751797143.55196,21.8996887207031,,,0.107362553477287,0.107252076268196
,3751797143.57196,22.0746879577637,,,0.106462977826595,0.106306061148643
,3751797143.59196,22.2496871948242,,,0.105241186916828,0.105035446584225
,3751797143.61196,22.4246883392334,,,0.103681415319443,0.103424616158009
,3751797143.63196,22.5996875762939,,,0.101769082248211,0.101459182798862
,3751797143.65196,22.7746887207031,,,0.0994908511638641,0.0991259887814522
,3751797143.67196,22.9496879577637,,,0.0968349277973175,0.0964134931564331
,3751797143.69196,23.1246871948242,,,0.0937910676002502,0.0933117046952248
,3751797143.71196,23.2996883392334,,,0.090350940823555,0.0898125544190407
,3751797143.73196,23.4746875762939,,,0.0865080431103706,0.0859098434448242
,3751797143.75196,23.6496887207031,,,0.0822578594088554,0.0815993547439575
,3751797143.77196,23.8246879577637,,,0.0775981470942497,0.0768791809678078
,3751797143.79196,23.9996871948242,,,0.0725286453962326,0.071749359369278
,3751797143.81196,24.1746883392334,,,0.0670515149831772,0.0662123933434486
,3751797143.83196,24.3496875762939,,,0.0611709244549274,0.0602727755904198
,3751797143.85196,24.5246887207031,,,0.0548935085535049,0.0539374761283398
,3751797143.87196,24.6996879577637,,,0.0482278503477573,0.0472153834998608
,3751797143.89196,24.8746871948242,,,0.0411849580705166,0.040117833763361
,3751797143.91196,25.0496883392334,,,0.0337776504456997,0.032657939940691
,3751797143.93196,25.2246875762939,,,0.0260210782289505,0.0248511508107185
,3751797143.95196,25.3996887207031,,,0.0179320182651281,0.0167145188897848
,3751797143.97196,25.5746879577637,,,0.00952944066375494,0.00826728250831366
,3751797143.99196,25.7496871948242,,,0.000833825033623725,-0.000469826685730368
,3751797144.01196,25.9246883392334,,,-0.00813268404453993,-0.00947442464530468
,3751797144.03196,26.0996875762939,,,-0.0173460617661476,-0.0187222566455603
,3751797144.05196,26.2746868133545,,,-0.0267811734229326,-0.0281879771500826
,3751797144.07196,26.4496879577637,,,-0.0364110581576824,-0.0378444232046604
,3751797144.09196,26.6246871948242,,,-0.0462078303098679,-0.0476635098457336
,3751797144.11196,26.7996883392334,,,-0.0561418943107128,-0.0576154626905918
,3751797144.13196,26.9746875762939,,,-0.0661828890442848,-0.0676697492599487
,3751797144.15196,27.1496868133545,,,-0.0762988701462746,-0.0777942538261414
,3751797144.17196,27.3246879577637,,,-0.0864572450518608,-0.0879562422633171
,3751797144.19196,27.4996871948242,,,-0.0966239646077156,-0.0981215164065361
,3751797144.21196,27.6746883392334,,,-0.106764376163483,-0.108255282044411
,3751797144.23196,27.8496875762939,,,-0.116842940449715,-0.118321880698204
,3751797144.25196,28.0246868133545,,,-0.126823008060455,-0.128284558653831
,3751797144.27196,28.1996879577637,,,-0.136667683720589,-0.138106316328049
,3751797144.29196,28.3746871948242,,,-0.146339073777199,-0.147749215364456
,3751797144.31196,28.5496883392334,,,-0.155799269676209,-0.157175272703171
,3751797144.33196,28.7246875762939,,,-0.165009692311287,-0.166345879435539
,3751797144.35196,28.8996868133545,,,-0.173932075500488,-0.175222769379616
,3751797144.37196,29.0746879577637,,,-0.182527840137482,-0.183767423033714
,3751797144.39196,29.2496871948242,,,-0.190759167075157,-0.19194208085537
,3751797144.41196,29.4246883392334,,,-0.198588445782661,-0.199709236621857
,3751797144.43196,29.5996875762939,,,-0.205979317426682,-0.207032680511475
,3751797144.45196,29.7746868133545,,,-0.212896198034286,-0.213877022266388
,3751797144.47196,29.9496879577637,,,-0.219305232167244,-0.220208659768105
,3751797144.49196,30.1246871948242,,,-0.225174322724342,-0.225995779037476
,3751797144.51196,30.2996883392334,,,-0.230473250150681,-0.231208473443985
,3751797144.53196,30.4746875762939,,,-0.23517444729805,-0.235819578170776
,3751797144.55196,30.6496868133545,,,-0.239252820611,-0.239804416894913
,3751797144.57196,30.8246879577637,,,-0.242686465382576,-0.243141531944275
,3751797144.59196,30.9996871948242,,,-0.245456516742706,-0.245812565088272
,3751797144.61196,31.1746883392334,,,-0.247547715902328,-0.247802793979645
,3751797144.63196,31.3496875762939,,,-0.248948395252228,-0.24910107254982
,3751797144.65196,31.5246868133545,,,-0.249650716781616,-0.249700158834457
,3751797144.67196,31.6996879577637,,,-0.249650716781616,-0.249596640467644
,3751797144.69196,31.8746871948242,,,-0.248948395252228,-0.248791128396988
,3751797144.71196,32.0496864318848,,,-0.247547686100006,-0.247288152575493
,3751797144.73196,32.2246894836426,,,-0.245456516742706,-0.245096147060394
,3751797144.75196,32.3996887207031,,,-0.242686435580254,-0.242227271199226
,3751797144.77196,32.5746879577637,,,-0.239252790808678,-0.238697350025177
,3751797144.79196,32.7496871948242,,,-0.23517444729805,-0.234525784850121
,3751797144.81196,32.9246864318848,,,-0.230473250150681,-0.229734823107719
,3751797144.83196,33.0996894836426,,,-0.225174263119698,-0.224349990487099
,3751797144.85196,33.2746887207031,,,-0.219305172562599,-0.218399316072464
,3751797144.87196,33.4496879577637,,,-0.212896198034286,-0.211913362145424
,3751797144.89196,33.6246871948242,,,-0.205979242920876,-0.204924315214157
,3751797144.91196,33.7996864318848,,,-0.198588371276855,-0.197466462850571
,3751797144.93196,33.9746894836426,,,-0.190758988261223,-0.189575418829918
,3751797144.95196,34.1496887207031,,,-0.182527840137482,-0.181288048624992
,3751797144.97196,34.3246879577637,,,-0.17393197119236,-0.172641530632973
,3751797144.99196,34.4996871948242,,,-0.16500960290432,-0.163674131035805
,3751797145.01196,34.6746864318848,,,-0.155799269676209,-0.154424428939819
[...]
,3751799968.54294,26.9039402008057,-0.135806307196617,-0.0779926255345345
,3751799968.56294,26.7309074401855,-0.123315028846264,-0.065502718091011
,3751799968.58294,26.5577278137207,-0.11126846075058,-0.0534575246274471
,3751799968.60294,26.383939743042,-0.0993556380271912,-0.0415460765361786
,3751799968.62294,26.2113647460938,-0.087473526597023,-0.0296653341501951
,3751799968.64294,26.0375747680664,-0.0756825655698776,-0.017875749617815
,3751799968.66294,25.8643951416016,-0.0643343850970268,-0.00652894144877791
,3751799968.68294,25.6907577514648,-0.0534082055091858,0.00439586210995913
,3751799968.70294,25.5174236297607,-0.0427226275205612,0.0150800663977861
,3751799968.72294,25.3440914154053,-0.0322500541806221,0.0255512669682503
,3751799968.74294,25.1696968078613,-0.0222031120210886,0.0355968251824379
,3751799968.76294,24.9971218109131,-0.0128366202116013,0.0449619516730309
,3751799968.78294,24.8236351013184,-0.00386584922671318,0.0539313480257988
,3751799968.80294,24.6503028869629,0.00477362796664238,0.0625694543123245
,3751799968.82294,24.4769706726074,0.0131095545366406,0.0709040015935898
,3751799968.84294,24.3034839630127,0.020969619974494,0.0787626951932907
,3751799968.86294,24.1303024291992,0.0281786751002073,0.0859703794121742
,3751799968.88294,23.9572734832764,0.0348058640956879,0.0925961956381798
,3751799968.90294,23.7839412689209,0.0410771407186985,0.0988660976290703
,3751799968.92294,23.6103019714355,0.0469809249043465,0.104768507182598
,3751799968.94294,23.4368190765381,0.0523354299366474,0.110121637582779
,3751799968.96294,23.2637882232666,0.0570681840181351,0.114853017032146
,3751799968.98294,23.0898494720459,0.0613612532615662,0.119144707918167
,3751799969.00294,22.9168186187744,0.0652452856302261,0.123027369379997
,3751799969.02294,22.7434844970703,0.0687335878610611,0.126514300704002
,3751799969.04294,22.5698490142822,0.0717402994632721,0.129519641399384
,3751799969.06294,22.3962116241455,0.0742143765091896,0.131992340087891
,3751799969.08294,22.2234840393066,0.0762648209929466,0.134041413664818
,3751799969.10294,22.0503025054932,0.0779701620340347,0.135745376348495
,3751799969.12294,21.8763656616211,0.0792831107974052,0.137056946754456
,3751799969.14294,21.703332901001,0.080208458006382,0.137980923056602
,3751799969.16294,21.5295467376709,0.0807835012674332,0.138554587960243
,3751799969.18294,21.3559074401855,0.0810240358114243,0.138793751597404
,3751799969.20294,21.1830291748047,0.0809424296021462,0.138710781931877
,3751799969.22294,21.008939743042,0.0805769115686417,0.138343885540962
,3751799969.24294,20.8359088897705,0.0799527242779732,0.137718319892883
,3751799969.26294,20.6622734069824,0.0790601372718811,0.136824354529381
,3751799969.28294,20.488941192627,0.0779475122690201,0.13571035861969
,3751799969.30294,20.3153018951416,0.0766185522079468,0.134380027651787
,3751799969.32294,20.1424236297607,0.075089231133461,0.132849335670471
,3751799969.34294,19.9689388275146,0.0734000578522682,0.131158784031868
,3751799969.36294,19.7956047058105,0.0715743452310562,0.129331693053246
,3751799969.38294,19.6222724914551,0.0696123838424683,0.127368360757828
,3751799969.40294,19.448787689209,0.0675056055188179,0.125260204076767
,3751799969.42294,19.2753028869629,0.0653169080615044,0.123070135712624
,3751799969.44294,19.1018180847168,0.0630414932966232,0.120793350040913
,3751799969.46294,18.9278793334961,0.0607188604772091,0.118469335138798
,3751799969.48294,18.7551517486572,0.0583309717476368,0.116080082952976
,3751799969.50294,18.5816669464111,0.0558504574000835,0.113598190248013
,3751799969.52294,18.4078788757324,0.0533411391079426,0.111087493598461
,3751799969.54294,18.2348480224609,0.0508618019521236,0.108606785535812
,3751799969.56294,18.0612125396729,0.0484050810337067,0.106148689985275
,3751799969.58294,17.8881816864014,0.0459147617220879,0.103656999766827
,3751799969.60294,17.714241027832,0.0433830097317696,0.101123869419098
,3751799969.62294,17.5415153503418,0.040881060063839,0.0986205488443375
,3751799969.64294,17.3674240112305,0.0384101569652557,0.0961482673883438
,3751799969.66294,17.1946964263916,0.035983182489872,0.0937199294567108
,3751799969.68294,17.0215148925781,0.0335776656866074,0.0913130342960358
,3751799969.70294,16.8474235534668,0.0311919450759888,0.0889259353280067
,3751799969.72294,16.6746978759766,0.0288264714181423,0.0865590944886208
,3751799969.74294,16.5006046295166,0.0265452917665243,0.0842765346169472
,3751799969.76294,16.3272724151611,0.024342954158783,0.0820728242397308
,3751799969.78294,16.1545467376709,0.0221564751118422,0.0798849761486054
,3751799969.80294,15.9804544448853,0.019966708496213,0.0776938274502754
,3751799969.82294,15.8068180084229,0.0178353190422058,0.075561061501503
,3751799969.84294,15.6339387893677,0.0158125180751085,0.0735368952155113
,3751799969.86294,15.4598484039307,0.0138241425156593,0.0715471357107162
,3751799969.88294,15.28590965271,0.0118809407576919,0.0696025565266609
,3751799969.90294,15.1130294799805,0.0099760303273797,0.0676962807774544
,3751799969.92294,14.9389390945435,0.00813782308250666,0.0658566951751709
,3751799969.94294,14.7657585144043,0.00639072014018893,0.0641082152724266
,3751799969.96294,14.5927267074585,0.0046929270029068,0.0624090507626534
,3751799969.98294,14.4190902709961,0.00301310536451638,0.0607278533279896
,3751799970.5592,14.1996879577637,,,0.0565656125545502,0.0565153434872627
,3751799970.5792,14.3746881484985,,,0.0581141449511051,0.058062132447958
,3751799970.5992,14.5496883392334,,,0.0597159564495087,0.0596621632575989
,3751799970.6192,14.7246875762939,,,0.0613720081746578,0.0613164082169533
,3751799970.6392,14.8996877670288,,,0.0630831569433212,0.0630257278680801
,3751799970.6592,15.0746879577637,,,0.0648501366376877,0.0647908449172974
,3751799970.6792,15.2496881484985,,,0.0666735246777534,0.0666123554110527
,3751799970.6992,15.4246883392334,,,0.068553701043129,0.0684906542301178
,3751799970.7192,15.5996875762939,,,0.0704908892512322,0.07042595744133
,3751799970.7392,15.7746877670288,,,0.0724850594997406,0.0724182426929474
,3751799970.7592,15.9496879577637,,,0.0745358988642693,0.0744672194123268
,3751799970.7792,16.1246871948242,,,0.0766428261995316,0.0765723064541817
,3751799970.7992,16.2996883392334,,,0.0788049325346947,0.0787326022982597
,3751799970.8192,16.4746875762939,,,0.0810208767652512,0.0809467881917954
,3751799970.8392,16.6496887207031,,,0.0832889750599861,0.0832131952047348
,3751799970.8592,16.8246879577637,,,0.0856070816516876,0.0855296924710274
,3751799970.8792,16.9996871948242,,,0.0879724770784378,0.0878935679793358
,3751799970.8992,17.1746883392334,,,0.0903819724917412,0.0903016701340675
,3751799970.9192,17.3496875762939,,,0.0928316861391068,0.0927501171827316
,3751799970.9392,17.5246887207031,,,0.0953171700239182,0.0952344983816147
,3751799970.9592,17.6996879577637,,,0.0978331714868546,0.0977495834231377
,3751799970.9792,17.8746871948242,,,0.100373767316341,0.100289471447468
,3751799970.9992,18.0496883392334,,,0.10293211042881,0.10284735262394
,3751799971.0192,18.2246875762939,,,0.105500601232052,0.105415642261505
,3751799971.0392,18.3996887207031,,,0.108070582151413,0.107985720038414
,3751799971.0592,18.5746879577637,,,0.110632561147213,0.110548131167889
,3751799971.0792,18.7496871948242,,,0.11317589879036,0.11309227347374
,3751799971.0992,18.9246883392334,,,0.115689001977444,0.1156065762043
,3751799971.1192,19.0996875762939,,,0.118159182369709,0.118078395724297
,3751799971.1392,19.2746887207031,,,0.120572566986084,0.120493896305561
,3751799971.1592,19.4496879577637,,,0.122914254665375,0.122838214039803
,3751799971.1792,19.6246871948242,,,0.125168144702911,0.125095292925835
,3751799971.1992,19.7996883392334,,,0.127317130565643,0.127248018980026
,3751799971.2192,19.9746875762939,,,0.129342868924141,0.129278153181076
,3751799971.2392,20.1496887207031,,,0.131226167082787,0.131166487932205
,3751799971.2592,20.3246879577637,,,0.132946684956551,0.132892742753029
,3751799971.2792,20.4996871948242,,,0.134483337402344,0.134435817599297
,3751799971.2992,20.6746883392334,,,0.135814115405083,0.135773777961731
,3751799971.3192,20.8496875762939,,,0.136916473507881,0.136884063482285
,3751799971.3392,21.0246887207031,,,0.13776721060276,0.137743502855301
,3751799971.3592,21.1996879577637,,,0.13834285736084,0.138328641653061
,3751799971.3792,21.3746871948242,,,0.138619735836983,0.138615787029266
,3751799971.3992,21.5496883392334,,,0.138574153184891,0.138581275939941
,3751799971.4192,21.7246875762939,,,0.13818271458149,0.138201653957367
,3751799971.4392,21.8996887207031,,,0.137422427535057,0.137453943490982
,3751799971.4592,22.0746879577637,,,0.13627102971077,0.13631583750248
,3751799971.4792,22.2496871948242,,,0.134707197546959,0.13476599752903
,3751799971.4992,22.4246883392334,,,0.132710784673691,0.132784202694893
,3751799971.5192,22.5996875762939,,,0.130263105034828,0.130351766943932
,3751799971.5392,22.7746887207031,,,0.127347096800804,0.127451509237289
,3751799971.5592,22.9496879577637,,,0.123947665095329,0.124068297445774
,3751799971.5792,23.1246871948242,,,0.120051696896553,0.12018895149231
,3751799971.5992,23.2996883392334,,,0.115648530423641,0.115802720189095
,3751799971.6192,23.4746875762939,,,0.110729828476906,0.110901191830635
,3751799971.6392,23.6496887207031,,,0.105289839208126,0.105478510260582
,3751799971.6592,23.8246879577637,,,0.0993256717920303,0.0995317175984383
,3751799971.6792,23.9996871948242,,,0.0928369909524918,0.0930603668093681
,3751799971.6992,24.1746883392334,,,0.085826575756073,0.0860671475529671
,3751799971.7192,24.3496875762939,,,0.0782997459173203,0.0785572975873947
,3751799971.7392,24.5246887207031,,,0.0702650099992752,0.0705392062664032
,3751799971.7592,24.6996879577637,,,0.0617333389818668,0.0620237663388252
,3751799971.7792,24.8746871948242,,,0.0527188330888748,0.0530249923467636
,3751799971.7992,25.0496883392334,,,0.0432378947734833,0.0435591898858547
,3751799971.8192,25.2246875762939,,,0.033309917896986,0.0336456745862961
,3751799971.8392,25.3996887207031,,,0.0229563768953085,0.0233058370649815
,3751799971.8592,25.5746879577637,,,0.0122015494853258,0.0125638786703348
,3751799971.8792,25.7496871948242,,,0.0010716503020376,0.0014459426747635
,3751799971.8992,25.9246883392334,,,-0.010404977016151,-0.0100196981802583
,3751799971.9192,26.0996875762939,,,-0.0221975818276405,-0.0218023583292961
,3751799971.9392,26.2746868133545,,,-0.0342739932239056,-0.0338699296116829
,3751799971.9592,26.4496879577637,,,-0.0465997084975243,-0.0461879670619965
,3751799971.9792,26.6246871948242,,,-0.0591390244662762,-0.0587208196520805
,3751799971.9992,26.7996883392334,,,-0.0718540698289871,-0.0714306756854057
,3751799972.0192,26.9746875762939,,,-0.0847059786319733,-0.0842787101864815
,3751799972.0392,27.1496868133545,,,-0.097653865814209,-0.0972240939736366
,3751799972.0592,27.3246879577637,,,-0.110656008124352,-0.110225148499012
,3751799972.0792,27.4996871948242,,,-0.123668842017651,-0.12323834747076
,3751799972.0992,27.6746883392334,,,-0.136647999286652,-0.136219352483749
,3751799972.1192,27.8496875762939,,,-0.14954799413681,-0.149122729897499
,3751799972.1392,28.0246868133545,,,-0.162321925163269,-0.161901608109474
,3751799972.1592,28.1996879577637,,,-0.174922555685043,-0.174508765339851
,3751799972.1792,28.3746871948242,,,-0.187301397323608,-0.186895728111267
,3751799972.1992,28.5496883392334,,,-0.199409916996956,-0.199014008045197
,3751799972.2192,28.7246875762939,,,-0.211198747158051,-0.210814222693443
,3751799972.2392,28.8996868133545,,,-0.222618877887726,-0.222247362136841
,3751799972.2592,29.0746879577637,,,-0.233620971441269,-0.233264088630676
,3751799972.2792,29.2496871948242,,,-0.244156613945961,-0.243815958499908
,3751799972.2992,29.4246883392334,,,-0.254177659749985,-0.253854811191559
,3751799972.3192,29.5996875762939,,,-0.263637542724609,-0.263334035873413
,3751799972.3392,29.7746868133545,,,-0.27249076962471,-0.27220806479454
,3751799972.3592,29.9496879577637,,,-0.280693978071213,-0.280433475971222
,3751799972.3792,30.1246871948242,,,-0.288206070661545,-0.28796911239624
,3751799972.3992,30.2996883392334,,,-0.294988393783569,-0.294776171445847
,3751799972.4192,30.4746875762939,,,-0.301005691289902,-0.300819337368011
,3751799972.4392,30.6496868133545,,,-0.306225776672363,-0.306066304445267
,3751799972.4592,30.8246879577637,,,-0.31062063574791,-0.310488909482956
,3751799972.4792,30.9996871948242,,,-0.314166128635406,-0.314062863588333
,3751799972.4992,31.1746883392334,,,-0.316842764616013,-0.316768556833267
,3751799972.5192,31.3496875762939,,,-0.318635553121567,-0.31859079003334
,3751799972.5392,31.5246868133545,,,-0.319534480571747,-0.319519430398941
,3751799972.5592,31.6996879577637,,,-0.319534480571747,-0.319549202919006
,3751799972.5792,31.8746871948242,,,-0.318635553121567,-0.318679988384247
,3751799972.5992,32.0496864318848,,,-0.31684273481369,-0.316916614770889
,3751799972.6192,32.2246894836426,,,-0.314166128635406,-0.314269095659256
,3751799972.6392,32.3996887207031,,,-0.310620576143265,-0.310752004384994
,3751799972.6592,32.5746879577637,,,-0.306225717067719,-0.306384891271591
,3751799972.6792,32.7496871948242,,,-0.301005691289902,-0.301191747188568
,3751799972.6992,32.9246864318848,,,-0.294988393783569,-0.295200377702713
,3751799972.7192,33.0996894836426,,,-0.2882060110569,-0.288442760705948
,3751799972.7392,33.2746887207031,,,-0.280693888664246,-0.28095418214798
,3751799972.7592,33.4496879577637,,,-0.27249076962471,-0.272773295640945
,3751799972.7792,33.6246871948242,,,-0.263637453317642,-0.263940811157227
,3751799972.7992,33.7996864318848,,,-0.254177540540695,-0.254500269889832
,3751799972.8192,33.9746894836426,,,-0.244156390428543,-0.244496941566467
,3751799972.8392,34.1496887207031,,,-0.233620971441269,-0.233977779746056
,3751799972.8592,34.3246879577637,,,-0.222618758678436,-0.222990229725838
,3751799972.8792,34.4996871948242,,,-0.2111986130476,-0.211583137512207
,3751799972.8992,34.6746864318848,,,-0.199409916996956,-0.199805840849876
,3751799972.9192,34.8496894836426,,,-0.187301397323608,-0.187707096338272
,3751799972.9392,35.0246887207031,,,-0.174922421574593,-0.175336286425591
,3751799972.9592,35.1996879577637,,,-0.162321791052818,-0.16274219751358
,3751799972.9792,35.3746871948242,,,-0.14954799413681,-0.149973377585411
,3751799972.9992,35.5496864318848,,,-0.136647999286652,-0.137076780200005
,3751799973.0192,35.7246894836426,,,-0.1236687079072,-0.124099358916283
,3751799973.0392,35.8996887207031,,,-0.110655725002289,-0.111086763441563
,3751799973.0592,36.0746879577637,,,-0.097653865814209,-0.0980838313698769
,3751799973.0792,36.2496871948242,,,-0.0847058370709419,-0.085133321583271
,3751799973.0992,36.4246864318848,,,-0.0718539282679558,-0.0722775533795357
,3751799973.1192,36.5996856689453,,,-0.0591390244662762,-0.0595574714243412
,3751799973.1392,36.7746887207031,,,-0.0465997084975243,-0.0470117069780827
,3751799973.1592,36.9496879577637,,,-0.0342738628387451,-0.0346781946718693
,3751799973.1792,37.1246871948242,,,-0.0221974533051252,-0.0225929524749517
,3751799973.1992,37.2996864318848,,,-0.010404977016151,-0.010790541768074
,3751799973.2192,37.4746856689453,,,0.0010716503020376,0.000697065202984959
,3751799973.2392,37.6496887207031,,,0.0122016677632928,0.0118390396237373
,3751799973.2592,37.8246879577637,,,0.0229566060006618,0.0226068422198296
,3751799973.2792,37.9996871948242,,,0.033309917896986,0.0329738557338715
,3751799973.2992,38.1746864318848,,,0.0432379990816116,0.0429163984954357
,3751799973.3192,38.3496856689453,,,0.0527189336717129,0.0524124689400196
,3751799973.3392,38.5246887207031,,,0.0617335289716721,0.0614427961409092
,3751799973.3592,38.6996879577637,,,0.0702650099992752,0.0699905157089233
,3751799973.3792,38.8746871948242,,,0.0782998353242874,0.0780419930815697
,3751799973.3992,39.0496864318848,,,0.085826650261879,0.0855857953429222
,3751799973.4192,39.2246856689453,,,0.0928369909524918,0.0926133394241333
,3751799973.4392,39.3996887207031,,,0.0993256717920303,0.0991193577647209
,3751799973.4592,39.5746879577637,,,0.105289898812771,0.105100974440575
,3751799973.4792,39.7496871948242,,,0.110729888081551,0.110558293759823
,3751799973.4992,39.9246864318848,,,0.115648530423641,0.115494124591351
,3751799973.5192,40.0996856689453,,,0.120051741600037,0.119914293289185
,3751799973.5392,40.2746887207031,,,0.123947702348232,0.123826898634434
,3751799973.5592,40.4496879577637,,,0.12734717130661,0.127242609858513
,3751799973.5792,40.6246871948242,,,0.130263105034828,0.130174338817596
,3751799973.5992,40.7996864318848,,,0.132710814476013,0.132637277245522
,3751799973.6192,40.9746856689453,,,0.134707227349281,0.134648337960243
,3751799973.6392,41.1496887207031,,,0.13627102971077,0.136226162314415
,3751799973.6592,41.3246879577637,,,0.137422427535057,0.13739088177681
,3751799973.6792,41.4996871948242,,,0.13818271458149,0.138163775205612
,3751799973.6992,41.6746864318848,,,0.138574168086052,0.138567060232162
,3751799973.7192,41.8496856689453,,,0.138619735836983,0.138623714447021
,3751799973.7392,42.0246887207031,,,0.13834285736084,0.138357132673264
,3751799973.7592,42.1996879577637,,,0.137767195701599,0.137790992856026
,3751799973.7792,42.3746871948242,,,0.136916443705559,0.136948972940445
,3751799973.7992,42.5496864318848,,,0.135814115405083,0.135854601860046
,3751799973.8192,42.7246856689453,,,0.134483322501183,0.134531006217003
,3751799973.8392,42.8996887207031,,,0.132946670055389,0.133000805974007
,3751799973.8592,43.0746879577637,,,0.131226122379303,0.131286010146141
,3751799973.8792,43.2496871948242,,,0.129342868924141,0.129407808184624
,3751799973.8992,43.4246864318848,,,0.127317100763321,0.127386435866356
,3751799973.9192,43.5996856689453,,,0.12516812980175,0.125241249799728
,3751799973.9392,43.7746887207031,,,0.122914254665375,0.122990570962429
,3751799973.9592,43.9496879577637,,,0.120572566986084,0.120651513338089
,3751799973.9792,44.1246871948242,,,0.118159160017967,0.118240237236023
,3751799973.9992,44.2996864318848,,,0.115688979625702,0.11577170342207
,3751799974.0192,44.4746856689453,,,0.11317589879036,0.113259837031364
,3751799974.0392,44.6496887207031,,,0.110632531344891,0.1107172742486
,3751799974.0592,44.8246879577637,,,0.108070552349091,0.108155734837055
,3751799974.0792,44.9996871948242,,,0.105500541627407,0.1055858284235
,3751799974.0992,45.1746864318848,,,0.10293211042881,0.103017203509808
,3751799974.1192,45.3496856689453,,,0.100373737514019,0.100458361208439
,3751799974.1392,45.5246887207031,,,0.0978331416845322,0.0979170650243759
,3751799974.1592,45.6996879577637,,,0.0953171700239182,0.0954001769423485
,3751799974.1792,45.8746871948242,,,0.0928316861391068,0.0929135829210281
,3751799974.1992,46.0496864318848,,,0.0903819426894188,0.0904625877737999
,3751799974.2192,46.2246856689453,,,0.0879724472761154,0.0880516916513443
,3751799974.2392,46.3996887207031,,,0.0856070816516876,0.0856848061084747
,3751799974.2592,46.5746879577637,,,0.0832889750599861,0.0833650827407837
,3751799974.2792,46.7496871948242,,,0.0810208544135094,0.0810952633619308
,3751799974.2992,46.9246864318848,,,0.0788048803806305,0.0788775384426117
,3751799974.3192,47.0996856689453,,,0.0766428261995316,0.0767136737704277
,3751799974.3392,47.2746887207031,,,0.0745358839631081,0.0746048837900162
,3751799974.3592,47.4496879577637,,,0.0724850371479988,0.0725521594285965
,3751799974.3792,47.6246871948242,,,0.0704908594489098,0.070556104183197
,3751799974.3992,47.7996864318848,,,0.068553701043129,0.0686170533299446
,3751799974.4192,47.9746856689453,,,0.0666735023260117,0.0667349696159363
,3751799974.4392,48.1496887207031,,,0.0648501068353653,0.0649096965789795
,3751799974.4592,48.3246879577637,,,0.0630831569433212,0.0631408840417862
,3751799974.4792,48.4996871948242,,,0.0613720007240772,0.0614278838038445
,3751799974.4992,48.6746864318848,,,0.0597159378230572,0.0597700104117394
,3751799974.5192,48.8496856689453,,,0.0581141225993633,0.0581664107739925
,3751799974.5392,49.0246887207031,,,0.0565656125545502,0.0566161535680294