File: examples/report_creation/example_dir/sample_ID/qd_files/101022_00001.dat
[Header]
; MPMS3 Data File (default extension .dat)
; Copyright (c) 2007, Quantum Design, Inc. All rights reserved.
TITLE,
FILEOPENTIME,3874580582.29837,10/10/2022,4:23 pm
BYAPP,MPMS3 w/ AC,1.0,1.1
INFO,MPMS3 Measurement Release 1.1.16 Build 424, MultiVu Release 2.3.4.19,APPNAME
INFO,Linear Motor Servo Controller,MOTOR_MODULE_NAME
INFO,3101-100 J0,MOTOR_HW_VERSION
INFO,MMC721,MOTOR_SERIAL_NUMBER
INFO,01.04.28,MOTOR_SOFTWARE_VERSION
INFO,Quantum Design Squid Module,SQUID_MODULE_NAME
INFO,3101-501 B0,SQUID_HW_VERSION
INFO,SQM195,SQUID_SERIAL_NUMBER
INFO,01.03.04,SQUID_SOFTWARE_VERSION
INFO,SQUID AC,AC_MODULE_NAME
INFO,3101-401 f1,AC_HW_VERSION
INFO,SAC107,AC_SERIAL_NUMBER
INFO,SQUID AC 00.95.07,AC_SOFTWARE_VERSION
INFO,TCI166,COIL_SERIAL_NUMBER
INFO,0,MOMENT_UNITS
INFO,Quidel - 101022,SAMPLE_MATERIAL
INFO,,SAMPLE_COMMENT
INFO,1.38,SAMPLE_MASS
INFO,,SAMPLE_VOLUME
INFO,,SAMPLE_MOLECULAR_WEIGHT
INFO,,SAMPLE_SIZE
INFO,,SAMPLE_SHAPE
INFO,Brass,SAMPLE_HOLDER
INFO,Standard,SAMPLE_HOLDER_DETAIL
INFO,64.25,SAMPLE_OFFSET
DATATYPE,COMMENT,1
DATATYPE,TIME,2
STARTUPAXIS,X,2
STARTUPAXIS,Y1,5
FIELDGROUP, VSM,2,3,4,5,6,8,9,10,11,14,15
FIELDGROUP, DC, 2,3,4,14,56,57,58,59,60,61,62,63,64,65,66,67,68,69
FIELDGROUP, AC, 2,3,4,11,16,17,18,19,20,21,22,23,24,25,26,27,28,29,30
STARTUPGROUP, All
[Data]
Comment,Time Stamp (sec),Temperature (K),Magnetic Field (Oe),Moment (emu),M. Std. Err. (emu),Transport Action,Averaging Time (sec),Frequency (Hz),Peak Amplitude (mm),Center Position (mm),Lockin Signal' (V),Lockin Signal (V),Range,M. Quad. Signal (emu),AC Moment (emu),AC M. Std Err. (emu),AC Phase (deg),AC Phase Std. Err. (deg),AC Susceptibility (emu/Oe),AC Suscept. Std Err. (emu/Oe),AC X' (emu/Oe),AC X' Std Err. (emu/Oe),AC X'' (emu/Oe),AC X'' Std Err. (emu/Oe),AC Drive (Oe),AC Frequency (Hz),AC Averaging Time (sec),AC Cycles,AC Range,AC Measure Type,AC Signal' (V),AC Signal'' (V),AC Trim Coil Ratio,AC Trim Coil Phase,Min. Temperature (K),Max. Temperature (K),Min. Field (Oe),Max. Field (Oe),Mass (grams),Motor Lag (deg),Pressure (Torr),Measure Count,Measurement Number,SQUID Status (code),Motor Status (code),Measure Status (code),Motor Current (amps),Motor Temp. (C),Temp. Status (code),Field Status (code),Chamber Status (code),Chamber Temp (K),Redirection State,Evercool Status,Average Temp (K),Rotation Angle (deg),Rotator state,DC Moment Fixed Ctr (emu),DC Moment Err Fixed Ctr (emu),DC Moment Free Ctr (emu),DC Moment Err Free Ctr (emu),DC Fixed Fit,DC Free Fit,DC Calculated Center (mm),DC Calculated Center Err (mm),DC Scan Length (mm),DC Scan Time (s),DC Number of Points,DC Squid Drift,DC Min V (V),DC Max V (V),DC Scans per Measure,Map 01,Map 02,Map 03,Map 04,Map 05,Map 06,Map 07,Map 08,Map 09,Map 10,Map 11,Map 12,Map 13,Map 14,Map 15,Map 16
"ZFC, 100",3874580582.41911
,3874581535.65665,7.63694882392883,100.072647094727,6.26426761245841E-5,1.09590679502265E-8,1,2,13.0063810348511,4.99337181454871,33.7399989366531,0.0808373254691776,0.0120527207581229,1,1.72724114995028E-7,,,,,,,,,,,,,,,,,,,,,7.56904411315918,7.70485353469849,100.072647094727,100.072647094727,55.2791137655635,5.5166053287031,4.32199764251709,26,1,0,0,1,0.286178588867187,31.7693061828613,6,1,1,7.70485353469849,0,4232058624,7.63694882392883,,,,,,,,,,,,,,,,,,,,,,,,,,,,,,,,,
,3874581573.646,10.5875582695007,100.072647094727,6.74862032422216E-5,1.90506234158916E-8,1,2,13.0063810348511,4.99339725652176,33.7399989366531,0.0870923327898604,0.0129570324949612,1,1.64625555948615E-7,,,,,,,,,,,,,,,,,,,,,10.5012979507446,10.6738185882568,100.072647094727,100.072647094727,55.1509266884097,5.5169529799913,4.71157932281494,26,1,0,0,1,0.285797119140625,32.2580642700195,6,1,1,10.6738185882568,0,4232058656,10.5875582695007,,,,,,,,,,,,,,,,,,,,,,,,,,,,,,,,,
,3874581611.6747,13.5785784721375,100.072647094727,7.45605656446329E-5,2.6578156886331E-8,1,2,13.0063810348511,4.99340007267761,33.7399989366531,0.096220265000126,0.0143272766792584,1,1.91169232357381E-7,,,,,,,,,,,,,,,,,,,,,13.5209560394287,13.6362009048462,100.072647094727,100.072647094727,55.2709066661116,5.51677533439821,4.99222612380981,26,1,0,0,1,0.285568237304687,32.2580642700195,6,1,1,13.6362009048462,0,4232058656,13.5785784721375,,,,,,,,,,,,,,,,,,,,,,,,,,,,,,,,,
,3874581649.59073,16.6822338104248,100.072647094727,8.50010465569507E-5,3.93936158521997E-8,1,2,13.0063810348511,4.99322938135728,33.7399989366531,0.109693319621078,0.0162993930147801,1,1.92137000395524E-7,,,,,,,,,,,,,,,,,,,,,16.612943649292,16.7515239715576,100.072647094727,100.072647094727,55.2564465385058,5.51778219077915,5.84114551544189,26,1,0,0,1,0.286865234375,32.2580642700195,2,1,1,16.7515239715576,0,4232058880,16.6822338104248,,,,,,,,,,,,,,,,,,,,,,,,,,,,,,,,,
,3874581687.57402,19.7081661224365,100.072647094727,9.76620710121283E-5,4.01484251065871E-8,1,2,13.0063810348511,4.99291422325417,33.7399989366531,0.126010876939189,0.0187959942056849,1,2.75322765042311E-7,,,,,,,,,,,,,,,,,,,,,19.6159553527832,19.8003768920898,100.072647094727,100.072647094727,55.2752056229674,5.51955332199918,5.9718861579895,26,1,0,0,1,0.288619995117188,32.2580642700195,2,1,1,19.8003768920898,0,4232058720,19.7081661224365,,,,,,,,,,,,,,,,,,,,,,,,,,,,,,,,,
,3874581725.56412,22.7468280792236,100.072647094727,0.000111739813827616,4.30405098492658E-8,1,2,13.0063810348511,4.99273976081506,33.7399989366531,0.144171216241855,0.0214822937171492,1,2.9792963305105E-7,,,,,,,,,,,,,,,,,,,,,22.67822265625,22.8154335021973,100.072647094727,100.072647094727,55.3580582460059,5.52051027003189,6.09468793869018,26,1,0,0,1,0.287322998046875,32.2580642700195,2,1,1,22.8154335021973,0,4232058720,22.7468280792236,,,,,,,,,,,,,,,,,,,,,,,,,,,,,,,,,
,3874581763.56684,25.7544069290161,100.072647094727,0.000127855349459497,5.07937586431542E-8,1,2,13.0063810348511,4.99248966877958,33.7500013411045,0.164952318730127,0.0245806600006689,1,3.42315545362898E-7,,,,,,,,,,,,,,,,,,,,,25.6766357421875,25.8321781158447,100.072647094727,100.072647094727,55.4893718372366,5.5209625727036,6.23680591583252,26,1,0,0,1,0.288238525390625,32.7468223571777,2,1,1,25.8321781158447,0,4232058592,25.7544069290161,,,,,,,,,,,,,,,,,,,,,,,,,,,,,,,,,
,3874581801.54659,28.7828073501587,100.072647094727,0.000146075163285746,5.39708105785674E-8,1,2,13.0063810348511,4.99243479793952,33.7500013411045,0.188464954646524,0.0280196561853345,1,3.41974546824609E-7,,,,,,,,,,,,,,,,,,,,,28.7067718505859,28.8588428497314,100.072647094727,100.072647094727,55.2900565648328,5.52195568558073,6.29240465164185,26,1,0,0,1,0.2886962890625,31.7693061828613,2,1,1,28.8588428497314,0,4232058784,28.7828073501587,,,,,,,,,,,,,,,,,,,,,,,,,,,,,,,,,
,3874581839.50487,31.8148431777954,100.072647094727,0.00016544354485043,6.44431340104772E-8,1,2,13.0063810348511,4.992377937673,33.7500013411045,0.213436287317844,0.031831368226981,1,4.62505058517059E-7,,,,,,,,,,,,,,,,,,,,,31.7338123321533,31.8958740234375,100.072647094727,100.072647094727,55.1700765871308,5.52214385258186,6.36472415924072,26,1,0,0,1,0.287933349609375,32.7468223571777,2,1,1,31.8958740234375,0,4232058656,31.8148431777954,,,,,,,,,,,,,,,,,,,,,,,,,,,,,,,,,
,3874581877.51978,34.8515071868897,100.072647094727,0.000184665486424659,6.06313054779904E-8,1,2,13.0063810348511,4.9923044026783,33.7500013411045,0.238232485906943,0.0355073623765378,1,4.99519995402007E-7,,,,,,,,,,,,,,,,,,,,,34.7648963928223,34.938117980957,100.072647094727,100.072647094727,55.1556164595251,5.52257045006111,6.4508228302002,26,1,0,0,1,0.2880859375,32.7468223571777,2,1,1,34.938117980957,0,4232058816,34.8515071868897,,,,,,,,,,,,,,,,,,,,,,,,,,,,,,,,,
,3874581915.46898,37.8984699249268,100.072647094727,0.000202124365887514,5.06110720722654E-8,1,2,13.0063810348511,4.99221837360203,33.7500013411045,0.260749025332417,0.0388665635848558,1,5.49190676366525E-7,,,,,,,,,,,,,,,,,,,,,37.8323936462402,37.9645462036133,100.072647094727,100.072647094727,55.417852827727,5.52225320657978,6.47640085220337,26,1,0,0,1,0.2886962890625,33.2355842590332,2,1,1,37.9645462036133,0,4232058688,37.8984699249268,,,,,,,,,,,,,,,,,,,,,,,,,,,,,,,,,
,3874581953.47492,41.0064086914063,100.072647094727,0.000216540358937373,4.93771373746347E-8,1,2,13.0063810348511,4.99219591708782,33.7600000202656,0.27936512465344,0.0414974577556373,1,4.79181493390059E-7,,,,,,,,,,,,,,,,,,,,,40.9053955078125,41.107421875,100.072647094727,100.072647094727,55.1778928723231,5.52203276704579,6.55825662612915,26,1,0,0,1,0.287933349609375,32.2580642700195,2,1,1,41.107421875,0,4232058656,41.0064086914063,,,,,,,,,,,,,,,,,,,,,,,,,,,,,,,,,
,3874581991.43009,44.0039939880371,100.072647094727,0.000227515626535067,4.0410247530002E-8,1,2,13.0063810348511,4.99220423678448,33.7500013411045,0.293503378331083,0.0437508774892998,1,6.19725225483495E-7,,,,,,,,,,,,,,,,,,,,,43.9222831726074,44.0857048034668,100.072647094727,100.072647094727,55.377208144727,5.5224517082244,6.59749507904053,26,1,0,0,1,0.2874755859375,33.7243423461914,2,1,1,44.0857048034668,0,4232058624,44.0039939880371,,,,,,,,,,,,,,,,,,,,,,,,,,,,,,,,,
,3874582029.40668,47.0742416381836,100.072647094727,0.000235409077276012,3.70109538949431E-8,1,2,13.0063810348511,4.99217042259202,33.7500013411045,0.303700210324537,0.0451530252418415,1,5.51866940816745E-7,,,,,,,,,,,,,,,,,,,,,46.9947395324707,47.1537437438965,100.072647094727,100.072647094727,55.1134085194866,5.52275967531854,6.62377548217773,26,1,0,0,1,0.288314819335937,33.2355842590332,2,1,1,47.1537437438965,0,4232058752,47.0742416381836,,,,,,,,,,,,,,,,,,,,,,,,,,,,,,,,,
,3874582067.38505,50.1084899902344,100.072647094727,0.000241430416540902,4.1548355395004E-8,1,2,13.0063810348511,4.9921999137628,33.7600000202656,0.311448399097308,0.0464620527313483,1,6.85088923298615E-7,,,,,,,,,,,,,,,,,,,,,50.0172805786133,50.1996994018555,100.072647094727,100.072647094727,55.3267931052366,5.52131287903028,6.68902730941772,26,1,0,0,1,0.289840698242188,32.7468223571777,2,1,1,50.1996994018555,0,4232058624,50.1084899902344,,,,,,,,,,,,,,,,,,,,,,,,,,,,,,,,,
,3874582105.37125,53.2139205932617,100.072647094727,0.000246081782779916,3.14676615143462E-8,1,2,13.0063810348511,4.99212828351781,33.7699986994266,0.317460087498056,0.0472350365846098,1,6.04373515124999E-7,,,,,,,,,,,,,,,,,,,,,53.1322441101074,53.295597076416,100.072647094727,100.072647094727,55.2630903809193,5.52321674850332,6.6996545791626,26,1,0,0,1,0.288543701171875,33.2355842590332,2,1,1,53.295597076416,0,4232058816,53.2139205932617,,,,,,,,,,,,,,,,,,,,,,,,,,,,,,,,,
,3874582143.36727,56.2755928039551,100.072647094727,0.000249608470065335,3.59894070045148E-8,1,2,13.0063810348511,4.9921053203449,33.7600000202656,0.321996928123032,0.0479849923259762,1,6.69850505139485E-7,,,,,,,,,,,,,,,,,,,,,56.2035751342773,56.3476104736328,100.072647094727,100.072647094727,55.361966388602,5.52287934472157,6.72859621047974,26,1,0,0,1,0.288848876953125,32.7468223571777,2,1,1,56.3476104736328,0,4232058688,56.2755928039551,,,,,,,,,,,,,,,,,,,,,,,,,,,,,,,,,
,3874582181.34732,59.3542060852051,100.072647094727,0.000252607268914427,2.8826380547661E-8,1,2,13.0063810348511,4.99210521258423,33.7600000202656,0.325870635373401,0.0485256444288744,1,6.50127277030459E-7,,,,,,,,,,,,,,,,,,,,,59.2862815856934,59.4221305847168,100.072647094727,100.072647094727,55.5179012781886,5.52269595801958,6.79104423522949,26,1,0,0,1,0.289840698242188,33.2355842590332,2,1,1,59.4221305847168,0,4232058592,59.3542060852051,,,,,,,,,,,,,,,,,,,,,,,,,,,,,,,,,
,3874582219.33443,62.4268741607666,100.072647094727,0.000255158294686025,4.02622854416554E-8,1,2,13.0063810348511,4.99212791991985,33.7699986994266,0.329169391099622,0.0489765800963203,1,6.26142550596012E-7,,,,,,,,,,,,,,,,,,,,,62.3526496887207,62.5010986328125,100.072647094727,100.072647094727,55.2177559268039,5.52351474731431,6.77639389038086,26,1,0,0,1,0.289459228515625,32.7468223571777,2,1,1,62.5010986328125,0,4232058624,62.4268741607666,,,,,,,,,,,,,,,,,,,,,,,,,,,,,,,,,
,3874582257.33228,65.5033836364746,100.072647094727,0.000257250121693764,3.33542989470035E-8,1,2,13.0063810348511,4.99207309505674,33.7600000202656,0.331862812752394,0.0493778008473254,1,6.31632894607085E-7,,,,,,,,,,,,,,,,,,,,,65.4210739135742,65.585693359375,100.072647094727,100.072647094727,55.4577158822078,5.52314844372669,6.80138683319092,26,1,0,0,1,0.288925170898438,32.7468223571777,2,1,1,65.585693359375,0,4232058624,65.5033836364746,,,,,,,,,,,,,,,,,,,,,,,,,,,,,,,,,
,3874582295.29113,68.608757019043,100.072647094727,0.000258925678204086,4.13495943486082E-8,1,2,13.0063810348511,4.99206103222663,33.7699986994266,0.334014338145106,0.0497599586114095,1,6.82791806180962E-7,,,,,,,,,,,,,,,,,,,,,68.5284194946289,68.689094543457,100.072647094727,100.072647094727,55.280677022602,5.52347936220624,6.85459184646606,26,1,0,0,1,0.28900146484375,33.2355842590332,2,1,1,68.689094543457,0,4232058688,68.608757019043,,,,,,,,,,,,,,,,,,,,,,,,,,,,,,,,,
,3874582333.28534,71.6670150756836,100.072647094727,0.000260300769040693,3.75795558668321E-8,1,2,13.0063810348511,4.9918633948275,33.7699986994266,0.335770438242853,0.050015941525664,1,6.82145820631389E-7,,,,,,,,,,,,,,,,,,,,,71.601448059082,71.7325820922852,100.072647094727,100.072647094727,55.3350002046886,5.52441457551634,6.83007097244263,26,1,0,0,1,0.29022216796875,33.2355842590332,2,1,1,71.7325820922852,0,4232058656,71.6670150756836,,,,,,,,,,,,,,,,,,,,,,,,,,,,,,,,,
,3874582371.25712,74.7576446533203,100.072647094727,0.000261447328984503,4.83171888603895E-8,1,2,13.0063810348511,4.99172068270718,33.7699986994266,0.337247985439624,0.0501519754701784,1,6.21396171682822E-7,,,,,,,,,,,,,,,,,,,,,74.6750335693359,74.8402557373047,100.072647094727,100.072647094727,55.3947947864097,5.52459087947884,6.8759708404541,26,1,0,0,1,0.289993286132812,32.7468223571777,2,1,1,74.8402557373047,0,4232058624,74.7576446533203,,,,,,,,,,,,,,,,,,,,,,,,,,,,,,,,,
,3874582409.22423,77.8649597167969,100.072647094727,0.000262174118665165,3.25307244314953E-8,1,2,13.0063810348511,4.9918193639739,33.7699986994266,0.338182896790087,0.0503743771310903,1,6.86356489571888E-7,,,,,,,,,,,,,,,,,,,,,77.7883148193359,77.9416046142578,100.072647094727,100.072647094727,55.2458945534962,5.52447651503584,6.89151239395142,26,1,0,0,1,0.289077758789063,33.7243423461914,2,1,1,77.9416046142578,0,4232058656,77.8649597167969,,,,,,,,,,,,,,,,,,,,,,,,,,,,,,,,,
,3874582447.24223,80.9606513977051,100.072647094727,0.000262723812982099,3.06371926625155E-8,1,2,13.0063810348511,4.99183954295907,33.7899997830391,0.338900264533443,0.0504365745352058,1,6.53925542941287E-7,,,,,,,,,,,,,,,,,,,,,80.8845748901367,81.0367279052734,100.072647094727,100.072647094727,55.2337793114482,5.52391490489529,6.88927125930786,26,1,0,0,1,0.289688110351562,33.2355842590332,2,1,1,81.0367279052734,0,4232058656,80.9606513977051,,,,,,,,,,,,,,,,,,,,,,,,,,,,,,,,,
,3874582485.21402,84.0606155395508,100.072647094727,0.000263064568434232,4.14747991586861E-8,1,2,13.0063810348511,4.99188388151576,33.780001103878,0.339348069024059,0.0504750277439969,1,6.33393058416575E-7,,,,,,,,,,,,,,,,,,,,,83.9779586791992,84.1432723999023,100.072647094727,100.072647094727,55.3334369476501,5.5241169041409,6.94503402709961,26,1,0,0,1,0.288467407226562,33.2355842590332,2,1,1,84.1432723999023,0,4232058624,84.0606155395508,,,,,,,,,,,,,,,,,,,,,,,,,,,,,,,,,
,3874582523.16994,87.1780776977539,100.072647094727,0.000263198730343325,2.95203320491864E-8,1,2,13.0063810348511,4.99186021606402,33.780001103878,0.339519270504981,0.050497808150532,1,6.31680216123139E-7,,,,,,,,,,,,,,,,,,,,,87.1084671020508,87.247688293457,100.072647094727,100.072647094727,55.5413501337655,5.52352561337531,6.94325685501099,26,1,0,0,1,0.289154052734375,33.7243423461914,2,1,1,87.247688293457,0,4232058752,87.1780776977539,,,,,,,,,,,,,,,,,,,,,,,,,,,,,,,,,
,3874582561.19337,90.3529281616211,100.072647094727,0.000263232422430298,3.3303912805188E-8,1,2,13.0063810348511,4.99185491884083,33.780001103878,0.339569296175749,0.0504558845486947,1,5.94321492986218E-7,,,,,,,,,,,,,,,,,,,,,90.2720336914062,90.4338226318359,100.072647094727,100.072647094727,55.2791137655635,5.52437518481428,6.94667434692383,26,1,0,0,1,0.289459228515625,33.7243423461914,2,1,1,90.4338226318359,0,4232058656,90.3529281616211,,,,,,,,,,,,,,,,,,,,,,,,,,,,,,,,,
,3874582599.14394,93.4745368957519,100.072647094727,0.000262907987108265,3.77698909996009E-8,1,2,13.0063810348511,4.99192063333439,33.7899997830391,0.339154377047458,0.0504126481640558,1,6.07556087900432E-7,,,,,,,,,,,,,,,,,,,,,93.3908538818359,93.558219909668,100.072647094727,100.072647094727,55.3944039721501,5.52387334936862,6.99877643585205,26,1,0,0,1,0.289230346679687,34.7018585205078,2,1,1,93.558219909668,0,4232058592,93.4745368957519,,,,,,,,,,,,,,,,,,,,,,,,,,,,,,,,,
,3874582637.11617,96.6144714355469,100.072647094727,0.000262622702426653,4.07923818761407E-8,1,2,13.0063810348511,4.99196168326801,33.7999984622002,0.338794102538447,0.0503321806470163,1,5.86483413708512E-7,,,,,,,,,,,,,,,,,,,,,96.5304183959961,96.6985244750977,100.072647094727,100.072647094727,55.3432073041405,5.52385562022936,6.96940326690674,26,1,0,0,1,0.289459228515625,33.2355842590332,2,1,1,96.6985244750977,0,4232058624,96.6144714355469,,,,,,,,,,,,,,,,,,,,,,,,,,,,,,,,,
,3874582675.12052,99.7576217651367,100.072647094727,0.000262173686340543,3.15787743987386E-8,1,2,13.0063810348511,4.99191236498048,33.7899997830391,0.338209991417,0.0502467525034087,1,5.86503826096863E-7,,,,,,,,,,,,,,,,,,,,,99.6723403930664,99.842903137207,100.072647094727,100.072647094727,55.3928407151116,5.52419972430827,6.99407911300659,26,1,0,0,1,0.288848876953125,33.2355842590332,2,1,1,99.842903137207,0,4232058624,99.7576217651367,,,,,,,,,,,,,,,,,,,,,,,,,,,,,,,,,
,3874582713.07837,102.909198760986,100.072647094727,0.000261615545901881,2.99080227752907E-8,1,2,13.0063810348511,4.99190767061745,33.7999984622002,0.337486421037113,0.0501609983528944,1,6.01747094902364E-7,,,,,,,,,,,,,,,,,,,,,102.84001159668,102.978385925293,100.072647094727,100.072647094727,55.4010478145636,5.52381316408037,7.04067325592041,26,1,0,0,1,0.28961181640625,33.2355842590332,2,1,1,102.978385925293,0,4232058656,102.909198760986,,,,,,,,,,,,,,,,,,,,,,,,,,,,,,,,,
,3874582751.05799,106.033599853516,100.072647094727,0.000260962022744561,3.04686160491868E-8,1,2,13.0063810348511,4.99191828136092,33.7999984622002,0.336653191576279,0.0499755381689058,1,5.53511913453586E-7,,,,,,,,,,,,,,,,,,,,,105.964508056641,106.102691650391,100.072647094727,100.072647094727,55.499142193727,5.52421961840812,7.01785087585449,26,1,0,0,1,0.289154052734375,33.2355842590332,2,1,1,106.102691650391,0,4232058656,106.033599853516,,,,,,,,,,,,,,,,,,,,,,,,,,,,,,,,,
,3874582789.05131,109.185962677002,100.072647094727,0.000260180276319825,4.12787775599977E-8,1,2,13.0063810348511,4.99192304661145,33.8100008666515,0.335636181929438,0.0498872025568656,1,5.99361528585902E-7,,,,,,,,,,,,,,,,,,,,,109.111785888672,109.260139465332,100.072647094727,100.072647094727,55.2931830789097,5.52387548183352,7.0554986000061,26,1,0,0,1,0.288772583007812,33.7243423461914,2,1,1,109.260139465332,0,4232058688,109.185962677002,,,,,,,,,,,,,,,,,,,,,,,,,,,,,,,,,
,3874582827.05841,112.344551086426,100.072647094727,0.000259394096766794,3.92719034862396E-8,1,2,13.0063810348511,4.99182883798627,33.8100008666515,0.334616191425758,0.0497145318380419,1,5.81573865624491E-7,,,,,,,,,,,,,,,,,,,,,112.260696411133,112.428405761719,100.072647094727,100.072647094727,55.4291864412559,5.52452064019169,7.05023193359375,26,1,0,0,1,0.289306640625,32.7468223571777,2,1,1,112.428405761719,0,4232058592,112.344551086426,,,,,,,,,,,,,,,,,,,,,,,,,,,,,,,,,
,3874582865.00633,115.486236572266,100.072647094727,0.000258567517662692,3.66784659654755E-8,1,2,13.0063810348511,4.99188492620759,33.8100008666515,0.333561093040281,0.0495162494249373,1,5.48226393019241E-7,,,,,,,,,,,,,,,,,,,,,115.409828186035,115.562644958496,100.072647094727,100.072647094727,55.275596437227,5.52435458868571,7.05043458938599,26,1,0,0,1,0.289459228515625,33.7243423461914,2,1,1,115.562644958496,0,4232058624,115.486236572266,,,,,,,,,,,,,,,,,,,,,,,,,,,,,,,,,
,3874582903.03587,118.643486022949,100.072647094727,0.000257595888614831,3.56603458622659E-8,1,2,13.0063810348511,4.99175615026503,33.8199995458126,0.332286473243857,0.0493913386267643,1,5.94939539263596E-7,,,,,,,,,,,,,,,,,,,,,118.574119567871,118.712852478027,100.072647094727,100.072647094727,55.3271839194962,5.52453603876641,7.10676288604736,26,1,0,0,1,0.2886962890625,33.7243423461914,2,1,1,118.712852478027,0,4232058624,118.643486022949,,,,,,,,,,,,,,,,,,,,,,,,,,,,,,,,,
,3874582940.97797,121.787223815918,100.072647094727,0.000256602993572223,3.20658117256793E-8,1,2,13.0063810348511,4.99182150437049,33.8199995458126,0.331011832497323,0.0492012365490679,1,5.92162156059964E-7,,,,,,,,,,,,,,,,,,,,,121.708221435547,121.866226196289,100.072647094727,100.072647094727,55.3650929026789,5.52473051320958,7.07718133926392,26,1,0,0,1,0.291290283203125,33.7243423461914,2,1,1,121.866226196289,0,4232058720,121.787223815918,,,,,,,,,,,,,,,,,,,,,,,,,,,,,,,,,
,3874582978.93772,124.941287994385,100.072647094727,0.000255642513565851,3.22074402156423E-8,1,2,13.0063810348511,4.99149398062755,33.8299982249737,0.329746683095227,0.0489846841898677,1,5.6832623728943E-7,,,,,,,,,,,,,,,,,,,,,124.857414245605,125.025161743164,100.072647094727,100.072647094727,55.3498511465539,5.52611319008751,7.07082462310791,26,1,0,0,1,0.290451049804687,33.7243423461914,2,1,1,125.025161743164,0,4232058528,124.941287994385,,,,,,,,,,,,,,,,,,,,,,,,,,,,,,,,,
,3874583016.91625,128.12809753418,100.072647094727,0.000254657741036394,3.5726045976713E-8,1,2,13.0063810348511,4.99157597092444,33.8299982249737,0.328483371464933,0.0488013355367283,1,5.69413305142091E-7,,,,,,,,,,,,,,,,,,,,,128.04670715332,128.209487915039,100.072647094727,100.072647094727,55.229871168852,5.52549630228492,7.12062549591064,26,1,0,0,1,0.2886962890625,33.2355842590332,2,1,1,128.209487915039,0,4232058656,128.12809753418,,,,,,,,,,,,,,,,,,,,,,,,,,,,,,,,,
,3874583054.90196,131.226829528809,100.072647094727,0.000253651246576693,4.10424951163719E-8,1,2,13.0063810348511,4.99158388739995,33.840000629425,0.327189760939183,0.0485816088368595,1,5.46272833339153E-7,,,,,,,,,,,,,,,,,,,,,131.157104492188,131.29655456543,100.072647094727,100.072647094727,55.3588398745251,5.5251850715197,7.09879636764526,26,1,0,0,1,0.289840698242188,33.2355842590332,2,1,1,131.29655456543,0,4232058688,131.226829528809,,,,,,,,,,,,,,,,,,,,,,,,,,,,,,,,,
,3874583092.88583,134.380722045898,100.072647094727,0.000252570211953262,3.39901919851773E-8,1,2,13.0063810348511,4.99160812981895,33.840000629425,0.325799098844331,0.0483641212609874,1,5.35600940838856E-7,,,,,,,,,,,,,,,,,,,,,134.29670715332,134.464736938477,100.072647094727,100.072647094727,55.3760357019482,5.52533308754076,7.11303091049194,26,1,0,0,1,0.288925170898438,33.2355842590332,2,1,1,134.464736938477,0,4232058720,134.380722045898,,,,,,,,,,,,,,,,,,,,,,,,,,,,,,,,,
,3874583131.20725,137.609275817871,100.072647094727,0.00025144827550591,4.09982603784507E-8,1,2,13.0063810348511,4.99161783467313,33.8499993085861,0.324342627390999,0.048218650062134,1,5.86878349912029E-7,,,,,,,,,,,,,,,,,,,,,137.552322387695,137.666229248047,100.072647094727,100.072647094727,55.4162895706886,5.52335784132984,7.13697004318237,25,1,64,0,0,0.288772583007812,33.2355842590332,2,1,1,137.666229248047,0,4232058784,137.609275817871,,,,,,,,,,,,,,,,,,,,,,,,,,,,,,,,,
,3874583168.96397,140.70874786377,100.072647094727,0.000250332064766719,3.83685848832582E-8,1,2,13.0063810348511,4.9915901521776,33.8499993085861,0.32290635297929,0.0479630357313791,1,5.52348202234141E-7,,,,,,,,,,,,,,,,,,,,,140.632522583008,140.784973144531,100.072647094727,100.072647094727,55.2881024935347,5.52547368170642,7.1194748878479,24,1,64,0,0,0.290756225585937,33.7243423461914,2,1,1,140.784973144531,0,4232058656,140.70874786377,,,,,,,,,,,,,,,,,,,,,,,,,,,,,,,,,
,3874583207.19293,143.876205444336,100.072647094727,0.000249233504415615,3.14893243093074E-8,1,2,13.0063810348511,4.99165928622929,33.8700003921986,0.32148942421763,0.0477952082947774,1,5.82264235997394E-7,,,,,,,,,,,,,,,,,,,,,143.812088012695,143.940322875977,100.072647094727,100.072647094727,55.3920590865924,5.52537767034072,7.17269515991211,24,1,64,0,0,0.289993286132812,33.7243423461914,2,1,1,143.940322875977,0,4232058656,143.876205444336,,,,,,,,,,,,,,,,,,,,,,,,,,,,,,,,,
,3874583244.91316,147.020805358887,100.072647094727,0.00024810657319627,3.00218352645158E-8,1,2,13.0063810348511,4.99158984860247,33.8600017130375,0.320034354959332,0.0475453992444608,1,5.54231755032432E-7,,,,,,,,,,,,,,,,,,,,,146.953475952148,147.088134765625,100.072647094727,100.072647094727,55.4260599271789,5.52555134720161,7.16124391555786,24,1,64,0,0,0.289840698242188,33.7243423461914,2,1,1,147.088134765625,0,4232058656,147.020805358887,,,,,,,,,,,,,,,,,,,,,,,,,,,,,,,,,
,3874583282.80247,150.133422851562,100.072647094727,0.000246968772997874,3.69454924312207E-8,1,2,13.0063810348511,4.99145627562085,33.8799990713596,0.318559417486035,0.0472939337312201,1,5.27156027027062E-7,,,,,,,,,,,,,,,,,,,,,150.058624267578,150.208221435547,100.072647094727,100.072647094727,55.4100365425347,5.52379906411291,7.13092279434204,26,1,0,0,1,0.28900146484375,33.7243423461914,2,1,1,150.208221435547,0,4232058784,150.133422851562,,,,,,,,,,,,,,,,,,,,,,,,,,,,,,,,,
,3874583320.77976,153.27710723877,100.072647094727,0.000245861703240581,2.85309022180052E-8,1,2,13.0063810348511,4.99167210290421,33.8700003921986,0.317150182685155,0.0470875925070684,1,5.26974778610771E-7,,,,,,,,,,,,,,,,,,,,,153.205947875977,153.348266601562,100.072647094727,100.072647094727,55.3412532328424,5.52485204943194,7.20844459533691,26,1,0,0,1,0.289382934570313,33.7243423461914,2,1,1,153.348266601562,0,4232058688,153.27710723877,,,,,,,,,,,,,,,,,,,,,,,,,,,,,,,,,
,3874583358.78013,156.479858398438,100.072647094727,0.000244707556367793,2.95025421709177E-8,1,2,13.0063810348511,4.99171719470298,33.8799990713596,0.315669492069979,0.0468389702841258,1,5.0266948403241E-7,,,,,,,,,,,,,,,,,,,,,156.38752746582,156.572189331055,100.072647094727,100.072647094727,55.3494603322943,5.52508654739237,7.17803001403809,26,1,0,0,1,0.2886962890625,33.7243423461914,2,1,1,156.572189331055,0,4232058656,156.479858398438,,,,,,,,,,,,,,,,,,,,,,,,,,,,,,,,,
,3874583396.74281,159.697944641113,100.072647094727,0.000243523970575949,3.64779956677313E-8,1,2,13.0063810348511,4.9916644284677,33.890001475811,0.314132252746779,0.0466513109658141,1,5.30909518166876E-7,,,,,,,,,,,,,,,,,,,,,159.616241455078,159.779647827148,100.072647094727,100.072647094727,55.3760357019482,5.52513516745981,7.19708871841431,26,1,0,0,1,0.289382934570313,34.2131004333496,2,1,1,159.779647827148,0,4232058752,159.697944641113,,,,,,,,,,,,,,,,,,,,,,,,,,,,,,,,,
,3874583434.70711,162.74284362793,100.072647094727,0.000242453722113403,3.48930052852077E-8,1,2,13.0063810348511,4.991777622063,33.890001475811,0.312760684828777,0.0464540285331886,1,5.33435879947866E-7,,,,,,,,,,,,,,,,,,,,,162.653839111328,162.831848144531,100.072647094727,100.072647094727,55.4459914544193,5.5249806214923,7.21407604217529,26,1,0,0,1,0.290069580078125,33.7243423461914,2,1,1,162.831848144531,0,4232058720,162.74284362793,,,,,,,,,,,,,,,,,,,,,,,,,,,,,,,,,
,3874583472.70435,165.886825561523,100.072647094727,0.00024129869232709,4.07372453075599E-8,1,2,13.0063810348511,4.99171520242796,33.890001475811,0.311270114065868,0.0461988695357374,1,5.0528345363926E-7,,,,,,,,,,,,,,,,,,,,,165.818878173828,165.954772949219,100.072647094727,100.072647094727,55.3971396719674,5.52462273910448,7.18688583374023,26,1,0,0,1,0.28900146484375,33.7243423461914,2,1,1,165.954772949219,0,4232058688,165.886825561523,,,,,,,,,,,,,,,,,,,,,,,,,,,,,,,,,
,3874583510.7176,169.027893066406,100.072647094727,0.000240229661669134,3.94104765332133E-8,1,2,13.0063810348511,4.99184033835723,33.9000001549721,0.30989558391092,0.0460392729980714,1,5.36730216978319E-7,,,,,,,,,,,,,,,,,,,,,168.947509765625,169.108276367187,100.072647094727,100.072647094727,55.4440373831213,5.52423672221263,7.22595596313477,26,1,0,0,1,0.289077758789063,33.7243423461914,2,1,1,169.126419067383,0,4232058560,169.027893066406,,,,,,,,,,,,,,,,,,,,,,,,,,,,,,,,,
,3874583548.96614,172.220962524414,100.072647094727,0.000239087130336719,2.61431838382789E-8,1,2,13.0063810348511,4.99188220679275,33.9099988341331,0.308424475236957,0.0458267332590063,1,5.38738692235814E-7,,,,,,,,,,,,,,,,,,,,,172.162780761719,172.279144287109,100.072647094727,100.072647094727,55.3072523922559,5.52289464445733,7.21867990493774,24,1,64,0,0,0.288772583007812,33.7243423461914,2,1,1,172.279144287109,0,4232058592,172.220962524414,,,,,,,,,,,,,,,,,,,,,,,,,,,,,,,,,
,3874583586.67573,175.413146972656,100.072647094727,0.000237919175437076,2.7609517722769E-8,1,2,13.0063810348511,4.99184031047665,33.9099988341331,0.306917011027274,0.0455831431198063,1,5.21236536161125E-7,,,,,,,,,,,,,,,,,,,,,175.332122802734,175.494171142578,100.072647094727,100.072647094727,55.4784290379674,5.52446082201301,7.20576858520508,26,1,0,0,1,0.289154052734375,33.7243423461914,2,1,1,175.494171142578,0,4232058784,175.413146972656,,,,,,,,,,,,,,,,,,,,,,,,,,,,,,,,,
,3874583624.63145,178.514450073242,100.072647094727,0.000236718675297939,3.58950638962834E-8,1,2,13.0063810348511,4.99183555113237,33.9299999177456,0.3053732904029,0.0453165878275608,1,4.90328787022258E-7,,,,,,,,,,,,,,,,,,,,,178.446807861328,178.582092285156,100.072647094727,100.072647094727,55.4796014807463,5.52440768263537,7.25663375854492,26,1,0,0,1,0.290069580078125,33.7243423461914,2,1,1,178.582092285156,0,4232058688,178.514450073242,,,,,,,,,,,,,,,,,,,,,,,,,,,,,,,,,
,3874583662.5987,181.65266418457,100.072647094727,0.000235645433988844,3.11320678634458E-8,1,2,13.0063810348511,4.99182503333958,33.9299999177456,0.303984835210808,0.0451318535219049,1,5.04268009032564E-7,,,,,,,,,,,,,,,,,,,,,181.579055786133,181.726272583008,100.072647094727,100.072647094727,55.3869785012174,5.52395541125466,7.23763608932495,26,1,0,0,1,0.289306640625,33.7243423461914,2,1,1,181.726272583008,0,4232058720,181.65266418457,,,,,,,,,,,,,,,,,,,,,,,,,,,,,,,,,
,3874583700.88339,184.825813293457,100.072647094727,0.000234548301050371,3.84793430956782E-8,1,2,13.0063810348511,4.99183803859976,33.9399985969067,0.302570160552089,0.0449250630381234,1,5.04379664297451E-7,,,,,,,,,,,,,,,,,,,,,184.768890380859,184.882736206055,100.072647094727,100.072647094727,55.5819948167655,5.52430491498638,7.26181173324585,25,1,64,0,0,0.289535522460937,33.2355842590332,2,1,1,184.882736206055,0,4232058688,184.825813293457,,,,,,,,,,,,,,,,,,,,,,,,,,,,,,,,,
,3874583738.57549,187.947860717773,100.072647094727,0.000233405793673665,4.26244231718588E-8,1,2,13.0063810348511,4.99183824271121,33.9399985969067,0.301097411012043,0.0446988368380775,1,4.96192513498484E-7,,,,,,,,,,,,,,,,,,,,,187.86572265625,188.029998779297,100.072647094727,100.072647094727,55.4225425988424,5.52444284134346,7.28225946426392,26,1,0,0,1,0.289840698242188,33.2355842590332,2,1,1,188.029998779297,0,4232058656,187.947860717773,,,,,,,,,,,,,,,,,,,,,,,,,,,,,,,,,
,3874583776.54581,191.101623535156,100.072647094727,0.000232296912351017,3.23487355909628E-8,1,2,13.0063810348511,4.99196741061185,33.9599996805191,0.299678887175863,0.044480448901814,1,4.87916486842571E-7,,,,,,,,,,,,,,,,,,,,,191.020294189453,191.182952880859,100.072647094727,100.072647094727,55.280677022602,5.52476269820677,7.25842714309692,26,1,0,0,1,0.289764404296875,33.2355842590332,2,1,1,191.182952880859,0,4232058752,191.101623535156,,,,,,,,,,,,,,,,,,,,,,,,,,,,,,,,,
,3874583814.53416,194.246162414551,100.072647094727,0.000231181573837487,2.79596328178651E-8,1,2,13.0063810348511,4.9917634964885,33.950001001358,0.298225141673904,0.0442497299604321,1,4.74239096007495E-7,,,,,,,,,,,,,,,,,,,,,194.169967651367,194.322357177734,100.072647094727,100.072647094727,55.2447221107174,5.52495300223148,7.31085252761841,26,1,0,0,1,0.28961181640625,33.2355842590332,2,1,1,194.322357177734,0,4232058688,194.246162414551,,,,,,,,,,,,,,,,,,,,,,,,,,,,,,,,,
,3874583852.57553,197.412940979004,100.072647094727,0.000230031648204968,3.29135058079798E-8,1,2,13.0063810348511,4.99160367228614,33.9699983596802,0.296727521094784,0.0440340575277945,1,4.76840885995962E-7,,,,,,,,,,,,,,,,,,,,,197.337478637695,197.488403320313,100.072647094727,100.072647094727,55.3529776606309,5.52542945613558,7.3280611038208,26,1,0,0,1,0.28961181640625,33.7243423461914,2,1,1,197.488403320313,0,4232058688,197.412940979004,,,,,,,,,,,,,,,,,,,,,,,,,,,,,,,,,
,3874583890.51228,200.561767578125,100.072647094727,0.000228924872605678,3.10192046421444E-8,1,2,13.0063810348511,4.99161055129973,33.9699983596802,0.295295549000158,0.0438555288984017,1,5.00317188533257E-7,,,,,,,,,,,,,,,,,,,,,200.480239868164,200.643295288086,100.072647094727,100.072647094727,55.4518536683136,5.52579093054508,7.33084344863892,26,1,0,0,1,0.290145874023438,33.2355842590332,2,1,1,200.643295288086,0,4232058656,200.561767578125,,,,,,,,,,,,,,,,,,,,,,,,,,,,,,,,,
,3874583928.48524,203.704330444336,100.072647094727,0.00022787083555758,3.24713729828668E-8,1,2,13.0063810348511,4.99155488619631,33.9899994432926,0.293936798270399,0.043615622758664,1,4.69104206007777E-7,,,,,,,,,,,,,,,,,,,,,203.629241943359,203.779418945313,100.072647094727,100.072647094727,55.3408624185828,5.52566612454405,7.37454509735107,26,1,0,0,1,0.289688110351562,34.2131004333496,2,1,1,203.779418945313,0,4232058656,203.704330444336,,,,,,,,,,,,,,,,,,,,,,,,,,,,,,,,,
,3874583966.47237,206.860534667969,100.072647094727,0.000226864872064915,2.84624458813063E-8,1,2,13.0063810348511,4.9915729253177,33.9800007641315,0.292642940074479,0.0434076836576813,1,4.54934051650804E-7,,,,,,,,,,,,,,,,,,,,,206.776321411133,206.944747924805,100.072647094727,100.072647094727,55.4158987564289,5.52576019589477,7.36584615707398,26,1,0,0,1,0.289154052734375,33.7243423461914,2,1,1,206.944747924805,0,4232058720,206.860534667969,,,,,,,,,,,,,,,,,,,,,,,,,,,,,,,,,
,3874584004.49971,210.04761505127,100.072647094727,0.000225763519581896,3.17012338037903E-8,1,2,13.0063810348511,4.99165645454542,33.9899994432926,0.291230524512476,0.0431879994021033,1,4.45003072052179E-7,,,,,,,,,,,,,,,,,,,,,209.968139648438,210.127090454102,100.072647094727,100.072647094727,55.3901050152943,5.52617848972242,7.37609434127808,24,1,64,0,0,0.289154052734375,33.7243423461914,2,1,1,210.127090454102,0,4232058720,210.04761505127,,,,,,,,,,,,,,,,,,,,,,,,,,,,,,,,,
,3874584042.41208,213.212768554687,100.072647094727,0.000224744428541428,4.6810879940602E-8,1,2,13.0063810348511,4.99168662558673,34.000001847744,0.289919356688708,0.0429866374161004,1,4.37743481133735E-7,,,,,,,,,,,,,,,,,,,,,213.113876342773,213.311660766602,100.072647094727,100.072647094727,55.3002177355828,5.52572260707086,7.40404605865479,26,1,0,0,1,0.289535522460937,33.7243423461914,2,1,1,213.311660766602,0,4232058752,213.212768554687,,,,,,,,,,,,,,,,,,,,,,,,,,,,,,,,,
,3874584080.40729,216.355529785156,100.072647094727,0.000223619979556581,3.86023574599397E-8,1,2,13.0063810348511,4.99165393626127,34.0100005269051,0.288466142715258,0.0427714465870692,1,4.35764737229594E-7,,,,,,,,,,,,,,,,,,,,,216.278244018555,216.432815551758,100.072647094727,100.072647094727,55.3690010452751,5.52536814529231,7.41851663589478,26,1,0,0,1,0.290985107421875,33.2355842590332,2,1,1,216.432815551758,0,4232058784,216.355529785156,,,,,,,,,,,,,,,,,,,,,,,,,,,,,,,,,
,3874584118.38983,219.495010375977,100.072647094727,0.00022256763207496,3.8603889409543E-8,1,2,13.0063810348511,4.99162966857394,34.0100005269051,0.287099756308377,0.0426172158225502,1,4.70401422956284E-7,,,,,,,,,,,,,,,,,,,,,219.421676635742,219.568344116211,100.072647094727,100.072647094727,55.504222779102,5.52533082345999,7.44505167007446,26,1,0,0,1,0.289764404296875,33.7243423461914,2,1,1,219.568344116211,0,4232058624,219.495010375977,,,,,,,,,,,,,,,,,,,,,,,,,,,,,,,,,
,3874584156.43759,222.653793334961,100.072647094727,0.000221499801574222,3.37740370682493E-8,1,2,13.0063810348511,4.99158109279001,34.0300016105175,0.285724683010106,0.0423694220722821,1,4.35014131492305E-7,,,,,,,,,,,,,,,,,,,,,222.586685180664,222.720901489258,100.072647094727,100.072647094727,55.3733000021309,5.52599032933223,7.47095155715942,24,1,64,0,0,0.28900146484375,33.2355842590332,2,1,1,222.720901489258,0,4232058624,222.653793334961,,,,,,,,,,,,,,,,,,,,,,,,,,,,,,,,,
,3874584194.35322,225.817344665527,100.072647094727,0.000220530143001742,4.62109814544192E-8,1,2,13.0063810348511,4.99162781272212,34.0300016105175,0.284469938793738,0.0422367846981238,1,4.73634934441245E-7,,,,,,,,,,,,,,,,,,,,,225.735992431641,225.898696899414,100.072647094727,100.072647094727,55.4420833118232,5.52579272692069,7.46738338470459,26,1,0,0,1,0.290451049804687,33.2355842590332,2,1,1,225.898696899414,0,4232058656,225.817344665527,,,,,,,,,,,,,,,,,,,,,,,,,,,,,,,,,
,3874584232.34311,228.950828552246,100.072647094727,0.000219532473018869,2.80982110426246E-8,1,2,13.0063810348511,4.99165193518442,34.0400002896786,0.283190825085006,0.0420056218419786,1,4.40206808604844E-7,,,,,,,,,,,,,,,,,,,,,228.87858581543,229.023071289062,100.072647094727,100.072647094727,55.4053467714193,5.52575597343626,7.53650999069214,26,1,0,0,1,0.289993286132812,33.2355842590332,2,1,1,229.023071289062,0,4232058656,228.950828552246,,,,,,,,,,,,,,,,,,,,,,,,,,,,,,,,,
,3874584270.35605,232.105735778809,100.072647094727,0.000218504420666101,3.04445446016014E-8,1,2,13.0063810348511,4.99167130454838,34.0400002896786,0.281863501994867,0.0418275442914817,1,4.52408531946094E-7,,,,,,,,,,,,,,,,,,,,,232.02702331543,232.184448242187,100.072647094727,100.072647094727,55.3604031315636,5.52492785714343,7.52689933776855,26,1,0,0,1,0.28961181640625,33.7243423461914,2,1,1,232.184448242187,0,4232058720,232.105735778809,,,,,,,,,,,,,,,,,,,,,,,,,,,,,,,,,
,3874584308.332,235.27165222168,100.072647094727,0.000217445997044377,3.32482852492889E-8,1,2,13.0063810348511,4.99164096310988,34.060001373291,0.280501456882065,0.0415858271075163,1,4.20183864625806E-7,,,,,,,,,,,,,,,,,,,,,235.189590454102,235.353713989258,100.072647094727,100.072647094727,55.3881509439962,5.52553411237807,7.55085182189941,26,1,0,0,1,0.29052734375,33.7243423461914,2,1,1,235.353713989258,0,4232058624,235.27165222168,,,,,,,,,,,,,,,,,,,,,,,,,,,,,,,,,
,3874584346.27604,238.437072753906,100.072647094727,0.000216429019676456,2.13541946128438E-8,1,2,13.0063810348511,4.99170899065359,34.060001373291,0.279193875348647,0.0413990636504007,1,4.23598455418794E-7,,,,,,,,,,,,,,,,,,,,,238.360000610352,238.514144897461,100.072647094727,100.072647094727,55.2017325421597,5.5252499656751,7.61014699935913,26,1,0,0,1,0.288772583007812,34.2131004333496,2,1,1,238.514144897461,0,4232058624,238.437072753906,,,,,,,,,,,,,,,,,,,,,,,,,,,,,,,,,
,3874584384.25766,241.584510803223,100.072647094727,0.000215443817313443,3.05148559133806E-8,1,2,13.0063810348511,4.99171162971402,34.0700000524521,0.27792091120069,0.0412260673768187,1,4.33624239258491E-7,,,,,,,,,,,,,,,,,,,,,241.504379272461,241.664642333984,100.072647094727,100.072647094727,55.4030018858616,5.5247672677719,7.62573480606079,26,1,0,0,1,0.289688110351562,33.2355842590332,2,1,1,241.664642333984,0,4232058752,241.584510803223,,,,,,,,,,,,,,,,,,,,,,,,,,,,,,,,,
,3874584422.23744,244.715721130371,100.072647094727,0.000214427364324618,2.96810705130238E-8,1,2,13.0063810348511,4.99172949697383,34.0799987316132,0.276609127568761,0.0410451029288709,1,4.41910911854725E-7,,,,,,,,,,,,,,,,,,,,,244.63525390625,244.796188354492,100.072647094727,100.072647094727,55.3912774580732,5.52552309868166,7.68362855911255,26,1,0,0,1,0.289154052734375,33.2355842590332,2,1,1,244.796188354492,0,4232058656,244.715721130371,,,,,,,,,,,,,,,,,,,,,,,,,,,,,,,,,
,3874584460.21543,247.86824798584,100.072647094727,0.000213337499928297,3.49167858545373E-8,1,2,13.0063810348511,4.99161078294829,34.0900011360645,0.275195195801453,0.0408274193264306,1,4.33691421998284E-7,,,,,,,,,,,,,,,,,,,,,247.780334472656,247.956161499023,100.072647094727,100.072647094727,55.3267931052366,5.52615944262126,7.75224924087524,26,1,0,0,1,0.289459228515625,33.7243423461914,2,1,1,247.956161499023,0,4232058656,247.86824798584,,,,,,,,,,,,,,,,,,,,,,,,,,,,,,,,,
,3874584498.18937,251.037567138672,100.072647094727,0.000212418671458214,2.53847350010995E-8,1,2,13.0063810348511,4.99159785418688,34.0999998152256,0.274015582425722,0.0406061543071832,1,3.96733886301698E-7,,,,,,,,,,,,,,,,,,,,,250.954177856445,251.120956420898,100.072647094727,100.072647094727,55.3744724449097,5.52581912116404,7.79694652557373,26,1,0,0,1,0.29022216796875,33.7243423461914,2,1,1,251.120956420898,0,4232058720,251.037567138672,,,,,,,,,,,,,,,,,,,,,,,,,,,,,,,,,
,3874584536.1808,254.195877075195,100.072647094727,0.000211405710537305,3.10672009019132E-8,1,2,13.0063810348511,4.99160758526861,34.1099984943867,0.272705916882888,0.0404379900937139,1,4.14499102547502E-7,,,,,,,,,,,,,,,,,,,,,254.121276855469,254.270477294922,100.072647094727,100.072647094727,55.4350486551501,5.52566637498568,7.92171955108643,26,1,0,0,1,0.290451049804687,33.2355842590332,2,1,1,254.270477294922,0,4232058560,254.195877075195,,,,,,,,,,,,,,,,,,,,,,,,,,,,,,,,,
,3874584574.17894,257.336685180664,100.072647094727,0.000210351542896589,3.11742942858753E-8,1,2,13.0063810348511,4.99166551686161,34.120000898838,0.271345950692037,0.0402679506175803,1,4.36418408835019E-7,,,,,,,,,,,,,,,,,,,,,257.256805419922,257.416564941406,100.072647094727,100.072647094727,55.3428164898809,5.52594641049581,7.97963619232178,26,1,0,0,1,0.29052734375,33.7243423461914,2,1,1,257.416564941406,0,4232058784,257.336685180664,,,,,,,,,,,,,,,,,,,,,,,,,,,,,,,,,
,3874584612.45995,260.517623901367,100.072647094727,0.000209407612492172,2.86977986851507E-8,1,2,13.0063810348511,4.99172999916361,34.1299995779991,0.270138096617186,0.0400544351146581,1,4.08466964835557E-7,,,,,,,,,,,,,,,,,,,,,260.450744628906,260.584503173828,100.072647094727,100.072647094727,55.4784290379674,5.52558268369063,8.11007308959961,24,1,64,0,0,0.28961181640625,33.2355842590332,2,1,1,260.584503173828,0,4232058656,260.517623901367,,,,,,,,,,,,,,,,,,,,,,,,,,,,,,,,,
,3874584650.12081,263.635620117187,100.072647094727,0.000208304238815662,2.50014611583888E-8,1,2,13.0063810348511,4.99165626704113,34.1299995779991,0.268712997673907,0.0398165112250607,1,3.86123528656813E-7,,,,,,,,,,,,,,,,,,,,,263.554870605469,263.716369628906,100.072647094727,100.072647094727,55.463578096102,5.52575838037912,8.29572105407715,26,1,0,0,1,0.29052734375,33.7243423461914,2,1,1,263.716369628906,0,4232058688,263.635620117187,,,,,,,,,,,,,,,,,,,,,,,,,,,,,,,,,
,3874584688.11389,266.815795898438,100.072647094727,0.00020735357205649,2.94073802028752E-8,1,2,13.0063810348511,4.99167884560902,34.1500006616116,0.267487385236433,0.0396414751952764,1,3.89344086986456E-7,,,,,,,,,,,,,,,,,,,,,266.722930908203,266.908660888672,100.072647094727,100.072647094727,55.4209793418039,5.52553844411253,8.40879535675049,26,1,0,0,1,0.2899169921875,33.7243423461914,2,1,1,266.908660888672,0,4232058656,266.815795898438,,,,,,,,,,,,,,,,,,,,,,,,,,,,,,,,,
,3874584726.08045,269.934463500977,100.072647094727,0.000206309725085039,3.1959432350175E-8,1,2,13.0063810348511,4.99169589473074,34.1500006616116,0.266144485954317,0.0394256987617887,1,3.74671469164883E-7,,,,,,,,,,,,,,,,,,,,,269.859283447266,270.009643554687,100.072647094727,100.072647094727,55.4670954244386,5.52625394579521,8.36314487457275,26,1,0,0,1,0.289459228515625,33.7243423461914,2,1,1,270.009643554687,0,4232058688,269.934463500977,,,,,,,,,,,,,,,,,,,,,,,,,,,,,,,,,
,3874584764.06302,273.105346679687,100.072647094727,0.000205395868379417,3.60136064258468E-8,1,2,13.0063810348511,4.99168015660031,34.1800004243851,0.264955965755133,0.0393086937888588,1,4.17809826241336E-7,,,,,,,,,,,,,,,,,,,,,273.022705078125,273.18798828125,100.072647094727,100.072647094727,55.4596699535059,5.52586451132939,8.29092788696289,26,1,0,0,1,0.290298461914063,33.7243423461914,2,1,1,273.18798828125,0,4232058656,273.105346679687,,,,,,,,,,,,,,,,,,,,,,,,,,,,,,,,,
,3874584802.05448,276.238967895508,100.072647094727,0.0002043395414734,2.11842265669211E-8,1,2,13.0063810348511,4.99169719401701,34.1800004243851,0.263601384545623,0.0390602401064644,1,3.79640185688187E-7,,,,,,,,,,,,,,,,,,,,,276.154724121094,276.323211669922,100.072647094727,100.072647094727,55.3764265162078,5.52555553072979,8.20394992828369,26,1,0,0,1,0.290374755859375,34.2131004333496,2,1,1,276.323211669922,0,4232058720,276.238967895508,,,,,,,,,,,,,,,,,,,,,,,,,,,,,,,,,
,3874584840.03664,279.405090332031,100.072647094727,0.000203338122558753,2.60155455395154E-8,1,2,13.0063810348511,4.99174395673198,34.1899991035461,0.262317568147061,0.0388378988774628,1,3.53426302098154E-7,,,,,,,,,,,,,,,,,,,,,279.326446533203,279.483734130859,100.072647094727,100.072647094727,55.4518536683136,5.52581772173523,8.20538234710693,26,1,0,0,1,0.2886962890625,33.7243423461914,2,1,1,279.483734130859,0,4232058624,279.405090332031,,,,,,,,,,,,,,,,,,,,,,,,,,,,,,,,,
,3874584878.02635,282.551910400391,100.072647094727,0.000202393849124104,2.42147022351844E-8,1,2,13.0063810348511,4.99169907824938,34.2000015079975,0.261094781471619,0.0386662229130224,1,3.58889501082453E-7,,,,,,,,,,,,,,,,,,,,,282.481018066406,282.622802734375,100.072647094727,100.072647094727,55.5690979461982,5.52629062032974,8.14689064025879,26,1,0,0,1,0.286102294921875,33.7243423461914,2,1,1,282.622802734375,0,4232058656,282.551910400391,,,,,,,,,,,,,,,,,,,,,,,,,,,,,,,,,
,3874584916.3261,285.753402709961,100.072647094727,0.000201403765854219,2.77840344512945E-8,1,2,13.0063810348511,4.9917161243526,34.2100001871586,0.259825296165644,0.0384327175623253,1,3.22617491914698E-7,,,,,,,,,,,,,,,,,,,,,285.703948974609,285.802856445313,100.072647094727,100.072647094727,55.3088156492943,5.52552798089324,8.10411643981934,24,1,64,0,0,0.288543701171875,33.7243423461914,2,1,1,285.802856445313,0,4232058624,285.753402709961,,,,,,,,,,,,,,,,,,,,,,,,,,,,,,,,,
,3874584953.9802,288.874282836914,100.072647094727,0.000200460007166421,3.02518033408647E-8,1,2,13.0063810348511,4.99180179270014,34.2199988663197,0.258601819185959,0.03833668517389,1,3.85536918090943E-7,,,,,,,,,,,,,,,,,,,,,288.785491943359,288.963073730469,100.072647094727,100.072647094727,55.4561526251693,5.52512012073429,8.12096118927002,26,1,0,0,1,0.289764404296875,33.7243423461914,2,1,1,288.963073730469,0,4232058624,288.874282836914,,,,,,,,,,,,,,,,,,,,,,,,,,,,,,,,,
,3874584991.95923,291.997436523438,100.072647094727,0.00019951981902873,3.11465503930763E-8,1,2,13.0063810348511,4.99177692130431,34.2199988663197,0.257391604207973,0.0381261317156142,1,3.60105795353415E-7,,,,,,,,,,,,,,,,,,,,,291.919128417969,292.075744628906,100.072647094727,100.072647094727,55.5370511769097,5.52563643225304,8.08458995819092,26,1,0,0,1,0.28961181640625,33.7243423461914,2,1,1,292.075744628906,0,4232058880,291.997436523438,,,,,,,,,,,,,,,,,,,,,,,,,,,,,,,,,
,3874585029.922,295.142822265625,100.072647094727,0.000198569022916569,2.63779226012635E-8,1,2,13.0063810348511,4.99178428792974,34.230001270771,0.256170050715525,0.0379137747205369,1,3.34561339392853E-7,,,,,,,,,,,,,,,,,,,,,295.045440673828,295.240203857422,100.072647094727,100.072647094727,55.397530486227,5.52548734835997,8.11752223968506,26,1,0,0,1,0.289077758789063,33.7243423461914,2,1,1,295.240203857422,0,4232058720,295.142822265625,,,,,,,,,,,,,,,,,,,,,,,,,,,,,,,,,
,3874585067.91377,298.284957885742,100.072647094727,0.000197725584035252,2.38304855394922E-8,1,2,13.0063810348511,4.99169762672459,34.2499986290932,0.255070438787376,0.0377881852715339,1,3.6132475473404E-7,,,,,,,,,,,,,,,,,,,,,298.218841552734,298.35107421875,100.072647094727,100.072647094727,55.3017809926212,5.52549318886452,8.1026725769043,26,1,0,0,1,0.288925170898438,33.7243423461914,2,1,1,298.35107421875,0,4232058752,298.284957885742,,,,,,,,,,,,,,,,,,,,,,,,,,,,,,,,,
,3874585105.88103,301.449249267578,100.072647094727,0.000196819613238046,3.86091979585468E-8,1,2,13.0063810348511,4.99181131697715,34.2699997127056,0.253908788851112,0.0376231264618747,1,3.65007083525954E-7,,,,,,,,,,,,,,,,,,,,,301.360321044922,301.538177490234,100.072647094727,100.072647094727,55.4170711992078,5.52596596320071,8.15813064575195,26,1,0,0,1,0.290069580078125,33.7243423461914,2,1,1,301.538177490234,0,4232058688,301.449249267578,,,,,,,,,,,,,,,,,,,,,,,,,,,,,,,,,
,3874585143.93638,304.612365722656,100.072647094727,0.000195935008825282,3.24212725269865E-8,1,2,13.0063810348511,4.99180209399145,34.2699997127056,0.252762194350071,0.0374864088887648,1,3.8853385634484E-7,,,,,,,,,,,,,,,,,,,,,304.541870117188,304.682861328125,100.072647094727,100.072647094727,55.3889325725155,5.52515587124765,8.25061798095703,25,1,64,0,0,0.289535522460937,36.1681327819824,2,1,1,304.682861328125,0,4232058656,304.612365722656,,,,,,,,,,,,,,,,,,,,,,,,,,,,,,,,,
,3874585181.86259,307.759948730469,100.072647094727,0.000195054440653624,2.98874036761891E-8,1,2,13.0063810348511,4.99181093925484,34.2799983918667,0.251631392476449,0.0372870272499894,1,3.62761845406967E-7,,,,,,,,,,,,,,,,,,,,,307.677978515625,307.841918945313,100.072647094727,100.072647094727,55.3205400770828,5.52586431359991,8.308424949646,26,1,0,0,1,0.289459228515625,33.7243423461914,2,1,1,307.841918945313,0,4232058656,307.759948730469,,,,,,,,,,,,,,,,,,,,,,,,,,,,,,,,,
,3874585219.85665,309.537826538086,100.072647094727,0.000194545727208244,2.52204953325198E-8,1,2,13.0063810348511,4.99191275829061,34.2799983918667,0.250982735047067,0.0371877015112126,1,3.59383324105508E-7,,,,,,,,,,,,,,,,,,,,,309.524719238281,309.550933837891,100.072647094727,100.072647094727,55.3463338182174,5.52532648966352,8.45536422729492,26,1,0,0,1,0.290298461914063,33.7243423461914,6,1,1,309.550933837891,0,4232058720,309.537826538086,,,,,,,,,,,,,,,,,,,,,,,,,,,,,,,,,
,3874585257.83876,309.858047485352,100.072647094727,0.000194535215627721,2.02532044563132E-8,1,2,13.0063810348511,4.99194108529046,34.2799983918667,0.250970350329005,0.0371915492422907,1,3.63674166359244E-7,,,,,,,,,,,,,,,,,,,,,309.853820800781,309.862274169922,100.072647094727,100.072647094727,55.5261083776405,5.52561807651839,8.61122798919678,26,1,0,0,1,0.289306640625,33.7243423461914,5,1,1,309.862274169922,0,4232058880,309.858047485352,,,,,,,,,,,,,,,,,,,,,,,,,,,,,,,,,
,3874585279.82149,309.920974731445,100.072647094727,0.000194562001274802,2.90319211768965E-8,1,2,13.0063810348511,4.99191418334234,34.2799983918667,0.251004802680545,0.0371841796767771,1,3.54262080680697E-7,,,,,,,,,,,,,,,,,,,,,309.919067382812,309.922882080078,100.072647094727,100.072647094727,55.3717367450924,5.52555240997063,8.67125511169434,26,1,0,0,1,0.289230346679687,33.7243423461914,1,1,1,309.922882080078,0,4232058752,309.920974731445,,,,,,,,,,,,,,,,,,,,,,,,,,,,,,,,,