File: example_report_creation/example_dir/sample_ID/qd_files/101022_00004.dat
[Header]
; MPMS3 Data File (default extension .dat)
; Copyright (c) 2007, Quantum Design, Inc. All rights reserved.
TITLE,
FILEOPENTIME,3874593053.23344,10/10/2022,7:50 pm
BYAPP,MPMS3 w/ AC,1.0,1.1
INFO,MPMS3 Measurement Release 1.1.16 Build 424, MultiVu Release 2.3.4.19,APPNAME
INFO,Linear Motor Servo Controller,MOTOR_MODULE_NAME
INFO,3101-100 J0,MOTOR_HW_VERSION
INFO,MMC721,MOTOR_SERIAL_NUMBER
INFO,01.04.28,MOTOR_SOFTWARE_VERSION
INFO,Quantum Design Squid Module,SQUID_MODULE_NAME
INFO,3101-501 B0,SQUID_HW_VERSION
INFO,SQM195,SQUID_SERIAL_NUMBER
INFO,01.03.04,SQUID_SOFTWARE_VERSION
INFO,SQUID AC,AC_MODULE_NAME
INFO,3101-401 f1,AC_HW_VERSION
INFO,SAC107,AC_SERIAL_NUMBER
INFO,SQUID AC 00.95.07,AC_SOFTWARE_VERSION
INFO,TCI166,COIL_SERIAL_NUMBER
INFO,0,MOMENT_UNITS
INFO,Quidel - 101022,SAMPLE_MATERIAL
INFO,,SAMPLE_COMMENT
INFO,1.38,SAMPLE_MASS
INFO,,SAMPLE_VOLUME
INFO,,SAMPLE_MOLECULAR_WEIGHT
INFO,,SAMPLE_SIZE
INFO,,SAMPLE_SHAPE
INFO,Brass,SAMPLE_HOLDER
INFO,Standard,SAMPLE_HOLDER_DETAIL
INFO,64.25,SAMPLE_OFFSET
DATATYPE,COMMENT,1
DATATYPE,TIME,2
STARTUPAXIS,X,2
STARTUPAXIS,Y1,5
FIELDGROUP, VSM,2,3,4,5,6,8,9,10,11,14,15
FIELDGROUP, DC, 2,3,4,14,56,57,58,59,60,61,62,63,64,65,66,67,68,69
FIELDGROUP, AC, 2,3,4,11,16,17,18,19,20,21,22,23,24,25,26,27,28,29,30
STARTUPGROUP, All
[Data]
Comment,Time Stamp (sec),Temperature (K),Magnetic Field (Oe),Moment (emu),M. Std. Err. (emu),Transport Action,Averaging Time (sec),Frequency (Hz),Peak Amplitude (mm),Center Position (mm),Lockin Signal' (V),Lockin Signal (V),Range,M. Quad. Signal (emu),AC Moment (emu),AC M. Std Err. (emu),AC Phase (deg),AC Phase Std. Err. (deg),AC Susceptibility (emu/Oe),AC Suscept. Std Err. (emu/Oe),AC X' (emu/Oe),AC X' Std Err. (emu/Oe),AC X'' (emu/Oe),AC X'' Std Err. (emu/Oe),AC Drive (Oe),AC Frequency (Hz),AC Averaging Time (sec),AC Cycles,AC Range,AC Measure Type,AC Signal' (V),AC Signal'' (V),AC Trim Coil Ratio,AC Trim Coil Phase,Min. Temperature (K),Max. Temperature (K),Min. Field (Oe),Max. Field (Oe),Mass (grams),Motor Lag (deg),Pressure (Torr),Measure Count,Measurement Number,SQUID Status (code),Motor Status (code),Measure Status (code),Motor Current (amps),Motor Temp. (C),Temp. Status (code),Field Status (code),Chamber Status (code),Chamber Temp (K),Redirection State,Evercool Status,Average Temp (K),Rotation Angle (deg),Rotator state,DC Moment Fixed Ctr (emu),DC Moment Err Fixed Ctr (emu),DC Moment Free Ctr (emu),DC Moment Err Free Ctr (emu),DC Fixed Fit,DC Free Fit,DC Calculated Center (mm),DC Calculated Center Err (mm),DC Scan Length (mm),DC Scan Time (s),DC Number of Points,DC Squid Drift,DC Min V (V),DC Max V (V),DC Scans per Measure,Map 01,Map 02,Map 03,Map 04,Map 05,Map 06,Map 07,Map 08,Map 09,Map 10,Map 11,Map 12,Map 13,Map 14,Map 15,Map 16
"FC, 1000",3874593053.34648
,3874593171.93381,309.000762939453,1000.22534179688,0.000698168166969905,8.98714407787896E-8,1,2,13.0063810348511,5.00074001611204,34.2900007963181,0.902834739972011,0.134427426089387,1,1.78597229130907E-6,,,,,,,,,,,,,,,,,,,,,308.934661865234,309.066864013672,1000.22534179688,1000.22534179688,55.3733000021309,5.52856484122256,9.0821647644043,26,1,0,0,1,0.29266357421875,33.2355842590332,2,1,1,308.934661865234,0,4232057952,309.000762939453,,,,,,,,,,,,,,,,,,,,,,,,,,,,,,,,,
,3874593207.95359,306.101791381836,1000.22534179688,0.000701870695149225,9.01373668321291E-8,1,2,13.0063810348511,5.00076073970022,34.2799983918667,0.907608041621587,0.135276884150931,1,1.90040393279969E-6,,,,,,,,,,,,,,,,,,,,,306.017547607422,306.18603515625,1000.22534179688,1000.22534179688,55.3181951915251,5.5286361986567,9.25383281707764,26,1,0,0,1,0.2923583984375,33.7243423461914,2,1,1,306.017547607422,0,4232058400,306.101791381836,,,,,,,,,,,,,,,,,,,,,,,,,,,,,,,,,
,3874593243.89116,302.818298339844,1000.22534179688,0.000707699872675301,1.15006405811089E-7,1,2,13.0063810348511,5.00080009389399,34.2600010335445,0.915141408887078,0.136501329129781,1,1.99305918792321E-6,,,,,,,,,,,,,,,,,,,,,302.724182128906,302.912414550781,1000.22534179688,1000.22534179688,55.2822402796405,5.52909821188952,9.5141429901123,26,1,0,0,1,0.292892456054687,33.2355842590332,2,1,1,302.724182128906,0,4232058656,302.818298339844,,,,,,,,,,,,,,,,,,,,,,,,,,,,,,,,,
,3874593279.88325,299.630157470703,1000.22534179688,0.000713428059427138,1.19066494955169E-7,1,2,13.0063810348511,5.00074528303391,34.2600010335445,0.922558264817771,0.137441896672773,1,1.88382142470309E-6,,,,,,,,,,,,,,,,,,,,,299.558410644531,299.701904296875,1000.22534179688,1000.22534179688,55.3201492628231,5.52913155823071,9.86394500732422,26,1,0,0,1,0.291061401367188,33.2355842590332,2,1,1,299.558410644531,0,4232058592,299.630157470703,,,,,,,,,,,,,,,,,,,,,,,,,,,,,,,,,
,3874593315.86157,296.720947265625,1000.22534179688,0.000718315084810739,9.49838816358014E-8,1,2,13.0063810348511,5.00072048477183,34.2600010335445,0.928864405573421,0.138430369634011,1,1.93378819850451E-6,,,,,,,,,,,,,,,,,,,,,296.642425537109,296.799468994141,1000.22534179688,1000.22534179688,55.4061283999385,5.52937175728583,10.1923217773438,26,1,0,0,1,0.293350219726562,33.2355842590332,2,1,1,296.642425537109,0,4232058784,296.720947265625,,,,,,,,,,,,,,,,,,,,,,,,,,,,,,,,,
,3874593351.83826,293.889251708984,1000.22534179688,0.000722458447495681,9.99552061746743E-8,1,2,13.0063810348511,5.00064542812051,34.2399999499321,0.934184902019142,0.139347555076642,1,2.0389524278185E-6,,,,,,,,,,,,,,,,,,,,,293.805603027344,293.972900390625,1000.22534179688,1000.22534179688,55.3103789063328,5.52910680087346,10.4219722747803,26,1,0,0,1,0.29327392578125,33.2355842590332,2,1,1,293.805603027344,0,4232058720,293.889251708984,,,,,,,,,,,,,,,,,,,,,,,,,,,,,,,,,
,3874593387.83798,291.030059814453,1000.22534179688,0.000726689682237893,1.07558576942975E-7,1,2,13.0063810348511,5.00113061247486,34.2199988663197,0.93979615247414,0.140095061145965,1,1.983197263857E-6,,,,,,,,,,,,,,,,,,,,,290.948028564453,291.112091064453,1000.22534179688,1000.22534179688,55.3178043772655,5.52818659089454,10.3069677352905,26,1,0,0,1,0.292816162109375,33.2355842590332,2,1,1,290.948028564453,0,4232058720,291.030059814453,,,,,,,,,,,,,,,,,,,,,,,,,,,,,,,,,
,3874593423.82123,288.078308105469,1000.22534179688,0.000731048734094943,8.53231308906299E-8,1,2,13.0063810348511,5.00067721075832,34.2199988663197,0.945324732818689,0.140843951195509,1,1.93816177080505E-6,,,,,,,,,,,,,,,,,,,,,287.988037109375,288.168579101562,1000.22534179688,1000.22534179688,55.3740816306501,5.52923964931083,10.1335306167603,26,1,0,0,1,0.292510986328125,33.2355842590332,2,1,1,287.988037109375,0,4232058752,288.078308105469,,,,,,,,,,,,,,,,,,,,,,,,,,,,,,,,,
,3874593459.79912,285.099670410156,1000.22534179688,0.0007354485755499,7.34435006565983E-8,1,2,13.0063810348511,5.00069197280449,34.2199988663197,0.950959711078792,0.14209148766486,1,2.25848030985101E-6,,,,,,,,,,,,,,,,,,,,,285.023651123047,285.175689697266,1000.22534179688,1000.22534179688,55.4323129553328,5.52883218969778,10.0379552841187,26,1,0,0,1,0.293426513671875,34.2131004333496,2,1,1,285.023651123047,0,4232058560,285.099670410156,,,,,,,,,,,,,,,,,,,,,,,,,,,,,,,,,
,3874593495.76463,282.086685180664,1000.22534179688,0.000739705150182428,8.21603480856582E-8,1,2,13.0063810348511,5.00084014887172,34.2000015079975,0.956534188873161,0.142707535809771,1,2.10748660748355E-6,,,,,,,,,,,,,,,,,,,,,282.01025390625,282.163116455078,1000.22534179688,1000.22534179688,55.3271839194962,5.52811212140832,9.90459537506104,26,1,0,0,1,0.291213989257812,33.2355842590332,2,1,1,282.01025390625,0,4232058784,282.086685180664,,,,,,,,,,,,,,,,,,,,,,,,,,,,,,,,,
,3874593531.78507,279.067260742187,1000.22534179688,0.000744211116651411,1.06542429687557E-7,1,2,13.0063810348511,5.00080269897436,34.2000015079975,0.962364020194694,0.143485871475232,1,2.05115804553715E-6,,,,,,,,,,,,,,,,,,,,,278.997924804687,279.136596679687,1000.22534179688,1000.22534179688,55.3334369476501,5.52821574123689,9.78730487823486,26,1,0,0,1,0.293807983398438,33.2355842590332,2,1,1,278.997924804687,0,4232058656,279.067260742187,,,,,,,,,,,,,,,,,,,,,,,,,,,,,,,,,
,3874593567.72904,276.084777832031,1000.22534179688,0.000748358345418096,8.0970687637584E-8,1,2,13.0063810348511,5.00089502113496,34.1800004243851,0.967702157289804,0.144628969092403,1,2.32523683009856E-6,,,,,,,,,,,,,,,,,,,,,275.999938964844,276.169616699219,1000.22534179688,1000.22534179688,55.3486787037751,5.52819947027181,9.7430305480957,26,1,0,0,1,0.293350219726562,33.7243423461914,2,1,1,275.999938964844,0,4232058656,276.084777832031,,,,,,,,,,,,,,,,,,,,,,,,,,,,,,,,,
,3874593603.72347,273.073104858398,1000.22534179688,0.000752766185037323,1.17348579945004E-7,1,2,13.0063810348511,5.000917944447,34.1899991035461,0.973458113932408,0.145140264963214,1,2.0749596071924E-6,,,,,,,,,,,,,,,,,,,,,272.993011474609,273.153198242187,1000.22534179688,1000.22534179688,55.3666561597174,5.52813425816482,9.62607192993164,26,1,0,0,1,0.290908813476562,33.7243423461914,2,1,1,272.993011474609,0,4232058688,273.073104858398,,,,,,,,,,,,,,,,,,,,,,,,,,,,,,,,,
,3874593639.70098,270.075271606445,1000.22534179688,0.000757211920739491,8.85355444900572E-8,1,2,13.0063810348511,5.0010274857031,34.1800004243851,0.979238290587489,0.145994084881377,1,2.08116954914401E-6,,,,,,,,,,,,,,,,,,,,,269.992950439453,270.157592773438,1000.22534179688,1000.22534179688,55.4401292405251,5.52771778441636,9.5355806350708,26,1,0,0,1,0.293502807617188,33.7243423461914,2,1,1,269.992950439453,0,4232058688,270.075271606445,,,,,,,,,,,,,,,,,,,,,,,,,,,,,,,,,
,3874593675.67842,267.031555175781,1000.22534179688,0.000761421648973784,9.51078567675234E-8,1,2,13.0063810348511,5.0008578197979,34.1599993407726,0.984645167159338,0.14673459590264,1,2.04311600290021E-6,,,,,,,,,,,,,,,,,,,,,266.954772949219,267.108337402344,1000.22534179688,1000.22534179688,55.3193676343039,5.52804895966058,9.5095739364624,26,1,0,0,1,0.292434692382812,33.2355842590332,2,1,1,266.954772949219,0,4232058688,267.031555175781,,,,,,,,,,,,,,,,,,,,,,,,,,,,,,,,,
,3874593711.6525,264.052505493164,1000.22534179688,0.000765887063956377,9.67299733599789E-8,1,2,13.0063810348511,5.00086674478532,34.1599993407726,0.990405957680646,0.147706255308511,1,2.1407111310188E-6,,,,,,,,,,,,,,,,,,,,,263.986602783203,264.118408203125,1000.22534179688,1000.22534179688,55.3729091878712,5.52808468817132,9.39713478088379,26,1,0,0,1,0.293121337890625,33.7243423461914,2,1,1,263.986602783203,0,4232058528,264.052505493164,,,,,,,,,,,,,,,,,,,,,,,,,,,,,,,,,
,3874593747.67291,261.076309204102,1000.22534179688,0.00077037835269007,1.05998886405424E-7,1,2,13.0063810348511,5.00085857970252,34.1599993407726,0.996228364563236,0.148457440741108,1,2.06464099615649E-6,,,,,,,,,,,,,,,,,,,,,260.991058349609,261.161560058594,1000.22534179688,1000.22534179688,55.3748632591693,5.5281956269491,9.33280181884766,26,1,0,0,1,0.29327392578125,34.2131004333496,2,1,1,260.991058349609,0,4232058656,261.076309204102,,,,,,,,,,,,,,,,,,,,,,,,,,,,,,,,,
,3874593783.73246,258.04931640625,1000.22534179688,0.000774585210816105,1.41847381686256E-7,1,2,13.0063810348511,5.00081248600981,34.1399982571602,1.00165988881231,0.149237291619665,1,2.05355905450966E-6,,,,,,,,,,,,,,,,,,,,,257.971771240234,258.126861572266,1000.22534179688,1000.22534179688,55.2927922646501,5.52812667303904,9.31278610229492,24,1,64,0,0,0.291976928710937,33.7243423461914,2,1,1,257.971771240234,0,4232058624,258.04931640625,,,,,,,,,,,,,,,,,,,,,,,,,,,,,,,,,
,3874593819.61848,255.03825378418,1000.22534179688,0.000778924447521006,8.43330506421926E-8,1,2,13.0063810348511,5.0008955472825,34.1399982571602,1.00723558497133,0.150479820840918,1,2.3765931360399E-6,,,,,,,,,,,,,,,,,,,,,254.956390380859,255.1201171875,1000.22534179688,1000.22534179688,55.3545409176693,5.52803491190616,9.20529365539551,26,1,0,0,1,0.293502807617188,33.7243423461914,2,1,1,254.956390380859,0,4232058720,255.03825378418,,,,,,,,,,,,,,,,,,,,,,,,,,,,,,,,,
,3874593855.5929,252.04517364502,1000.22534179688,0.000783290776666934,1.08810156636559E-7,1,2,13.0063810348511,5.0008180407646,34.1299995779991,1.01290071419766,0.151040610297048,1,2.17388742272185E-6,,,,,,,,,,,,,,,,,,,,,251.972183227539,252.1181640625,1000.22534179688,1000.22534179688,55.387369315477,5.52810370403485,9.1709098815918,26,1,0,0,1,0.292816162109375,33.7243423461914,2,1,1,251.972183227539,0,4232058656,252.04517364502,,,,,,,,,,,,,,,,,,,,,,,,,,,,,,,,,
,3874593891.62951,249.06551361084,1000.22534179688,0.00078768004737388,9.98168798232911E-8,1,2,13.0063810348511,5.00084425279779,34.120000898838,1.01858025739253,0.15191423862317,1,2.20627689440674E-6,,,,,,,,,,,,,,,,,,,,,248.992553710938,249.138473510742,1000.22534179688,1000.22534179688,55.3643112741597,5.52780397387197,9.13932037353516,26,1,0,0,1,0.2911376953125,33.7243423461914,2,1,1,248.992553710938,0,4232058624,249.06551361084,,,,,,,,,,,,,,,,,,,,,,,,,,,,,,,,,
,3874593927.57412,246.079605102539,1000.22534179688,0.000792132425603704,8.13839369362468E-8,1,2,13.0063810348511,5.00081635761073,34.120000898838,1.02433689259794,0.152723489163548,1,2.18144356339091E-6,,,,,,,,,,,,,,,,,,,,,246.000793457031,246.158416748047,1000.22534179688,1000.22534179688,55.4487271542366,5.52813129914729,9.03515815734863,26,1,0,0,1,0.294036865234375,33.2355842590332,2,1,1,246.000793457031,0,4232058688,246.079605102539,,,,,,,,,,,,,,,,,,,,,,,,,,,,,,,,,
,3874593963.55372,243.075538635254,1000.22534179688,0.000796315637609639,7.8508479484464E-8,1,2,13.0063810348511,5.00089180487466,34.0999998152256,1.02976696058964,0.153540604832691,1,2.19865227093077E-6,,,,,,,,,,,,,,,,,,,,,242.995727539062,243.155349731445,1000.22534179688,1000.22534179688,55.4037835143809,5.52804557952106,9.0084867477417,26,1,0,0,1,0.289459228515625,33.2355842590332,2,1,1,242.995727539062,0,4232058592,243.075538635254,,,,,,,,,,,,,,,,,,,,,,,,,,,,,,,,,
,3874593999.53336,240.076065063477,1000.22534179688,0.000800674290975194,1.0597432164261E-7,1,2,13.0063810348511,5.00088005618882,34.0999998152256,1.03539075039523,0.154443891263443,1,2.25968172140819E-6,,,,,,,,,,,,,,,,,,,,,239.998489379883,240.15364074707,1000.22534179688,1000.22534179688,55.3068615779962,5.52812927437438,8.96872234344482,26,1,0,0,1,0.290603637695313,33.2355842590332,2,1,1,239.998489379883,0,4232058688,240.076065063477,,,,,,,,,,,,,,,,,,,,,,,,,,,,,,,,,
,3874594035.52601,237.075340270996,1000.22534179688,0.000805077211885999,1.33441368947953E-7,1,2,13.0063810348511,5.0008614448364,34.1099984943867,1.04107489801631,0.155320252572332,1,2.29365724442731E-6,,,,,,,,,,,,,,,,,,,,,236.995086669922,237.15559387207,1000.22534179688,1000.22534179688,55.3647020884193,5.52836465902618,8.89613628387451,26,1,0,0,1,0.290069580078125,33.2355842590332,2,1,1,236.995086669922,0,4232058752,237.075340270996,,,,,,,,,,,,,,,,,,,,,,,,,,,,,,,,,
,3874594071.51624,234.072738647461,1000.22534179688,0.000809275552953876,1.04613151577212E-7,1,2,13.0063810348511,5.00083837313207,34.0799987316132,1.04650836228799,0.156052853682414,1,2.24659010749907E-6,,,,,,,,,,,,,,,,,,,,,233.980712890625,234.164764404297,1000.22534179688,1000.22534179688,55.3013901783616,5.52835559612344,8.8690013885498,26,1,0,0,1,0.292816162109375,34.2131004333496,2,1,1,233.980712890625,0,4232058688,234.072738647461,,,,,,,,,,,,,,,,,,,,,,,,,,,,,,,,,
,3874594107.54331,231.050857543945,1000.22534179688,0.00081369613471329,1.00247922584449E-7,1,2,13.0063810348511,5.00084522694297,34.0799987316132,1.05222965109049,0.156886186473272,1,2.24387401680444E-6,,,,,,,,,,,,,,,,,,,,,230.97541809082,231.12629699707,1000.22534179688,1000.22534179688,55.3756448876886,5.52786258391411,8.81719303131103,24,1,64,0,0,0.293502807617188,33.7243423461914,2,1,1,230.97541809082,0,4232058592,231.050857543945,,,,,,,,,,,,,,,,,,,,,,,,,,,,,,,,,
,3874594143.4827,228.087547302246,1000.22534179688,0.000818057746049053,1.13720591493768E-7,1,2,13.0063810348511,5.00089663825273,34.0799987316132,1.05786821789142,0.157844339592694,1,2.34475047179943E-6,,,,,,,,,,,,,,,,,,,,,228.010345458984,228.164749145508,1000.22534179688,1000.22534179688,55.4370027264482,5.52816405878738,8.7553882598877,26,1,0,0,1,0.294647216796875,33.7243423461914,2,1,1,227.99072265625,0,4232058656,228.087547302246,,,,,,,,,,,,,,,,,,,,,,,,,,,,,,,,,
,3874594179.44787,225.079742431641,1000.22534179688,0.000822286934852315,1.18791312888559E-7,1,2,13.0063810348511,5.00123962070733,34.060001373291,1.06345467878406,0.158567731161101,1,2.27354480462292E-6,,,,,,,,,,,,,,,,,,,,,224.996887207031,225.16259765625,1000.22534179688,1000.22534179688,55.367046973977,5.52731004899087,8.74204730987549,26,1,0,0,1,0.289688110351562,33.2355842590332,2,1,1,224.996887207031,0,4232058688,225.079742431641,,,,,,,,,,,,,,,,,,,,,,,,,,,,,,,,,
,3874594215.42846,222.031761169434,1000.22534179688,0.000826553700363637,1.2922733250644E-7,1,2,13.0063810348511,5.00104815461296,34.060001373291,1.06890082729456,0.159484056436422,1,2.36421761912743E-6,,,,,,,,,,,,,,,,,,,,,221.946533203125,222.116989135742,1000.22534179688,1000.22534179688,55.3478970752559,5.52761253974899,8.67339515686035,26,1,0,0,1,0.29052734375,34.2131004333496,2,1,1,221.946533203125,0,4232058688,222.031761169434,,,,,,,,,,,,,,,,,,,,,,,,,,,,,,,,,
,3874594251.40544,219.059242248535,1000.22534179688,0.00083050091804626,1.15857387411245E-7,1,2,13.0063810348511,5.00097715084346,34.060001373291,1.07398307543332,0.160249546014171,1,2.38095361028609E-6,,,,,,,,,,,,,,,,,,,,,218.976928710938,219.141555786133,1000.22534179688,1000.22534179688,55.3303104335732,5.52901813731312,8.61684989929199,26,1,0,0,1,0.292739868164063,33.2355842590332,2,1,1,218.976928710938,0,4232058752,219.059242248535,,,,,,,,,,,,,,,,,,,,,,,,,,,,,,,,,
,3874594287.40601,216.023193359375,1000.22534179688,0.000834902759920217,1.29337533683934E-7,1,2,13.0063810348511,5.00104136456795,34.0400002896786,1.07963245645871,0.161527749081729,1,2.72281911621524E-6,,,,,,,,,,,,,,,,,,,,,215.932586669922,216.113800048828,1000.22534179688,1000.22534179688,55.3150686774482,5.52720568378969,8.61126613616943,26,1,0,0,1,0.29022216796875,34.2131004333496,2,1,1,215.932586669922,0,4232058624,216.023193359375,,,,,,,,,,,,,,,,,,,,,,,,,,,,,,,,,
,3874594323.36329,213.04874420166,1000.22534179688,0.000839432641875188,1.09094989731181E-7,1,2,13.0063810348511,5.00097264521896,34.0400002896786,1.08551138845227,0.162113626247809,1,2.5154403582883E-6,,,,,,,,,,,,,,,,,,,,,212.959136962891,213.13835144043,1000.22534179688,1000.22534179688,55.3201492628231,5.52797446484485,8.53664684295654,26,1,0,0,1,0.2935791015625,33.7243423461914,2,1,1,212.959136962891,0,4232058560,213.04874420166,,,,,,,,,,,,,,,,,,,,,,,,,,,,,,,,,
,3874594359.43959,210.074005126953,1000.22534179688,0.000843719254718024,1.37578717922807E-7,1,2,13.0063810348511,5.00091941588301,34.0400002896786,1.09100609804013,0.163159990539439,1,2.69906804522833E-6,,,,,,,,,,,,,,,,,,,,,210.007446289062,210.140563964844,1000.22534179688,1000.22534179688,55.392449900852,5.52751446489748,8.48221206665039,26,1,0,0,1,0.292129516601562,33.7243423461914,2,1,1,210.007446289062,0,4232058592,210.074005126953,,,,,,,,,,,,,,,,,,,,,,,,,,,,,,,,,
,3874594395.3299,207.086418151855,1000.22534179688,0.000848132892976846,1.06484582832756E-7,1,2,13.0063810348511,5.00091957569496,34.0400002896786,1.09673111157885,0.163892330509404,1,2.61951400958669E-6,,,,,,,,,,,,,,,,,,,,,207.019271850586,207.153564453125,1000.22534179688,1000.22534179688,55.3252298481982,5.5274199512237,8.4889440536499,26,1,0,0,1,0.291290283203125,33.2355842590332,2,1,1,207.019271850586,0,4232058624,207.086418151855,,,,,,,,,,,,,,,,,,,,,,,,,,,,,,,,,
,3874594431.30517,204.094680786133,1000.22534179688,0.000852167631694537,1.51776866979442E-7,1,2,13.0063810348511,5.00093026617996,34.0199992060661,1.101969958204,0.16454813963354,1,2.53585541401895E-6,,,,,,,,,,,,,,,,,,,,,204.00959777832,204.179763793945,1000.22534179688,1000.22534179688,55.2775505085251,5.52783484161585,8.40471267700195,26,1,0,0,1,0.293807983398438,33.7243423461914,2,1,1,204.00959777832,0,4232058752,204.094680786133,,,,,,,,,,,,,,,,,,,,,,,,,,,,,,,,,
,3874594467.32456,201.085258483887,1000.22534179688,0.00085653301177295,1.33894588656098E-7,1,2,13.0063810348511,5.00088474209215,34.0199992060661,1.10757680866305,0.16555386326203,1,2.67630871194831E-6,,,,,,,,,,,,,,,,,,,,,201.006195068359,201.164321899414,1000.22534179688,1000.22534179688,55.3811162873232,5.52811687436631,8.3650951385498,26,1,0,0,1,0.294113159179687,33.7243423461914,2,1,1,201.006195068359,0,4232058688,201.085258483887,,,,,,,,,,,,,,,,,,,,,,,,,,,,,,,,,
,3874594503.28807,198.086723327637,1000.22534179688,0.000861037363260044,1.08501467250269E-7,1,2,13.0063810348511,5.00090267408105,34.0199992060661,1.11338352083397,0.166585295396355,1,2.81404616876124E-6,,,,,,,,,,,,,,,,,,,,,198.00212097168,198.171325683594,1000.22534179688,1000.22534179688,55.4264507414386,5.52774434178943,8.35527229309082,26,1,0,0,1,0.292739868164063,33.7243423461914,2,1,1,198.00212097168,0,4232058688,198.086723327637,,,,,,,,,,,,,,,,,,,,,,,,,,,,,,,,,
,3874594539.26375,195.038093566895,1000.22534179688,0.000864928871941944,1.24095026896568E-7,1,2,13.0063810348511,5.00103000337669,34.000001847744,1.11850055714577,0.167034377489373,1,2.58733908768589E-6,,,,,,,,,,,,,,,,,,,,,194.943023681641,195.133163452148,1000.22534179688,1000.22534179688,55.2869300507558,5.52716510915375,8.28281784057617,26,1,0,0,1,0.292739868164063,32.7468223571777,2,1,1,194.943023681641,0,4232058592,195.038093566895,,,,,,,,,,,,,,,,,,,,,,,,,,,,,,,,,
,3874594575.24146,192.068077087402,1000.22534179688,0.000869250061754806,1.043130845255E-7,1,2,13.0063810348511,5.00095267376156,34.000001847744,1.12404085277997,0.168025867156171,1,2.72440915350339E-6,,,,,,,,,,,,,,,,,,,,,191.981369018555,192.15478515625,1000.22534179688,1000.22534179688,55.3424256756212,5.52731155966147,8.25408458709717,26,1,0,0,1,0.292282104492188,33.7243423461914,2,1,1,191.981369018555,0,4232058784,192.068077087402,,,,,,,,,,,,,,,,,,,,,,,,,,,,,,,,,
,3874594611.20844,189.056526184082,1000.22534179688,0.000873508203734672,9.5370392345337E-8,1,2,13.0063810348511,5.00095171590975,34.000001847744,1.12956525524582,0.168722900604358,1,2.64034558050125E-6,,,,,,,,,,,,,,,,,,,,,188.973449707031,189.139602661133,1000.22534179688,1000.22534179688,55.361966388602,5.52731159250705,8.24133586883545,26,1,0,0,1,0.291748046875,33.7243423461914,2,1,1,188.973449707031,0,4232058784,189.056526184082,,,,,,,,,,,,,,,,,,,,,,,,,,,,,,,,,
,3874594647.21109,186.052177429199,1000.22534179688,0.000877671903199432,1.18802836993858E-7,1,2,13.0063810348511,5.00099452543523,34.000001847744,1.13497372985362,0.169456083902087,1,2.59644116519249E-6,,,,,,,,,,,,,,,,,,,,,185.963348388672,186.141006469727,1000.22534179688,1000.22534179688,55.3529776606309,5.52750219765575,8.17219161987305,26,1,0,0,1,0.291595458984375,33.2355842590332,2,1,1,185.963348388672,0,4232058688,186.052177429199,,,,,,,,,,,,,,,,,,,,,,,,,,,,,,,,,
,3874594683.19092,183.067604064941,1000.22534179688,0.000881670099165263,1.31122776615183E-7,1,2,13.0063810348511,5.00095899975734,33.9899994432926,1.14009618709154,0.170476330361796,1,2.80149894153964E-6,,,,,,,,,,,,,,,,,,,,,182.987030029297,183.148178100586,1000.22534179688,1000.22534179688,55.2372966397847,5.52760676348308,8.16325569152832,26,1,0,0,1,0.290908813476562,33.7243423461914,2,1,1,182.987030029297,0,4232058592,183.067604064941,,,,,,,,,,,,,,,,,,,,,,,,,,,,,,,,,
,3874594719.18896,180.06217956543,1000.22534179688,0.000885961197688282,1.0889451108093E-7,1,2,13.0063810348511,5.00091399428193,33.9899994432926,1.14563823692127,0.171252135317131,1,2.77512847714976E-6,,,,,,,,,,,,,,,,,,,,,179.97900390625,180.145355224609,1000.22534179688,1000.22534179688,55.3420348613616,5.52800691005859,8.13621234893799,26,1,0,0,1,0.29052734375,33.7243423461914,2,1,1,179.97900390625,0,4232058752,180.06217956543,,,,,,,,,,,,,,,,,,,,,,,,,,,,,,,,,
,3874594755.17994,177.079414367676,1000.22534179688,0.000890189847441401,1.16982007522744E-7,1,2,13.0063810348511,5.00094842227507,33.9699983596802,1.15112245377981,0.172036392850567,1,2.76149542477471E-6,,,,,,,,,,,,,,,,,,,,,176.992614746094,177.166213989258,1000.22534179688,1000.22534179688,55.3056891352174,5.52731867453743,8.07161426544189,26,1,0,0,1,0.293045043945313,33.7243423461914,2,1,1,176.992614746094,0,4232058720,177.079414367676,,,,,,,,,,,,,,,,,,,,,,,,,,,,,,,,,
,3874594791.14248,174.084815979004,1000.22534179688,0.000894298802341794,1.20390748372885E-7,1,2,13.0063810348511,5.00089292520785,33.9699983596802,1.15641532937614,0.172845544911797,1,2.78795376340102E-6,,,,,,,,,,,,,,,,,,,,,174.000259399414,174.169372558594,1000.22534179688,1000.22534179688,55.3686102310155,5.52761107292044,8.06722450256348,26,1,0,0,1,0.2935791015625,33.2355842590332,2,1,1,174.000259399414,0,4232058496,174.084815979004,,,,,,,,,,,,,,,,,,,,,,,,,,,,,,,,,
,3874594827.11717,171.081199645996,1000.22534179688,0.000898360200012913,1.34009327288519E-7,1,2,13.0063810348511,5.00094702134525,33.950001001358,1.16170478633471,0.173495414177189,1,2.6941634541597E-6,,,,,,,,,,,,,,,,,,,,,171.011138916016,171.151260375977,1000.22534179688,1000.22534179688,55.331482876352,5.52749311982242,8.03959369659424,26,1,0,0,1,0.291900634765625,33.2355842590332,2,1,1,171.011138916016,0,4232058720,171.081199645996,,,,,,,,,,,,,,,,,,,,,,,,,,,,,,,,,
,3874594863.09526,168.081413269043,1000.22534179688,0.000902691366976266,1.1481651553835E-7,1,2,13.0063810348511,5.00099979893518,33.9599996805191,1.16730206797747,0.174475977054536,1,2.81655880779627E-6,,,,,,,,,,,,,,,,,,,,,168.004943847656,168.15788269043,1000.22534179688,1000.22534179688,55.3189768200443,5.52727577853224,7.98327255249023,26,1,0,0,1,0.291213989257812,33.2355842590332,2,1,1,168.004943847656,0,4232058752,168.081413269043,,,,,,,,,,,,,,,,,,,,,,,,,,,,,,,,,
,3874594899.11298,165.083068847656,1000.22534179688,0.00090693444781284,9.88476485423411E-8,1,2,13.0063810348511,5.00095381148708,33.950001001358,1.17278140912381,0.175242526502133,1,2.7901272254636E-6,,,,,,,,,,,,,,,,,,,,,164.999099731445,165.167037963867,1000.22534179688,1000.22534179688,55.4092549140155,5.52738954036133,7.98390626907349,26,1,0,0,1,0.292434692382812,33.7243423461914,2,1,1,164.999099731445,0,4232058688,165.083068847656,,,,,,,,,,,,,,,,,,,,,,,,,,,,,,,,,
,3874594935.0703,162.07154083252,1000.22534179688,0.000910971518407887,7.58998617495593E-8,1,2,13.0063810348511,5.00098654397808,33.950001001358,1.17801379895907,0.1760160666656,1,2.79626245546082E-6,,,,,,,,,,,,,,,,,,,,,161.980484008789,162.16259765625,1000.22534179688,1000.22534179688,55.2701250375924,5.5274647368712,7.95508623123169,26,1,0,0,1,0.291900634765625,34.2131004333496,2,1,1,161.980484008789,0,4232058688,162.07154083252,,,,,,,,,,,,,,,,,,,,,,,,,,,,,,,,,
,3874594971.04062,159.038055419922,1000.22534179688,0.000914865883634931,1.1689452069575E-7,1,2,13.0063810348511,5.0009717648818,33.9299999177456,1.18307969029451,0.176529842761814,1,2.62428372663151E-6,,,,,,,,,,,,,,,,,,,,,158.955490112305,159.120620727539,1000.22534179688,1000.22534179688,55.2931830789097,5.52798367390613,7.90930414199829,26,1,0,0,1,0.293350219726562,34.2131004333496,2,1,1,158.955490112305,0,4232058624,159.038055419922,,,,,,,,,,,,,,,,,,,,,,,,,,,,,,,,,
,3874595007.03776,156.07160949707,1000.22534179688,0.000918866154758151,1.13318132338162E-7,1,2,13.0063810348511,5.00099341065404,33.9299999177456,1.18823409331347,0.177479257523204,1,2.77215828004195E-6,,,,,,,,,,,,,,,,,,,,,155.998992919922,156.144226074219,1000.22534179688,1000.22534179688,55.4256691129193,5.5275970826695,7.90602540969849,26,1,0,0,1,0.293045043945313,33.7243423461914,2,1,1,155.979614257813,0,4232058720,156.07160949707,,,,,,,,,,,,,,,,,,,,,,,,,,,,,,,,,
,3874595043.02287,153.076850891113,1000.22534179688,0.000923116410417022,1.42318616966706E-7,1,2,13.0063810348511,5.00060760061051,33.9299999177456,1.19359754869927,0.178310448375188,1,2.80774031873187E-6,,,,,,,,,,,,,,,,,,,,,152.992553710938,153.161148071289,1000.22534179688,1000.22534179688,55.3799438445443,5.52888219580616,7.86603927612305,26,1,0,0,1,0.294876098632812,33.7243423461914,2,1,1,152.992553710938,0,4232058688,153.076850891113,,,,,,,,,,,,,,,,,,,,,,,,,,,,,,,,,
,3874595079.04905,150.064437866211,1000.22534179688,0.000927170633793105,9.61497467627562E-8,1,2,13.0063810348511,5.00086335263821,33.9299999177456,1.19891087148575,0.179204497498151,1,2.89594202464988E-6,,,,,,,,,,,,,,,,,,,,,149.990524291992,150.13835144043,1000.22534179688,1000.22534179688,55.3346093904289,5.52813681910273,7.82043075561523,26,1,0,0,1,0.292129516601562,33.7243423461914,2,1,1,149.990524291992,0,4232058688,150.064437866211,,,,,,,,,,,,,,,,,,,,,,,,,,,,,,,,,
,3874595115.0117,147.010055541992,1000.22534179688,0.000931168848222612,1.24455149533046E-7,1,2,13.0063810348511,5.00092359394397,33.9200012385845,1.20410058360328,0.179984091099645,1,2.91135987679547E-6,,,,,,,,,,,,,,,,,,,,,146.92951965332,147.090591430664,1000.22534179688,1000.22534179688,55.2986544785443,5.52812250496174,7.81516885757446,26,1,0,0,1,0.290756225585937,33.2355842590332,2,1,1,146.92951965332,0,4232058656,147.010055541992,,,,,,,,,,,,,,,,,,,,,,,,,,,,,,,,,
,3874595151.00333,144.065078735352,1000.22534179688,0.000935018710551628,1.09511091963565E-7,1,2,13.0063810348511,5.00095856149744,33.9099988341331,1.20909727764273,0.180684742966182,1,2.88842408530979E-6,,,,,,,,,,,,,,,,,,,,,143.983871459961,144.146286010742,1000.22534179688,1000.22534179688,55.4041743286405,5.52749816295976,7.76565933227539,26,1,0,0,1,0.289764404296875,33.2355842590332,2,1,1,143.983871459961,0,4232058496,144.065078735352,,,,,,,,,,,,,,,,,,,,,,,,,,,,,,,,,
,3874595187.00772,140.936218261719,1000.22534179688,0.000939217023006635,9.43537557900028E-8,1,2,13.0063810348511,5.00093645058943,33.9099988341331,1.21452895459646,0.181425051562566,1,2.84739203180217E-6,,,,,,,,,,,,,,,,,,,,,140.861358642578,141.011077880859,1000.22534179688,1000.22534179688,55.3420348613616,5.52782969953192,7.7381911277771,24,1,64,0,0,0.290451049804687,33.7243423461914,2,1,1,140.861358642578,0,4232058560,140.936218261719,,,,,,,,,,,,,,,,,,,,,,,,,,,,,,,,,
,3874595223.22585,137.825523376465,1000.22534179688,0.00094328551293895,1.17685738798213E-7,1,2,13.0063810348511,5.00091389575534,33.890001475811,1.21978409476965,0.182197964599323,1,2.85057763419133E-6,,,,,,,,,,,,,,,,,,,,,137.782943725586,137.868103027344,1000.22534179688,1000.22534179688,55.3424256756212,5.52805195787314,7.73359107971191,24,1,64,0,0,0.29296875,33.7243423461914,2,1,1,137.782943725586,0,4232058528,137.825523376465,,,,,,,,,,,,,,,,,,,,,,,,,,,,,,,,,
,3874595258.97578,134.857841491699,1000.22534179688,0.000947199407956185,8.47751370913343E-8,1,2,13.0063810348511,5.00099351399986,33.890001475811,1.22484072214134,0.183174865216446,1,3.03002903163014E-6,,,,,,,,,,,,,,,,,,,,,134.790740966797,134.924942016602,1000.22534179688,1000.22534179688,55.3373450902462,5.52760931740923,7.69233989715576,24,1,64,0,0,0.291290283203125,33.7243423461914,2,1,1,134.790740966797,0,4232058592,134.857841491699,,,,,,,,,,,,,,,,,,,,,,,,,,,,,,,,,
,3874595294.96987,131.861625671387,1000.22534179688,0.000951055137117376,9.82959379592814E-8,1,2,13.0063810348511,5.00099351210776,33.890001475811,1.22982785654937,0.183912155803828,1,3.0359071791019E-6,,,,,,,,,,,,,,,,,,,,,131.787551879883,131.935699462891,1000.22534179688,1000.22534179688,55.3607939458232,5.52772252165183,7.64125537872314,25,1,64,0,0,0.293502807617188,33.7243423461914,2,1,1,131.787551879883,0,4232058688,131.861625671387,,,,,,,,,,,,,,,,,,,,,,,,,,,,,,,,,
,3874595330.9857,128.863952636719,1000.22534179688,0.000954694102378343,1.46107392883523E-7,1,2,13.0063810348511,5.00092978388178,33.890001475811,1.23447892609019,0.184835437873564,1,3.2197979026691E-6,,,,,,,,,,,,,,,,,,,,,128.800064086914,128.927841186523,1000.22534179688,1000.22534179688,55.3432073041405,5.52777774545908,7.65172004699707,25,1,64,0,0,0.29144287109375,33.7243423461914,2,1,1,128.800064086914,0,4232058592,128.863952636719,,,,,,,,,,,,,,,,,,,,,,,,,,,,,,,,,
,3874595367.1915,125.846626281738,1000.22534179688,0.000958463626033026,1.63854818910831E-7,1,2,13.0063810348511,5.00085413716185,33.8700003921986,1.23935285259137,0.185384617925987,1,3.09591513428306E-6,,,,,,,,,,,,,,,,,,,,,125.787780761719,125.905471801758,1000.22534179688,1000.22534179688,55.290838193352,5.52846367010976,7.59063005447388,24,1,64,0,0,0.2911376953125,33.2355842590332,2,1,1,125.787780761719,0,4232058656,125.846626281738,,,,,,,,,,,,,,,,,,,,,,,,,,,,,,,,,
,3874595402.90251,122.79776763916,1000.22534179688,0.00096236095841233,1.15298478953596E-7,1,2,13.0063810348511,5.00041752082963,33.8700003921986,1.24426233806891,0.18596840248869,1,2.99458123324722E-6,,,,,,,,,,,,,,,,,,,,,122.736473083496,122.859062194824,1000.22534179688,1000.22534179688,55.3846336156597,5.5300858849031,7.55768299102783,24,1,64,0,0,0.292816162109375,33.2355842590332,2,1,1,122.736473083496,0,4232058752,122.79776763916,,,,,,,,,,,,,,,,,,,,,,,,,,,,,,,,,
,3874595438.90423,119.85807800293,1000.22534179688,0.000966157909030392,1.14335260328558E-7,1,2,13.0063810348511,5.00064380982941,33.8700003921986,1.24923573193613,0.186814065842003,1,3.0838133228731E-6,,,,,,,,,,,,,,,,,,,,,119.782089233398,119.934066772461,1000.22534179688,1000.22534179688,55.3033442496597,5.52902866240523,7.56987476348877,24,1,64,0,0,0.292510986328125,33.2355842590332,2,1,1,119.782089233398,0,4232058624,119.85807800293,,,,,,,,,,,,,,,,,,,,,,,,,,,,,,,,,
,3874595474.82513,116.857948303223,1000.22534179688,0.00096970621984554,1.71479887543241E-7,1,2,13.0063810348511,5.00073356468583,33.8700003921986,1.25385762487297,0.187487378814912,1,3.0816304025435E-6,,,,,,,,,,,,,,,,,,,,,116.779151916504,116.936744689941,1000.22534179688,1000.22534179688,55.341644047102,5.52853837641561,7.50804138183594,26,1,0,0,1,0.2923583984375,33.7243423461914,2,1,1,116.779151916504,0,4232058656,116.857948303223,,,,,,,,,,,,,,,,,,,,,,,,,,,,,,,,,
,3874595510.8157,113.856647491455,1000.22534179688,0.000973368478132102,1.15517671930841E-7,1,2,13.0063810348511,5.00077971340306,33.8700003921986,1.25861295040822,0.188172455499101,1,3.07361599617493E-6,,,,,,,,,,,,,,,,,,,,,113.775039672852,113.938255310059,1000.22534179688,1000.22534179688,55.3478970752559,5.52821687358249,7.48065137863159,26,1,0,0,1,0.293502807617188,33.7243423461914,2,1,1,113.775039672852,0,4232058720,113.856647491455,,,,,,,,,,,,,,,,,,,,,,,,,,,,,,,,,
,3874595546.78454,110.887088775635,1000.22534179688,0.00097675812418326,1.18098609230021E-7,1,2,13.0063810348511,5.00071743338006,33.8499993085861,1.2629686032432,0.188861258168842,1,3.11276202020239E-6,,,,,,,,,,,,,,,,,,,,,110.802978515625,110.971199035645,1000.22534179688,1000.22534179688,55.3181951915251,5.52855695203294,7.48516178131103,26,1,0,0,1,0.291366577148438,33.2355842590332,2,1,1,110.802978515625,0,4232058656,110.887088775635,,,,,,,,,,,,,,,,,,,,,,,,,,,,,,,,,
,3874595582.75564,107.895610809326,1000.22534179688,0.000980223176185757,1.23466370997805E-7,1,2,13.0063810348511,5.00072748564973,33.8499993085861,1.26746788136744,0.189426912304677,1,3.04274322727017E-6,,,,,,,,,,,,,,,,,,,,,107.794357299805,107.996864318848,1000.22534179688,1000.22534179688,55.2845851651982,5.5286126999596,7.4172625541687,26,1,0,0,1,0.292434692382812,33.2355842590332,2,1,1,107.794357299805,0,4232058624,107.895610809326,,,,,,,,,,,,,,,,,,,,,,,,,,,,,,,,,
,3874595618.72362,104.893295288086,1000.22534179688,0.000983692085313063,1.244120878232E-7,1,2,13.0063810348511,5.00074449013811,33.8499993085861,1.27195869478536,0.190102680619069,1,3.05699298903626E-6,,,,,,,,,,,,,,,,,,,,,104.819931030273,104.966659545898,1000.22534179688,1000.22534179688,55.3475062609962,5.52886759944111,7.40769529342651,26,1,0,0,1,0.2935791015625,33.7243423461914,2,1,1,104.819931030273,0,4232058752,104.893295288086,,,,,,,,,,,,,,,,,,,,,,,,,,,,,,,,,
,3874595654.74881,101.880191802979,1000.22534179688,0.000986634044829,1.07005056691568E-7,1,2,13.0063810348511,5.00074265048849,33.8499993085861,1.27580548031454,0.190374764391334,1,2.83704085161077E-6,,,,,,,,,,,,,,,,,,,,,101.801345825195,101.959037780762,1000.22534179688,1000.22534179688,55.3482878895155,5.52859313768133,7.38694906234741,26,1,0,0,1,0.292739868164063,33.2355842590332,2,1,1,101.801345825195,0,4232058656,101.880191802979,,,,,,,,,,,,,,,,,,,,,,,,,,,,,,,,,
,3874595690.6934,98.911434173584,1000.22534179688,0.000990432275450195,1.53176868692778E-7,1,2,13.0063810348511,5.00078438227228,33.8299982249737,1.28066889607111,0.191540163100949,1,3.18058084303566E-6,,,,,,,,,,,,,,,,,,,,,98.8374710083008,98.9853973388672,1000.22534179688,1000.22534179688,55.3482878895155,5.52837258737023,7.33465719223022,26,1,0,0,1,0.291824340820313,33.2355842590332,2,1,1,98.8374710083008,0,4232058688,98.911434173584,,,,,,,,,,,,,,,,,,,,,,,,,,,,,,,,,
,3874595726.69482,95.9083366394043,1000.22534179688,0.000993771555312731,1.1957256149289E-7,1,2,13.0063810348511,5.00074593306985,33.8299982249737,1.28497643902585,0.192159948320965,1,3.17279955940932E-6,,,,,,,,,,,,,,,,,,,,,95.8293914794922,95.9872817993164,1000.22534179688,1000.22534179688,55.3154594917078,5.52818778083301,7.31610107421875,26,1,0,0,1,0.292739868164063,33.7243423461914,2,1,1,95.8293914794922,0,4232058592,95.9083366394043,,,,,,,,,,,,,,,,,,,,,,,,,,,,,,,,,
,3874595762.66683,92.9312438964844,1000.22534179688,0.000996766240285769,1.52249609217911E-7,1,2,13.0063810348511,5.00079129046229,33.840000629425,1.28889066476137,0.192565759476275,1,3.04654905214117E-6,,,,,,,,,,,,,,,,,,,,,92.8547058105469,93.0077819824219,1000.22534179688,1000.22534179688,55.3858060584386,5.52862324409935,7.28936958312988,26,1,0,0,1,0.289382934570313,33.7243423461914,2,1,1,92.8547058105469,0,4232058624,92.9312438964844,,,,,,,,,,,,,,,,,,,,,,,,,,,,,,,,,
,3874595798.64813,89.9300651550293,1000.22534179688,0.000999977387886709,1.52117909857206E-7,1,2,13.0063810348511,5.00077828810397,33.8199995458126,1.2929898484499,0.193516099532084,1,3.31198048278523E-6,,,,,,,,,,,,,,,,,,,,,89.8458786010742,90.0142517089844,1000.22534179688,1000.22534179688,55.2970912215058,5.52906888035386,7.23657941818237,26,1,0,0,1,0.290374755859375,33.7243423461914,2,1,1,89.8458786010742,0,4232058784,89.9300651550293,,,,,,,,,,,,,,,,,,,,,,,,,,,,,,,,,
,3874595834.63351,86.9244079589844,1000.22534179688,0.00100302349324585,1.77263017779519E-7,1,2,13.0063810348511,5.00079235119939,33.8199995458126,1.29691643596173,0.194223740119194,1,3.41281667129986E-6,,,,,,,,,,,,,,,,,,,,,86.8404235839844,87.0083923339844,1000.22534179688,1000.22534179688,55.3072523922559,5.52829514008815,7.2233738899231,26,1,0,0,1,0.293045043945313,33.2355842590332,2,1,1,86.8404235839844,0,4232058560,86.9244079589844,,,,,,,,,,,,,,,,,,,,,,,,,,,,,,,,,
,3874595870.60696,83.9358329772949,1000.22534179688,0.00100571161750727,1.39390398824501E-7,1,2,13.0063810348511,5.00081962720353,33.8199995458126,1.30045745914229,0.19436726067398,1,3.12939414908684E-6,,,,,,,,,,,,,,,,,,,,,83.8594665527344,84.0121994018555,1000.22534179688,1000.22534179688,55.3881509439962,5.52874516205244,7.18458318710327,26,1,0,0,1,0.29296875,33.2355842590332,2,1,1,83.8594665527344,0,4232058848,83.9358329772949,,,,,,,,,,,,,,,,,,,,,,,,,,,,,,,,,
,3874595906.60109,80.8972282409668,1000.22534179688,0.00100836202309759,1.81131955729957E-7,1,2,13.0063810348511,5.000816779199,33.8100008666515,1.30383727738257,0.195195921102243,1,3.38236461676973E-6,,,,,,,,,,,,,,,,,,,,,80.8065795898438,80.9878768920898,1000.22534179688,1000.22534179688,55.3525868463712,5.52857816797188,7.12955093383789,26,1,0,0,1,0.290756225585937,33.2355842590332,2,1,1,80.8065795898438,0,4232058784,80.8972282409668,,,,,,,,,,,,,,,,,,,,,,,,,,,,,,,,,
,3874595942.58809,77.8641242980957,1000.22534179688,0.0010111486524373,1.49337232586737E-7,1,2,13.0063810348511,5.00090728766846,33.8100008666515,1.30750472875096,0.195526590000128,1,3.22652504991182E-6,,,,,,,,,,,,,,,,,,,,,77.7809829711914,77.947265625,1000.22534179688,1000.22534179688,55.2884933077943,5.52829049625794,7.12792539596558,26,1,0,0,1,0.292892456054687,33.7243423461914,2,1,1,77.7809829711914,0,4232058656,77.8641242980957,,,,,,,,,,,,,,,,,,,,,,,,,,,,,,,,,
,3874595978.56796,74.8228530883789,1000.22534179688,0.00101371705594053,1.2411859634268E-7,1,2,13.0063810348511,5.00098579407421,33.8100008666515,1.31086833531414,0.195933690500069,1,3.16218083299144E-6,,,,,,,,,,,,,,,,,,,,,74.7386322021484,74.9070739746094,1000.22534179688,1000.22534179688,55.3447705611789,5.52924730628104,7.09109210968018,26,1,0,0,1,0.290908813476562,33.7243423461914,2,1,1,74.7386322021484,0,4232058784,74.8228530883789,,,,,,,,,,,,,,,,,,,,,,,,,,,,,,,,,
,3874596014.56417,71.7797622680664,1000.22534179688,0.00101527149159259,1.56251713050889E-7,1,2,13.0063810348511,5.00080357000727,33.7999984622002,1.31289608495914,0.195647228724147,1,2.72105885438588E-6,,,,,,,,,,,,,,,,,,,,,71.6975631713867,71.8619613647461,1000.22534179688,1000.22534179688,55.2798953940828,5.5284322691757,7.0261402130127,26,1,0,0,1,0.294189453125,33.7243423461914,2,1,1,71.6975631713867,0,4232058656,71.7797622680664,,,,,,,,,,,,,,,,,,,,,,,,,,,,,,,,,
,3874596050.51219,68.7455978393555,1000.22534179688,0.0010185708011555,8.85444241501355E-8,1,2,13.0063810348511,5.00081614425225,33.8100008666515,1.31705421151941,0.197056115190992,1,3.32697251459038E-6,,,,,,,,,,,,,,,,,,,,,68.661979675293,68.829216003418,1000.22534179688,1000.22534179688,55.3588398745251,5.5281627532197,7.02953958511353,26,1,0,0,1,0.290298461914063,33.7243423461914,2,1,1,68.661979675293,0,4232058720,68.7455978393555,,,,,,,,,,,,,,,,,,,,,,,,,,,,,,,,,
,3874596086.50183,65.7089538574219,1000.22534179688,0.00102077660949364,9.96479647460326E-8,1,2,13.0063810348511,5.00084352183884,33.7899997830391,1.31993962705202,0.197326219986549,1,3.21193095503481E-6,,,,,,,,,,,,,,,,,,,,,65.6383590698242,65.7795486450195,1000.22534179688,1000.22534179688,55.367046973977,5.52800100738607,6.96520280838013,26,1,0,0,1,0.291366577148438,33.2355842590332,2,1,1,65.6383590698242,0,4232058752,65.7089538574219,,,,,,,,,,,,,,,,,,,,,,,,,,,,,,,,,
,3874596122.54258,62.6640777587891,1000.22534179688,0.00102271012816755,1.18670985417049E-7,1,2,13.0063810348511,5.00089278948045,33.7899997830391,1.32242439267177,0.197932342355995,1,3.3955207334763E-6,,,,,,,,,,,,,,,,,,,,,62.5949630737305,62.7331924438477,1000.22534179688,1000.22534179688,55.3201492628231,5.52799200201733,6.90034008026123,26,1,0,0,1,0.291900634765625,33.7243423461914,2,1,1,62.5949630737305,0,4232058560,62.6640777587891,,,,,,,,,,,,,,,,,,,,,,,,,,,,,,,,,
,3874596158.46294,59.635570526123,1000.22534179688,0.00102505963153008,1.11542645529529E-7,1,2,13.0063810348511,5.00086321091233,33.7899997830391,1.3254453054467,0.198427786674285,1,3.43606922205977E-6,,,,,,,,,,,,,,,,,,,,,59.5491981506348,59.7219429016113,1000.22534179688,1000.22534179688,55.3095972778135,5.52800661878897,6.90740585327148,26,1,0,0,1,0.291213989257812,33.2355842590332,2,1,1,59.5491981506348,0,4232058752,59.635570526123,,,,,,,,,,,,,,,,,,,,,,,,,,,,,,,,,
,3874596194.43971,56.5954437255859,1000.22534179688,0.00102689354240351,1.01212043598521E-7,1,2,13.0063810348511,5.00089974031227,33.780001103878,1.32783192648081,0.198772736812557,1,3.43288048166292E-6,,,,,,,,,,,,,,,,,,,,,56.5171432495117,56.6737442016602,1000.22534179688,1000.22534179688,55.3838519871405,5.52790745292049,6.82283210754394,26,1,0,0,1,0.291976928710937,33.7243423461914,2,1,1,56.5171432495117,0,4232058784,56.5954437255859,,,,,,,,,,,,,,,,,,,,,,,,,,,,,,,,,
,3874596230.44088,53.5625305175781,1000.22534179688,0.00102848861641858,1.96351951142977E-7,1,2,13.0063810348511,5.00081634564647,33.7699986994266,1.3298627332439,0.199082178786625,1,3.44232466231872E-6,,,,,,,,,,,,,,,,,,,,,53.4751510620117,53.6499099731445,1000.22534179688,1000.22534179688,55.3330461333905,5.52852684830273,6.77935981750488,26,1,0,0,1,0.2935791015625,33.2355842590332,2,1,1,53.4751510620117,0,4232058528,53.5625305175781,,,,,,,,,,,,,,,,,,,,,,,,,,,,,,,,,
,3874596266.41083,50.5310325622559,1000.22534179688,0.00103000253931312,1.87396656307358E-7,1,2,13.0063810348511,5.00079284326325,33.7699986994266,1.33180796030123,0.199398414901562,1,3.46632778559036E-6,,,,,,,,,,,,,,,,,,,,,50.4531097412109,50.6089553833008,1000.22534179688,1000.22534179688,55.3733000021309,5.52846680601795,6.7522497177124,26,1,0,0,1,0.29388427734375,33.2355842590332,2,1,1,50.4531097412109,0,4232058624,50.5310325622559,,,,,,,,,,,,,,,,,,,,,,,,,,,,,,,,,
,3874596302.41485,47.490795135498,1000.22534179688,0.0010315455764712,1.09560892643852E-7,1,2,13.0063810348511,5.00076171077128,33.7699986994266,1.3337924168432,0.199689442730276,1,3.46691754051833E-6,,,,,,,,,,,,,,,,,,,,,47.3994750976562,47.5821151733398,1000.22534179688,1000.22534179688,55.3541501034097,5.52852431554196,6.66350412368774,26,1,0,0,1,0.294113159179687,33.7243423461914,2,1,1,47.3994750976562,0,4232058624,47.490795135498,,,,,,,,,,,,,,,,,,,,,,,,,,,,,,,,,
,3874596338.42345,44.453763961792,1000.22534179688,0.0010327967727986,1.23440952587527E-7,1,2,13.0063810348511,5.00074038249719,33.7699986994266,1.33539208556185,0.200000107529799,1,3.52495892515822E-6,,,,,,,,,,,,,,,,,,,,,44.3668479919434,44.5406799316406,1000.22534179688,1000.22534179688,55.2970912215058,5.52849479480657,6.61276912689209,26,1,0,0,1,0.292129516601562,33.7243423461914,2,1,1,44.3668479919434,0,4232058624,44.453763961792,,,,,,,,,,,,,,,,,,,,,,,,,,,,,,,,,
,3874596374.35254,41.3519859313965,1000.22534179688,0.00103381237868983,1.48127054995902E-7,1,2,13.0063810348511,5.00071355116347,33.7699986994266,1.33666083021968,0.200430544565274,1,3.7102900026754E-6,,,,,,,,,,,,,,,,,,,,,41.2704467773438,41.4335250854492,1000.22534179688,1000.22534179688,55.3303104335732,5.52849436138298,6.58227777481079,26,1,0,0,1,0.293655395507812,33.7243423461914,2,1,1,41.2704467773438,0,4232058752,41.3519859313965,,,,,,,,,,,,,,,,,,,,,,,,,,,,,,,,,
,3874596410.34086,38.3802738189697,1000.22534179688,0.00103500557637339,1.35418032763492E-7,1,2,13.0063810348511,5.0007611391916,33.7699986994266,1.33827293808648,0.200311754754343,1,3.44186495208699E-6,,,,,,,,,,,,,,,,,,,,,38.2955131530762,38.4650344848633,1000.22534179688,1000.22534179688,55.3326553191309,5.52828652745878,6.48942947387695,26,1,0,0,1,0.2935791015625,33.7243423461914,2,1,1,38.2955131530762,0,4232058752,38.3802738189697,,,,,,,,,,,,,,,,,,,,,,,,,,,,,,,,,
,3874596446.326,35.3544940948486,1000.22534179688,0.00103576613214146,1.27183073306258E-7,1,2,13.0063810348511,5.00099093617871,33.7699986994266,1.33931961034246,0.200626194756472,1,3.56373528925067E-6,,,,,,,,,,,,,,,,,,,,,35.2742347717285,35.4347534179687,1000.22534179688,1000.22534179688,55.2462853677558,5.52781456738882,6.42341327667236,26,1,0,0,1,0.290603637695313,33.2355842590332,2,1,1,35.2742347717285,0,4232058528,35.3544940948486,,,,,,,,,,,,,,,,,,,,,,,,,,,,,,,,,
,3874596482.32174,32.324089050293,1000.22534179688,0.00103707527780059,9.31643295678637E-8,1,2,13.0063810348511,5.00102616039333,33.7500013411045,1.34092014667127,0.201602677375702,1,4.12548621330955E-6,,,,,,,,,,,,,,,,,,,,,32.2434196472168,32.4047584533691,1000.22534179688,1000.22534179688,55.3435981184001,5.52767431633526,6.3554368019104,26,1,0,0,1,0.290603637695313,33.7243423461914,2,1,1,32.2434196472168,0,4232058528,32.324089050293,,,,,,,,,,,,,,,,,,,,,,,,,,,,,,,,,
,3874596518.28968,29.3010005950928,1000.22534179688,0.00103794126716761,1.25976294607207E-7,1,2,13.0063810348511,5.00088878294764,33.7500013411045,1.34198218256586,0.201805998056969,1,4.16194378210672E-6,,,,,,,,,,,,,,,,,,,,,29.2156982421875,29.386302947998,1000.22534179688,1000.22534179688,55.3600123173039,5.52797140241551,6.22773456573486,26,1,0,0,1,0.290603637695313,33.7243423461914,2,1,1,29.2156982421875,0,4232058624,29.3010005950928,,,,,,,,,,,,,,,,,,,,,,,,,,,,,,,,,
,3874596554.30754,26.292368888855,1000.22534179688,0.00103875095670097,1.44509069022049E-7,1,2,13.0063810348511,5.00074062654803,33.7500013411045,1.34298689546707,0.201863828627876,1,4.09465272511129E-6,,,,,,,,,,,,,,,,,,,,,26.2244300842285,26.3603076934814,1000.22534179688,1000.22534179688,55.3260114767174,5.52852368380354,6.13045406341553,26,1,0,0,1,0.291900634765625,33.2355842590332,2,1,1,26.2073993682861,0,4232058624,26.292368888855,,,,,,,,,,,,,,,,,,,,,,,,,,,,,,,,,
,3874596590.27182,23.2588424682617,1000.22534179688,0.00103951260257187,1.74501047981313E-7,1,2,13.0063810348511,5.00077629589135,33.7500013411045,1.34400657917606,0.201866264774617,1,3.98356886546738E-6,,,,,,,,,,,,,,,,,,,,,23.159143447876,23.3585414886475,1000.22534179688,1000.22534179688,55.3166319344866,5.52860625391312,5.99301958084106,26,1,0,0,1,0.290985107421875,34.2131004333496,2,1,1,23.159143447876,0,4232058720,23.2588424682617,,,,,,,,,,,,,,,,,,,,,,,,,,,,,,,,,
,3874596626.27912,20.2789936065674,1000.22534179688,0.00104002190395464,1.52818862412482E-7,1,2,13.0063810348511,5.00084557626511,33.7500013411045,1.34467051087974,0.202109495932171,1,4.09406840573318E-6,,,,,,,,,,,,,,,,,,,,,20.2000999450684,20.3578872680664,1000.22534179688,1000.22534179688,55.3084248350347,5.52796065109138,5.77269840240478,26,1,0,0,1,0.290756225585937,33.2355842590332,2,1,1,20.2000999450684,0,4232058688,20.2789936065674,,,,,,,,,,,,,,,,,,,,,,,,,,,,,,,,,
,3874596662.25178,17.3081130981445,1000.22534179688,0.00104068287223341,1.18426949715287E-7,1,2,13.0063810348511,5.00085927707215,33.7600000202656,1.34552502440758,0.202274342003687,1,4.12420883465039E-6,,,,,,,,,,,,,,,,,,,,,17.2255191802979,17.3907070159912,1000.22534179688,1000.22534179688,55.2924014503905,5.52793791200585,5.55205154418945,26,1,0,0,1,0.290145874023438,33.7243423461914,2,1,1,17.2255191802979,0,4232058592,17.3081130981445,,,,,,,,,,,,,,,,,,,,,,,,,,,,,,,,,
,3874596698.30036,14.3576135635376,1000.22534179688,0.00104134917074999,1.3697885898399E-7,1,2,13.0063810348511,5.00081006517363,33.7500013411045,1.34636752692222,0.202404411788249,1,4.12943266917602E-6,,,,,,,,,,,,,,,,,,,,,14.2895374298096,14.4256896972656,1000.22534179688,1000.22534179688,55.3592306887847,5.52823707507976,4.86301231384277,26,1,0,0,1,0.291900634765625,33.7243423461914,2,1,1,14.2895374298096,0,4232058880,14.3576135635376,,,,,,,,,,,,,,,,,,,,,,,,,,,,,,,,,
,3874596742.17682,10.8445315361023,1000.22534179688,0.00104191285060578,1.6662939385078E-7,1,2,13.0063810348511,5.00076545117557,33.7500013411045,1.34712029438365,0.202232900335508,1,3.91634381438803E-6,,,,,,,,,,,,,,,,,,,,,10.7607507705688,10.9283123016357,1000.22534179688,1000.22534179688,55.3295288050539,5.52845670271961,4.42016267776489,26,1,0,0,1,0.290756225585937,33.2355842590332,2,1,1,10.7607507705688,0,4232058624,10.8445315361023,,,,,,,,,,,,,,,,,,,,,,,,,,,,,,,,,
,3874596778.23827,8.32104444503784,1000.22534179688,0.00104288477166945,1.49469198833557E-7,1,2,13.0063810348511,5.0007749112154,33.7600000202656,1.34835728781374,0.202580617452881,1,4.04254640114754E-6,,,,,,,,,,,,,,,,,,,,,8.2582368850708,8.38385200500488,1000.22534179688,1000.22534179688,55.2896657505732,5.52906610761846,4.14547157287598,26,1,0,0,1,0.290679931640625,33.7243423461914,6,1,1,8.2582368850708,0,4232059264,8.32104444503784,,,,,,,,,,,,,,,,,,,,,,,,,,,,,,,,,
,3874596814.14341,5.30614948272705,1000.22534179688,0.00104445748098529,1.27149045715968E-7,1,2,13.0063810348511,5.00074860407078,33.7500013411045,1.35036916795701,0.202963812282391,1,4.10985360939352E-6,,,,,,,,,,,,,,,,,,,,,5.23215007781982,5.38014888763428,1000.22534179688,1000.22534179688,55.3088156492943,5.52844725521315,3.6855845451355,26,1,0,0,1,0.2923583984375,33.7243423461914,2,1,1,5.23215007781982,0,4232058848,5.30614948272705,,,,,,,,,,,,,,,,,,,,,,,,,,,,,,,,,
,3874596850.12637,4.99992203712463,1000.22534179688,0.00104471668608988,1.2472955852277E-7,1,2,13.0063810348511,5.00071483242559,33.7600000202656,1.35070374833024,0.202928994906241,1,4.04650030548008E-6,,,,,,,,,,,,,,,,,,,,,4.99984121322632,5.00000286102295,1000.22534179688,1000.22534179688,55.3701734880539,5.52938317250581,3.52792811393738,26,1,0,0,1,0.291290283203125,33.7243423461914,5,1,1,5.00000286102295,0,4232058816,4.99992203712463,,,,,,,,,,,,,,,,,,,,,,,,,,,,,,,,,
,3874596880.09834,5.00001096725464,1000.22534179688,0.00104467253084541,1.37166150286593E-7,1,2,13.0063810348511,5.00079752349508,33.7500013411045,1.35068273558875,0.202891473745859,1,4.02033681018513E-6,,,,,,,,,,,,,,,,,,,,,4.99989557266235,5.00012636184692,1000.22534179688,1000.22534179688,55.2853667937174,5.5290207887418,3.48360323905945,26,1,0,0,1,0.293045043945313,33.2355842590332,1,1,1,5.00012636184692,0,4232058784,5.00001096725464,,,,,,,,,,,,,,,,,,,,,,,,,,,,,,,,,