File: example_report_creation/example_dir/sample_ID/qd_files/101022_00003.dat
[Header]
; MPMS3 Data File (default extension .dat)
; Copyright (c) 2007, Quantum Design, Inc. All rights reserved.
TITLE,
FILEOPENTIME,3874589111.16648,10/10/2022,6:45 pm
BYAPP,MPMS3 w/ AC,1.0,1.1
INFO,MPMS3 Measurement Release 1.1.16 Build 424, MultiVu Release 2.3.4.19,APPNAME
INFO,Linear Motor Servo Controller,MOTOR_MODULE_NAME
INFO,3101-100 J0,MOTOR_HW_VERSION
INFO,MMC721,MOTOR_SERIAL_NUMBER
INFO,01.04.28,MOTOR_SOFTWARE_VERSION
INFO,Quantum Design Squid Module,SQUID_MODULE_NAME
INFO,3101-501 B0,SQUID_HW_VERSION
INFO,SQM195,SQUID_SERIAL_NUMBER
INFO,01.03.04,SQUID_SOFTWARE_VERSION
INFO,SQUID AC,AC_MODULE_NAME
INFO,3101-401 f1,AC_HW_VERSION
INFO,SAC107,AC_SERIAL_NUMBER
INFO,SQUID AC 00.95.07,AC_SOFTWARE_VERSION
INFO,TCI166,COIL_SERIAL_NUMBER
INFO,0,MOMENT_UNITS
INFO,Quidel - 101022,SAMPLE_MATERIAL
INFO,,SAMPLE_COMMENT
INFO,1.38,SAMPLE_MASS
INFO,,SAMPLE_VOLUME
INFO,,SAMPLE_MOLECULAR_WEIGHT
INFO,,SAMPLE_SIZE
INFO,,SAMPLE_SHAPE
INFO,Brass,SAMPLE_HOLDER
INFO,Standard,SAMPLE_HOLDER_DETAIL
INFO,64.25,SAMPLE_OFFSET
DATATYPE,COMMENT,1
DATATYPE,TIME,2
STARTUPAXIS,X,2
STARTUPAXIS,Y1,5
FIELDGROUP, VSM,2,3,4,5,6,8,9,10,11,14,15
FIELDGROUP, DC, 2,3,4,14,56,57,58,59,60,61,62,63,64,65,66,67,68,69
FIELDGROUP, AC, 2,3,4,11,16,17,18,19,20,21,22,23,24,25,26,27,28,29,30
STARTUPGROUP, All
[Data]
Comment,Time Stamp (sec),Temperature (K),Magnetic Field (Oe),Moment (emu),M. Std. Err. (emu),Transport Action,Averaging Time (sec),Frequency (Hz),Peak Amplitude (mm),Center Position (mm),Lockin Signal' (V),Lockin Signal (V),Range,M. Quad. Signal (emu),AC Moment (emu),AC M. Std Err. (emu),AC Phase (deg),AC Phase Std. Err. (deg),AC Susceptibility (emu/Oe),AC Suscept. Std Err. (emu/Oe),AC X' (emu/Oe),AC X' Std Err. (emu/Oe),AC X'' (emu/Oe),AC X'' Std Err. (emu/Oe),AC Drive (Oe),AC Frequency (Hz),AC Averaging Time (sec),AC Cycles,AC Range,AC Measure Type,AC Signal' (V),AC Signal'' (V),AC Trim Coil Ratio,AC Trim Coil Phase,Min. Temperature (K),Max. Temperature (K),Min. Field (Oe),Max. Field (Oe),Mass (grams),Motor Lag (deg),Pressure (Torr),Measure Count,Measurement Number,SQUID Status (code),Motor Status (code),Measure Status (code),Motor Current (amps),Motor Temp. (C),Temp. Status (code),Field Status (code),Chamber Status (code),Chamber Temp (K),Redirection State,Evercool Status,Average Temp (K),Rotation Angle (deg),Rotator state,DC Moment Fixed Ctr (emu),DC Moment Err Fixed Ctr (emu),DC Moment Free Ctr (emu),DC Moment Err Free Ctr (emu),DC Fixed Fit,DC Free Fit,DC Calculated Center (mm),DC Calculated Center Err (mm),DC Scan Length (mm),DC Scan Time (s),DC Number of Points,DC Squid Drift,DC Min V (V),DC Max V (V),DC Scans per Measure,Map 01,Map 02,Map 03,Map 04,Map 05,Map 06,Map 07,Map 08,Map 09,Map 10,Map 11,Map 12,Map 13,Map 14,Map 15,Map 16
"ZFC, 1000",3874589111.2818
,3874589301.84286,7.30873441696167,1000.37194824219,0.000865237166455195,1.27483213066864E-7,1,2,13.0063810348511,5.00243606773017,33.7399989366531,1.11919892548345,0.168110377521709,1,3.32300207153995E-6,,,,,,,,,,,,,,,,,,,,,7.22839832305908,7.38907051086426,1000.37194824219,1000.37194824219,55.2623087524001,5.52302544223362,3.91501140594482,26,1,0,0,1,0.288619995117188,33.2355842590332,6,1,1,7.38907051086426,0,4232058912,7.30873441696167,,,,,,,,,,,,,,,,,,,,,,,,,,,,,,,,,
,3874589337.82866,10.0918941497803,1000.37194824219,0.00089221361053159,1.07863492558274E-7,1,2,13.0063810348511,5.00233077765739,33.7399989366531,1.15404978643965,0.173413303092644,1,3.47810811348893E-6,,,,,,,,,,,,,,,,,,,,,10.0150518417358,10.1687364578247,1000.37194824219,1000.37194824219,55.3596215030443,5.52332141235591,4.31439733505249,26,1,0,0,1,0.288619995117188,33.2355842590332,6,1,1,10.1687364578247,0,4232058816,10.0918941497803,,,,,,,,,,,,,,,,,,,,,,,,,,,,,,,,,
,3874589373.79857,12.9009428024292,1000.37194824219,0.000920427845468268,1.66161112736358E-7,1,2,13.0063810348511,5.00216219168885,33.7399989366531,1.19048128488195,0.178934882829889,1,3.62378309879201E-6,,,,,,,,,,,,,,,,,,,,,12.8284749984741,12.9734106063843,1000.37194824219,1000.37194824219,55.3775989589866,5.52400748316479,4.62574768066406,26,1,0,0,1,0.290374755859375,34.2131004333496,6,1,1,12.9902486801147,0,4232058720,12.9009428024292,,,,,,,,,,,,,,,,,,,,,,,,,,,,,,,,,
,3874589409.80704,15.7725958824158,1000.37194824219,0.00094843035786045,1.34636557470604E-7,1,2,13.0063810348511,5.00186705156547,33.7399989366531,1.22659691113646,0.184376337791681,1,3.74394245042654E-6,,,,,,,,,,,,,,,,,,,,,15.682107925415,15.8630838394165,1000.37194824219,1000.37194824219,55.4010478145636,5.52570497603556,4.84407377243042,26,1,0,0,1,0.29022216796875,33.2355842590332,2,1,1,15.8630838394165,0,4232058688,15.7725958824158,,,,,,,,,,,,,,,,,,,,,,,,,,,,,,,,,
,3874589445.77454,18.6931858062744,1000.37194824219,0.000973877385483106,1.41614938435296E-7,1,2,13.0063810348511,5.00161940524942,33.7399989366531,1.25953159269916,0.188549802765118,1,3.25673433811089E-6,,,,,,,,,,,,,,,,,,,,,18.6094818115234,18.7768898010254,1000.37194824219,1000.37194824219,55.4420833118232,5.52661601815029,5.60110902786255,26,1,0,0,1,0.29022216796875,33.2355842590332,2,1,1,18.7768898010254,0,4232058688,18.6931858062744,,,,,,,,,,,,,,,,,,,,,,,,,,,,,,,,,
,3874589481.75726,21.5639972686768,1000.37194824219,0.000994836371056977,1.57522240901183E-7,1,2,13.0063810348511,5.00146409385841,33.7399989366531,1.28663074121724,0.192269256349757,1,3.07176532621188E-6,,,,,,,,,,,,,,,,,,,,,21.4854049682617,21.6425895690918,1000.37194824219,1000.37194824219,55.3099880920732,5.52751225337127,5.77671813964844,26,1,0,0,1,0.29052734375,33.2355842590332,2,1,1,21.6425895690918,0,4232058656,21.5639972686768,,,,,,,,,,,,,,,,,,,,,,,,,,,,,,,,,
,3874589517.75479,24.4279117584229,1000.37194824219,0.00101020414400994,1.17918856124274E-7,1,2,13.0063810348511,5.00196406871999,33.7399989366531,1.30666992712257,0.195391394464612,1,3.21567847737208E-6,,,,,,,,,,,,,,,,,,,,,24.3495903015137,24.506233215332,1000.37194824219,1000.37194824219,55.3944039721501,5.5245428381211,5.8731837272644,26,1,0,0,1,0.29205322265625,33.2355842590332,2,1,1,24.506233215332,0,4232058752,24.4279117584229,,,,,,,,,,,,,,,,,,,,,,,,,,,,,,,,,
,3874589553.71471,27.2841053009033,1000.37194824219,0.00101975420945334,1.15180446328076E-7,1,2,13.0063810348511,5.00180451304088,33.7399989366531,1.31898583248421,0.197080375659927,1,3.13062698058412E-6,,,,,,,,,,,,,,,,,,,,,27.2018756866455,27.3663349151611,1000.37194824219,1000.37194824219,55.387369315477,5.52595777436591,6.00088119506836,26,1,0,0,1,0.290298461914063,33.7243423461914,2,1,1,27.3663349151611,0,4232058688,27.2841053009033,,,,,,,,,,,,,,,,,,,,,,,,,,,,,,,,,
,3874589589.68141,30.1524038314819,1000.37194824219,0.00102553528431922,1.30076598665436E-7,1,2,13.0063810348511,5.00159397039329,33.7399989366531,1.32638963571131,0.198157052767472,1,3.12599940276505E-6,,,,,,,,,,,,,,,,,,,,,30.0643615722656,30.2404460906982,1000.37194824219,1000.37194824219,55.3267931052366,5.52593009519964,6.0794153213501,26,1,0,0,1,0.292205810546875,35.190616607666,2,1,1,30.2404460906982,0,4232058720,30.1524038314819,,,,,,,,,,,,,,,,,,,,,,,,,,,,,,,,,
,3874589633.67165,33.675422668457,1000.37194824219,0.00102874331426547,1.17201966249898E-7,1,2,13.0063810348511,5.00144998540975,33.7399989366531,1.33044247332973,0.199062102292432,1,3.36235537157421E-6,,,,,,,,,,,,,,,,,,,,,33.5960311889648,33.7548141479492,1000.37194824219,1000.37194824219,55.3854152441789,5.52765686437808,6.14680862426758,26,1,0,0,1,0.29266357421875,33.7243423461914,2,1,1,33.7548141479492,0,4232058720,33.675422668457,,,,,,,,,,,,,,,,,,,,,,,,,,,,,,,,,
,3874589669.68603,36.5826721191406,1000.37194824219,0.00103037569820534,1.32862442146912E-7,1,2,13.0063810348511,5.00131992821236,33.7399989366531,1.33243011335674,0.199884399006357,1,3.76469585765276E-6,,,,,,,,,,,,,,,,,,,,,36.5170249938965,36.6483192443848,1000.37194824219,1000.37194824219,55.3189768200443,5.52796981955271,6.26753091812134,26,1,0,0,1,0.293121337890625,33.7243423461914,2,1,1,36.6483192443848,0,4232058720,36.5826721191406,,,,,,,,,,,,,,,,,,,,,,,,,,,,,,,,,
,3874589705.64225,39.4526805877686,1000.37194824219,0.00103024394302298,1.42206096150812E-7,1,2,13.0063810348511,5.00121263369025,33.7399989366531,1.33222524651997,0.199816082498729,1,3.73578942112953E-6,,,,,,,,,,,,,,,,,,,,,39.3859062194824,39.5194549560547,1000.37194824219,1000.37194824219,55.3084248350347,5.52819855139645,6.29819869995117,26,1,0,0,1,0.290985107421875,33.7243423461914,2,1,1,39.5194549560547,0,4232058720,39.4526805877686,,,,,,,,,,,,,,,,,,,,,,,,,,,,,,,,,
,3874589741.60975,42.3313446044922,1000.37194824219,0.00102972638445855,9.81333746841612E-8,1,2,13.0063810348511,5.00096137413681,33.7399989366531,1.33144847367764,0.199798737599368,1,3.80891532854139E-6,,,,,,,,,,,,,,,,,,,,,42.2580451965332,42.4046440124512,1000.37194824219,1000.37194824219,55.4174620134674,5.52958895770102,6.33710098266602,26,1,0,0,1,0.293502807617188,32.7468223571777,2,1,1,42.4046440124512,0,4232058656,42.3313446044922,,,,,,,,,,,,,,,,,,,,,,,,,,,,,,,,,
,3874589777.59401,45.2303352355957,1000.37194824219,0.00102882860198901,1.28550861118313E-7,1,2,13.0063810348511,5.00079277843402,33.7600000202656,1.33024683814951,0.199466336524876,1,3.69055915586564E-6,,,,,,,,,,,,,,,,,,,,,45.1442184448242,45.3164520263672,1000.37194824219,1000.37194824219,55.4209793418039,5.5297632691958,6.43790721893311,26,1,0,0,1,0.292129516601562,33.7243423461914,2,1,1,45.3164520263672,0,4232058720,45.2303352355957,,,,,,,,,,,,,,,,,,,,,,,,,,,,,,,,,
,3874589813.62723,48.1386280059814,1000.37194824219,0.00102781645287676,1.9444047696765E-7,1,2,13.0063810348511,5.00094310552571,33.7500013411045,1.32898642807797,0.199329440739802,1,3.72633502321503E-6,,,,,,,,,,,,,,,,,,,,,48.0580558776855,48.2192001342773,1000.37194824219,1000.37194824219,55.3052983209578,5.52941128557535,6.44280958175659,26,1,0,0,1,0.290985107421875,33.7243423461914,2,1,1,48.2192001342773,0,4232058752,48.1386280059814,,,,,,,,,,,,,,,,,,,,,,,,,,,,,,,,,
,3874589849.55849,51.0500774383545,1000.37194824219,0.00102674880633413,1.29420978515399E-7,1,2,13.0063810348511,5.00087854150334,33.7600000202656,1.32760019600527,0.198994621865748,1,3.62647556181365E-6,,,,,,,,,,,,,,,,,,,,,50.9723320007324,51.1278228759766,1000.37194824219,1000.37194824219,55.3115513491116,5.52959438557117,6.47285270690918,26,1,0,0,1,0.290451049804687,33.2355842590332,2,1,1,51.1278228759766,0,4232058624,51.0500774383545,,,,,,,,,,,,,,,,,,,,,,,,,,,,,,,,,
,3874589885.54744,53.9583053588867,1000.37194824219,0.00102541814856991,1.32854135176428E-7,1,2,13.0063810348511,5.00073463145065,33.7500013411045,1.3258570622236,0.198519217771304,1,3.45980453475845E-6,,,,,,,,,,,,,,,,,,,,,53.8835411071777,54.0330696105957,1000.37194824219,1000.37194824219,55.3764265162078,5.53019552389543,6.55230236053467,26,1,0,0,1,0.292510986328125,33.7243423461914,2,1,1,54.0330696105957,0,4232058720,53.9583053588867,,,,,,,,,,,,,,,,,,,,,,,,,,,,,,,,,
,3874589921.52953,56.8772411346436,1000.37194824219,0.00102380427860515,1.29722630301224E-7,1,2,13.0063810348511,5.00075562112014,33.7600000202656,1.32378889220526,0.198134110777795,1,3.39729146205605E-6,,,,,,,,,,,,,,,,,,,,,56.8051681518555,56.9493141174316,1000.37194824219,1000.37194824219,55.3947947864097,5.53086521030131,6.57592153549194,26,1,0,0,1,0.292892456054687,33.7243423461914,2,1,1,56.9493141174316,0,4232058752,56.8772411346436,,,,,,,,,,,,,,,,,,,,,,,,,,,,,,,,,
,3874589957.51787,59.7864284515381,1000.37194824219,0.00102220467714746,1.58284175963471E-7,1,2,13.0063810348511,5.00050493270802,33.7600000202656,1.3216185604852,0.197876334470949,1,3.44271589846835E-6,,,,,,,,,,,,,,,,,,,,,59.6914596557617,59.8813972473145,1000.37194824219,1000.37194824219,55.3064707637366,5.53152930811137,6.63587284088135,26,1,0,0,1,0.293121337890625,33.7243423461914,2,1,1,59.8813972473145,0,4232058720,59.7864284515381,,,,,,,,,,,,,,,,,,,,,,,,,,,,,,,,,
,3874589993.54492,62.6986675262451,1000.37194824219,0.00102032519872795,1.23385998029333E-7,1,2,13.0063810348511,5.00052660994994,33.7600000202656,1.31919933561466,0.197494607095018,1,3.42162337420106E-6,,,,,,,,,,,,,,,,,,,,,62.6272163391113,62.7701187133789,1000.37194824219,1000.37194824219,55.417852827727,5.53097658193543,6.68055105209351,26,1,0,0,1,0.294113159179687,33.7243423461914,2,1,1,62.7701187133789,0,4232058688,62.6986675262451,,,,,,,,,,,,,,,,,,,,,,,,,,,,,,,,,
,3874590029.47072,65.6322441101074,1000.37194824219,0.00101834803472958,1.23100154269357E-7,1,2,13.0063810348511,5.00026910172279,33.7600000202656,1.31653655337561,0.197178935188513,1,3.47776232892664E-6,,,,,,,,,,,,,,,,,,,,,65.5558166503906,65.7086715698242,1000.37194824219,1000.37194824219,55.3514144035924,5.53219413849101,6.67592763900757,26,1,0,0,1,0.294647216796875,33.7243423461914,2,1,1,65.7086715698242,0,4232058720,65.6322441101074,,,,,,,,,,,,,,,,,,,,,,,,,,,,,,,,,
,3874590065.47714,68.5324172973633,1000.37194824219,0.00101632849423856,1.40452445970475E-7,1,2,13.0063810348511,5.00026940176203,33.7600000202656,1.31391190050453,0.196882724601128,1,3.54416404642896E-6,,,,,,,,,,,,,,,,,,,,,68.4591293334961,68.6057052612305,1000.37194824219,1000.37194824219,55.4100365425347,5.53154948451223,6.7456111907959,26,1,0,0,1,0.295486450195313,33.2355842590332,2,1,1,68.6057052612305,0,4232058720,68.5324172973633,,,,,,,,,,,,,,,,,,,,,,,,,,,,,,,,,
,3874590101.46004,71.4643783569336,1000.37194824219,0.00101380068692044,1.11472484950291E-7,1,2,13.0063810348511,5.00014305374,33.7699986994266,1.31061396925957,0.196275178440288,1,3.4495785164108E-6,,,,,,,,,,,,,,,,,,,,,71.3904647827148,71.5382919311523,1000.37194824219,1000.37194824219,55.3154594917078,5.53218787424436,6.73684120178223,26,1,0,0,1,0.29449462890625,32.7468223571777,2,1,1,71.5382919311523,0,4232058816,71.4643783569336,,,,,,,,,,,,,,,,,,,,,,,,,,,,,,,,,
,3874590137.42482,74.4638938903809,1000.37194824219,0.0010113918935802,1.0101870948449E-7,1,2,13.0063810348511,5.0000938660329,33.780001103878,1.30751361094084,0.195590055156103,1,3.27431436118578E-6,,,,,,,,,,,,,,,,,,,,,74.3922576904297,74.535530090332,1000.37194824219,1000.37194824219,55.3404716043232,5.53322648110194,6.74366569519043,26,1,0,0,1,0.294342041015625,33.7243423461914,2,1,1,74.535530090332,0,4232058720,74.4638938903809,,,,,,,,,,,,,,,,,,,,,,,,,,,,,,,,,
,3874590173.40375,77.3221969604492,1000.37194824219,0.00100899402949527,1.36716611209121E-7,1,2,13.0063810348511,5.00048581364584,33.780001103878,1.3045311538061,0.195319854526874,1,3.39965552861709E-6,,,,,,,,,,,,,,,,,,,,,77.2357788085938,77.4086151123047,1000.37194824219,1000.37194824219,55.3529776606309,5.5309676413028,6.80479669570923,26,1,0,0,1,0.293350219726562,33.2355842590332,2,1,1,77.4086151123047,0,4232058656,77.3221969604492,,,,,,,,,,,,,,,,,,,,,,,,,,,,,,,,,
,3874590209.40754,80.2737808227539,1000.37194824219,0.00100615400060382,1.01178665795675E-7,1,2,13.0063810348511,5.00041024066426,33.780001103878,1.30084189995538,0.194697242754771,1,3.33694759313688E-6,,,,,,,,,,,,,,,,,,,,,80.1810073852539,80.3665542602539,1000.37194824219,1000.37194824219,55.5046135933616,5.5312652315379,6.79221487045288,26,1,0,0,1,0.290603637695313,33.2355842590332,2,1,1,80.3665542602539,0,4232058720,80.2737808227539,,,,,,,,,,,,,,,,,,,,,,,,,,,,,,,,,
,3874590245.36314,83.2052230834961,1000.37194824219,0.00100329079498164,1.52876309133779E-7,1,2,13.0063810348511,5.00029158399799,33.780001103878,1.29711610225861,0.194007282345045,1,3.22734524648048E-6,,,,,,,,,,,,,,,,,,,,,83.1241149902344,83.2863311767578,1000.37194824219,1000.37194824219,55.3854152441789,5.53162333502395,6.79847431182861,26,1,0,0,1,0.294647216796875,33.2355842590332,2,1,1,83.2863311767578,0,4232058688,83.2052230834961,,,,,,,,,,,,,,,,,,,,,,,,,,,,,,,,,
,3874590289.35164,86.8095436096191,1000.37194824219,0.000999998258945618,1.01157482911455E-7,1,2,13.0063810348511,5.00037813128678,33.7899997830391,1.29283278953465,0.193769981363167,1,3.52190274280641E-6,,,,,,,,,,,,,,,,,,,,,86.744514465332,86.8745727539063,1000.37194824219,1000.37194824219,55.3396899758039,5.53205735506918,6.85270643234253,26,1,0,0,1,0.291366577148438,33.7243423461914,2,1,1,86.8745727539063,0,4232058720,86.8095436096191,,,,,,,,,,,,,,,,,,,,,,,,,,,,,,,,,
,3874590325.33423,89.7784996032715,1000.37194824219,0.000996993649901555,1.01194071405518E-7,1,2,13.0063810348511,5.00033179823758,33.780001103878,1.28894084102759,0.193122540919841,1,3.46281687833918E-6,,,,,,,,,,,,,,,,,,,,,89.686149597168,89.870849609375,1000.37194824219,1000.37194824219,55.3142870489289,5.53230021630657,6.8256573677063,26,1,0,0,1,0.29388427734375,33.7243423461914,2,1,1,89.870849609375,0,4232058656,89.7784996032715,,,,,,,,,,,,,,,,,,,,,,,,,,,,,,,,,
,3874590361.3832,92.7773742675781,1000.37194824219,0.000994023295717922,1.071245856133E-7,1,2,13.0063810348511,5.00038890911398,33.7899997830391,1.285144196645,0.192392771082783,1,3.33076435043291E-6,,,,,,,,,,,,,,,,,,,,,92.6943359375,92.8604125976563,1000.37194824219,1000.37194824219,55.3908866438135,5.53100860476989,6.8482518196106,26,1,0,0,1,0.292205810546875,34.2131004333496,2,1,1,92.8604125976563,0,4232058688,92.7773742675781,,,,,,,,,,,,,,,,,,,,,,,,,,,,,,,,,
,3874590397.29722,95.7344474792481,1000.37194824219,0.000990851933670733,1.22489966499338E-7,1,2,13.0063810348511,5.00010194940645,33.7899997830391,1.28095194974158,0.19169195876526,1,3.26474721464916E-6,,,,,,,,,,,,,,,,,,,,,95.6466979980469,95.8221969604492,1000.37194824219,1000.37194824219,55.3889325725155,5.53191578347067,6.89565372467041,26,1,0,0,1,0.293807983398438,33.7243423461914,2,1,1,95.8221969604492,0,4232058688,95.7344474792481,,,,,,,,,,,,,,,,,,,,,,,,,,,,,,,,,
,3874590433.28298,98.7140808105469,1000.37194824219,0.000987499792084168,1.41782685874178E-7,1,2,13.0063810348511,5.00023125144592,33.7999984622002,1.27667608690698,0.190970669099448,1,3.19210640642422E-6,,,,,,,,,,,,,,,,,,,,,98.6387100219727,98.7894515991211,1000.37194824219,1000.37194824219,55.3361726474674,5.53157020549265,6.88615703582764,26,1,0,0,1,0.293731689453125,33.2355842590332,2,1,1,98.7894515991211,0,4232058720,98.7140808105469,,,,,,,,,,,,,,,,,,,,,,,,,,,,,,,,,
,3874590469.27093,101.691761016846,1000.37194824219,0.000984229385839639,7.68918764229431E-8,1,2,13.0063810348511,4.99988097601733,33.7999984622002,1.27233463045422,0.190244364941299,1,3.12335584266328E-6,,,,,,,,,,,,,,,,,,,,,101.602325439453,101.781196594238,1000.37194824219,1000.37194824219,55.4151171279097,5.53354482050942,6.90852785110474,26,1,0,0,1,0.29449462890625,33.2355842590332,2,1,1,101.781196594238,0,4232058656,101.691761016846,,,,,,,,,,,,,,,,,,,,,,,,,,,,,,,,,
,3874590505.27784,104.698921203613,1000.37194824219,0.0009808153691858,1.27084739609755E-7,1,2,13.0063810348511,4.99982107142109,33.8100008666515,1.26790265528831,0.189563562205258,1,3.09881345945751E-6,,,,,,,,,,,,,,,,,,,,,104.606262207031,104.791580200195,1000.37194824219,1000.37194824219,55.3424256756212,5.5339390070957,6.94064903259277,26,1,0,0,1,0.2935791015625,33.7243423461914,2,1,1,104.791580200195,0,4232058624,104.698921203613,,,,,,,,,,,,,,,,,,,,,,,,,,,,,,,,,
,3874590541.24024,107.670139312744,1000.37194824219,0.00097742744652362,1.19044547515891E-7,1,2,13.0063810348511,4.99983999369949,33.7999984622002,1.2635268594165,0.188929535345357,1,3.10339146321085E-6,,,,,,,,,,,,,,,,,,,,,107.593856811523,107.746421813965,1000.37194824219,1000.37194824219,55.4041743286405,5.53306054292507,6.92284440994263,26,1,0,0,1,0.29449462890625,33.7243423461914,2,1,1,107.746421813965,0,4232058784,107.670139312744,,,,,,,,,,,,,,,,,,,,,,,,,,,,,,,,,
,3874590577.20972,110.642387390137,1000.37194824219,0.000973715440003559,1.01959969991593E-7,1,2,13.0063810348511,4.99997874572995,33.8100008666515,1.25874556841733,0.18843461193059,1,3.25806592846028E-6,,,,,,,,,,,,,,,,,,,,,110.557167053223,110.727607727051,1000.37194824219,1000.37194824219,55.3275747337559,5.53224603317305,6.93792867660522,26,1,0,0,1,0.29541015625,33.2355842590332,2,1,1,110.727607727051,0,4232058656,110.642387390137,,,,,,,,,,,,,,,,,,,,,,,,,,,,,,,,,
,3874590613.22693,113.6227684021,1000.37194824219,0.000970107866113092,1.23234037292059E-7,1,2,13.0063810348511,5.0003229574501,33.8100008666515,1.25423048396259,0.18756266778239,1,3.09768687590023E-6,,,,,,,,,,,,,,,,,,,,,113.539695739746,113.705841064453,1000.37194824219,1000.37194824219,55.4581066964674,5.5310841849553,6.96715259552002,26,1,0,0,1,0.295333862304687,33.7243423461914,2,1,1,113.705841064453,0,4232058784,113.6227684021,,,,,,,,,,,,,,,,,,,,,,,,,,,,,,,,,
,3874590649.19843,116.614345550537,1000.37194824219,0.000966551004467627,9.89105963708785E-8,1,2,13.0063810348511,4.99999791823064,33.8199995458126,1.24949807682954,0.186998121620084,1,3.19464563807766E-6,,,,,,,,,,,,,,,,,,,,,116.523933410645,116.70475769043,1000.37194824219,1000.37194824219,55.4147263136501,5.53185042315788,6.93519401550293,26,1,0,0,1,0.295486450195313,33.7243423461914,2,1,1,116.70475769043,0,4232058816,116.614345550537,,,,,,,,,,,,,,,,,,,,,,,,,,,,,,,,,
,3874590685.15386,119.69393157959,1000.37194824219,0.000962818760911403,1.67040501101538E-7,1,2,13.0063810348511,5.0000275731745,33.8199995458126,1.24469909575842,0.186171382932728,1,3.10019528545369E-6,,,,,,,,,,,,,,,,,,,,,119.6171875,119.77067565918,1000.37194824219,1000.37194824219,55.3842428014001,5.53224159019395,6.96231889724731,26,1,0,0,1,0.294570922851562,33.7243423461914,2,1,1,119.77067565918,0,4232058752,119.69393157959,,,,,,,,,,,,,,,,,,,,,,,,,,,,,,,,,
,3874590721.14963,122.602962493896,1000.37194824219,0.00095914751508059,1.52789777489894E-7,1,2,13.0063810348511,4.99995382833596,33.8199995458126,1.23992109548871,0.185501608137765,1,3.12232985605093E-6,,,,,,,,,,,,,,,,,,,,,122.532348632812,122.67357635498,1000.37194824219,1000.37194824219,55.3779897732462,5.53213198451364,6.97319650650024,26,1,0,0,1,0.29327392578125,33.7243423461914,2,1,1,122.67357635498,0,4232058432,122.602962493896,,,,,,,,,,,,,,,,,,,,,,,,,,,,,,,,,
,3874590757.11233,125.560436248779,1000.37194824219,0.000955434939915353,1.23478422783477E-7,1,2,13.0063810348511,4.9997198078554,33.8299982249737,1.23503672303697,0.184801248857926,1,3.13323205008751E-6,,,,,,,,,,,,,,,,,,,,,125.47745513916,125.643417358398,1000.37194824219,1000.37194824219,55.3787714017655,5.53272765456568,6.96317863464355,26,1,0,0,1,0.292510986328125,34.7018585205078,2,1,1,125.643417358398,0,4232058624,125.560436248779,,,,,,,,,,,,,,,,,,,,,,,,,,,,,,,,,
,3874590793.108,128.53002166748,1000.37194824219,0.000951687868636978,1.25831567745112E-7,1,2,13.0063810348511,4.99985189654607,33.8299982249737,1.23027943598717,0.183803037138981,1,2.90426412018278E-6,,,,,,,,,,,,,,,,,,,,,128.445297241211,128.61474609375,1000.37194824219,1000.37194824219,55.5186829067078,5.53271176004899,6.98996257781982,26,1,0,0,1,0.291824340820313,33.7243423461914,2,1,1,128.61474609375,0,4232058656,128.53002166748,,,,,,,,,,,,,,,,,,,,,,,,,,,,,,,,,
,3874590829.07111,131.503509521484,1000.37194824219,0.000947967134339687,1.20556159375701E-7,1,2,13.0063810348511,4.99975319609966,33.840000629425,1.2254027404986,0.18330513753079,1,3.06746043557265E-6,,,,,,,,,,,,,,,,,,,,,131.427307128906,131.579711914062,1000.37194824219,1000.37194824219,55.2404231538616,5.53288033991275,7.00143146514893,26,1,0,0,1,0.29541015625,33.2355842590332,2,1,1,131.579711914062,0,4232058656,131.503509521484,,,,,,,,,,,,,,,,,,,,,,,,,,,,,,,,,
,3874590865.06246,134.504028320312,1000.37194824219,0.000943983161192685,1.12162414754043E-7,1,2,13.0063810348511,5.00024373837833,33.840000629425,1.22044984613729,0.182354658586171,1,2.89600187267219E-6,,,,,,,,,,,,,,,,,,,,,134.408020019531,134.600036621094,1000.37194824219,1000.37194824219,55.4362210979289,5.53078027842778,6.98842525482178,26,1,0,0,1,0.293045043945313,33.7243423461914,2,1,1,134.600036621094,0,4232058688,134.504028320312,,,,,,,,,,,,,,,,,,,,,,,,,,,,,,,,,
,3874590901.04467,137.472541809082,1000.37194824219,0.000940044589673242,1.32913325210127E-7,1,2,13.0063810348511,5.0012448894203,33.8499993085861,1.21566928754187,0.181835706178489,1,3.03166893888843E-6,,,,,,,,,,,,,,,,,,,,,137.406600952148,137.538482666016,1000.37194824219,1000.37194824219,55.2701250375924,5.52719649988137,7.03393316268921,26,1,0,0,1,0.291748046875,33.7243423461914,2,1,1,137.538482666016,0,4232058624,137.472541809082,,,,,,,,,,,,,,,,,,,,,,,,,,,,,,,,,
,3874590937.03303,140.459457397461,1000.37194824219,0.000936206216419937,1.32028768101952E-7,1,2,13.0063810348511,5.00035494990486,33.8499993085861,1.2104147235778,0.180981568845602,1,2.96771067515147E-6,,,,,,,,,,,,,,,,,,,,,140.380401611328,140.538513183594,1000.37194824219,1000.37194824219,55.2736423659289,5.53101506444554,7.02703428268433,26,1,0,0,1,0.293350219726562,33.7243423461914,2,1,1,140.538513183594,0,4232058720,140.459457397461,,,,,,,,,,,,,,,,,,,,,,,,,,,,,,,,,
,3874590973.01364,143.464561462402,1000.37194824219,0.000932317348255969,9.89354920729842E-8,1,2,13.0063810348511,5.00001664451379,33.8600017130375,1.20527558129906,0.180195521138221,1,2.94203513702789E-6,,,,,,,,,,,,,,,,,,,,,143.387832641602,143.541290283203,1000.37194824219,1000.37194824219,55.3135054204097,5.53298899751894,7.02069473266602,26,1,0,0,1,0.294876098632812,34.2131004333496,2,1,1,143.541290283203,0,4232058688,143.464561462402,,,,,,,,,,,,,,,,,,,,,,,,,,,,,,,,,
,3874591009.00395,146.436935424805,1000.37194824219,0.000928378045272613,1.25997262816807E-7,1,2,13.0063810348511,5.00020688122489,33.8600017130375,1.20024388028926,0.179462686866977,1,2.94430733014374E-6,,,,,,,,,,,,,,,,,,,,,146.35400390625,146.519866943359,1000.37194824219,1000.37194824219,55.3729091878712,5.53140751914661,7.0855393409729,26,1,0,0,1,0.294647216796875,33.2355842590332,2,1,1,146.519866943359,0,4232058656,146.436935424805,,,,,,,,,,,,,,,,,,,,,,,,,,,,,,,,,
,3874591044.98216,149.44953918457,1000.37194824219,0.000924437515421521,1.11977368596172E-7,1,2,13.0063810348511,5.00031030941724,33.8799990713596,1.19519680836142,0.178617846304291,1,2.86357347989006E-6,,,,,,,,,,,,,,,,,,,,,149.361343383789,149.537734985352,1000.37194824219,1000.37194824219,55.3166319344866,5.53191167583982,7.05059957504273,26,1,0,0,1,0.29296875,33.7243423461914,2,1,1,149.537734985352,0,4232058656,149.44953918457,,,,,,,,,,,,,,,,,,,,,,,,,,,,,,,,,
,3874591080.98813,152.406509399414,1000.37194824219,0.000920485153910979,1.17164301767468E-7,1,2,13.0063810348511,5.00049823280625,33.8700003921986,1.19015522827237,0.177822529400292,1,2.81965381290903E-6,,,,,,,,,,,,,,,,,,,,,152.323226928711,152.489791870117,1000.37194824219,1000.37194824219,55.3385175330251,5.5310766818817,7.05247449874878,26,1,0,0,1,0.2947998046875,33.7243423461914,2,1,1,152.489791870117,0,4232058688,152.406509399414,,,,,,,,,,,,,,,,,,,,,,,,,,,,,,,,,
,3874591116.96467,155.411834716797,1000.37194824219,0.000916472769876089,9.17624083136469E-8,1,2,13.0063810348511,5.00054262762567,33.890001475811,1.18493455144635,0.177374180582283,1,3.05828637756236E-6,,,,,,,,,,,,,,,,,,,,,155.329177856445,155.494491577148,1000.37194824219,1000.37194824219,55.4131630566116,5.53083118804897,7.10367059707642,26,1,0,0,1,0.293045043945313,33.7243423461914,2,1,1,155.494491577148,0,4232058656,155.411834716797,,,,,,,,,,,,,,,,,,,,,,,,,,,,,,,,,
,3874591152.93038,158.439109802246,1000.37194824219,0.000912396038401828,1.35407088493619E-7,1,2,13.0063810348511,5.00063195896639,33.8799990713596,1.17974411529976,0.176240309032182,1,2.77468885453254E-6,,,,,,,,,,,,,,,,,,,,,158.365524291992,158.5126953125,1000.37194824219,1000.37194824219,55.2634811951789,5.53051766261862,7.0670166015625,26,1,0,0,1,0.294036865234375,33.7243423461914,2,1,1,158.5126953125,0,4232058720,158.439109802246,,,,,,,,,,,,,,,,,,,,,,,,,,,,,,,,,
,3874591188.92224,161.354331970215,1000.37194824219,0.000908288999990293,1.11994199594225E-7,1,2,13.0063810348511,5.000671458469,33.890001475811,1.17446045033842,0.175354124839276,1,2.68892055647322E-6,,,,,,,,,,,,,,,,,,,,,161.270385742187,161.438278198242,1000.37194824219,1000.37194824219,55.377208144727,5.53025977203959,7.08582448959351,26,1,0,0,1,0.294036865234375,33.2355842590332,2,1,1,161.438278198242,0,4232058688,161.354331970215,,,,,,,,,,,,,,,,,,,,,,,,,,,,,,,,,
,3874591224.89408,164.343566894531,1000.37194824219,0.000904264049787678,1.23144589113583E-7,1,2,13.0063810348511,5.00066267769358,33.890001475811,1.16924381822138,0.174640338863299,1,2.72624562997313E-6,,,,,,,,,,,,,,,,,,,,,164.268371582031,164.418762207031,1000.37194824219,1000.37194824219,55.3201492628231,5.53018443389204,7.10395336151123,26,1,0,0,1,0.29327392578125,33.7243423461914,2,1,1,164.418762207031,0,4232058656,164.343566894531,,,,,,,,,,,,,,,,,,,,,,,,,,,,,,,,,
,3874591260.88439,167.324440002441,1000.37194824219,0.00090021866017727,1.1155438783896E-7,1,2,13.0063810348511,5.00087892841758,33.9000001549721,1.16405485254351,0.174063429373993,1,2.86392183427715E-6,,,,,,,,,,,,,,,,,,,,,167.244049072266,167.404830932617,1000.37194824219,1000.37194824219,55.4225425988424,5.52969687016018,7.07447957992554,26,1,0,0,1,0.291824340820313,32.7468223571777,2,1,1,167.404830932617,0,4232058688,167.324440002441,,,,,,,,,,,,,,,,,,,,,,,,,,,,,,,,,
,3874591296.89703,170.302093505859,1000.37194824219,0.000896195860313593,9.69022022820138E-8,1,2,13.0063810348511,5.00115448741206,33.9000001549721,1.15895858062044,0.173186423597479,1,2.76417751216142E-6,,,,,,,,,,,,,,,,,,,,,170.226547241211,170.377639770508,1000.37194824219,1000.37194824219,55.3541501034097,5.52851755101575,7.10383605957031,26,1,0,0,1,0.290145874023438,33.7243423461914,2,1,1,170.377639770508,0,4232058656,170.302093505859,,,,,,,,,,,,,,,,,,,,,,,,,,,,,,,,,
,3874591332.86469,173.291709899902,1000.37194824219,0.0008920941969824,1.30172762546919E-7,1,2,13.0063810348511,5.00092572076348,33.9099988341331,1.15358331102036,0.172364985802145,1,2.73776218049348E-6,,,,,,,,,,,,,,,,,,,,,173.223083496094,173.360336303711,1000.37194824219,1000.37194824219,55.4022202573424,5.52860109129122,7.11114025115967,26,1,0,0,1,0.294036865234375,33.7243423461914,2,1,1,173.360336303711,0,4232058688,173.291709899902,,,,,,,,,,,,,,,,,,,,,,,,,,,,,,,,,
,3874591368.81081,176.28173828125,1000.37194824219,0.00088799204099052,1.32433156714998E-7,1,2,13.0063810348511,5.00102233880577,33.9099988341331,1.14831086771864,0.171568931277047,1,2.71892363817027E-6,,,,,,,,,,,,,,,,,,,,,176.198196411133,176.365280151367,1000.37194824219,1000.37194824219,55.3295288050539,5.52812930146528,7.09073448181152,26,1,0,0,1,0.29022216796875,34.2131004333496,2,1,1,176.365280151367,0,4232058720,176.28173828125,,,,,,,,,,,,,,,,,,,,,,,,,,,,,,,,,
,3874591404.94481,179.266044616699,1000.37194824219,0.000883888058608627,1.07319360003139E-7,1,2,13.0063810348511,5.00102841626618,33.9200012385845,1.14301135564385,0.1707377793895,1,2.67659046639397E-6,,,,,,,,,,,,,,,,,,,,,179.191696166992,179.340393066406,1000.37194824219,1000.37194824219,55.351805217852,5.52833833137381,7.11154174804687,24,1,64,0,0,0.294036865234375,33.2355842590332,2,1,1,179.340393066406,0,4232058656,179.266044616699,,,,,,,,,,,,,,,,,,,,,,,,,,,,,,,,,
,3874591440.76907,182.248313903809,1000.37194824219,0.000879751378484483,1.24179067749784E-7,1,2,13.0063810348511,5.00104231695129,33.9299999177456,1.13765979352934,0.169984292525138,1,2.69878730173649E-6,,,,,,,,,,,,,,,,,,,,,182.164413452148,182.332214355469,1000.37194824219,1000.37194824219,55.3944039721501,5.52822583860736,7.1111626625061,26,1,0,0,1,0.292739868164063,33.7243423461914,2,1,1,182.332214355469,0,4232058720,182.248313903809,,,,,,,,,,,,,,,,,,,,,,,,,,,,,,,,,
,3874591476.85275,185.255271911621,1000.37194824219,0.000875518840599009,1.28756475084693E-7,1,2,13.0063810348511,5.00112872625309,33.9299999177456,1.13223377164701,0.16903355967628,1,2.57990733160918E-6,,,,,,,,,,,,,,,,,,,,,185.19775390625,185.312789916992,1000.37194824219,1000.37194824219,55.3904958295539,5.52796331315348,7.10023212432861,26,1,0,0,1,0.29388427734375,34.2131004333496,2,1,1,185.312789916992,0,4232058688,185.255271911621,,,,,,,,,,,,,,,,,,,,,,,,,,,,,,,,,
,3874591512.7766,188.211311340332,1000.37194824219,0.000871416439366834,9.29562245393951E-8,1,2,13.0063810348511,5.00105260660405,33.9399985969067,1.12688771730603,0.168353090434399,1,2.65681613065374E-6,,,,,,,,,,,,,,,,,,,,,188.133834838867,188.288787841797,1000.37194824219,1000.37194824219,55.3447705611789,5.52836639253685,7.13648509979248,26,1,0,0,1,0.294036865234375,33.7243423461914,2,1,1,188.288787841797,0,4232058720,188.211311340332,,,,,,,,,,,,,,,,,,,,,,,,,,,,,,,,,
,3874591548.72422,191.185707092285,1000.37194824219,0.00086723769089385,9.26658309742906E-8,1,2,13.0063810348511,5.00105344793532,33.9399985969067,1.12148900928525,0.167512648761048,1,2.61843803873052E-6,,,,,,,,,,,,,,,,,,,,,191.1005859375,191.27082824707,1000.37194824219,1000.37194824219,55.3521960321116,5.5290330023803,7.12144613265991,26,1,0,0,1,0.2911376953125,33.2355842590332,2,1,1,191.27082824707,0,4232058848,191.185707092285,,,,,,,,,,,,,,,,,,,,,,,,,,,,,,,,,
,3874591584.7041,194.166839599609,1000.37194824219,0.000863181678450057,1.3266842059301E-7,1,2,13.0063810348511,5.00101162656021,33.950001001358,1.11623255090125,0.166715694381,1,2.59725325158801E-6,,,,,,,,,,,,,,,,,,,,,194.091262817383,194.242416381836,1000.37194824219,1000.37194824219,55.3420348613616,5.52890271973075,7.11847066879272,26,1,0,0,1,0.293350219726562,33.2355842590332,2,1,1,194.242416381836,0,4232058752,194.166839599609,,,,,,,,,,,,,,,,,,,,,,,,,,,,,,,,,
,3874591620.69399,197.175682067871,1000.37194824219,0.000858835694393468,1.14095990376076E-7,1,2,13.0063810348511,5.0011268749138,33.9599996805191,1.11062666787758,0.166028820080719,1,2.69793744287223E-6,,,,,,,,,,,,,,,,,,,,,197.088134765625,197.263229370117,1000.37194824219,1000.37194824219,55.3525868463712,5.52825453842251,7.16621685028076,26,1,0,0,1,0.292129516601562,33.7243423461914,2,1,1,197.263229370117,0,4232058720,197.175682067871,,,,,,,,,,,,,,,,,,,,,,,,,,,,,,,,,
,3874591656.66837,200.138816833496,1000.37194824219,0.000854743677838444,9.27542932256002E-8,1,2,13.0063810348511,5.00114331809923,33.9699983596802,1.10535228256803,0.165154790136794,1,2.62036898387653E-6,,,,,,,,,,,,,,,,,,,,,200.054916381836,200.222717285156,1000.37194824219,1000.37194824219,55.3068615779962,5.5281594675297,7.14283990859985,26,1,0,0,1,0.29205322265625,34.2131004333496,2,1,1,200.222717285156,0,4232058784,200.138816833496,,,,,,,,,,,,,,,,,,,,,,,,,,,,,,,,,
,3874591692.699,203.123176574707,1000.37194824219,0.000850666680895585,1.27131057772603E-7,1,2,13.0063810348511,5.00111621778282,33.9800007641315,1.10006874441653,0.164385343608715,1,2.62298811548748E-6,,,,,,,,,,,,,,,,,,,,,203.039093017578,203.207260131836,1000.37194824219,1000.37194824219,55.2560557242462,5.52920453988257,7.14358806610107,26,1,0,0,1,0.292587280273438,33.2355842590332,2,1,1,203.207260131836,0,4232058720,203.123176574707,,,,,,,,,,,,,,,,,,,,,,,,,,,,,,,,,
,3874591728.6767,206.102439880371,1000.37194824219,0.000846268560588114,1.22499321438327E-7,1,2,13.0063810348511,5.0011313700383,33.9800007641315,1.09440086314683,0.16343308471403,1,2.52978041457136E-6,,,,,,,,,,,,,,,,,,,,,206.026580810547,206.178298950195,1000.37194824219,1000.37194824219,55.3916682723328,5.52867319337315,7.18584394454956,26,1,0,0,1,0.293807983398438,34.2131004333496,2,1,1,206.178298950195,0,4232058688,206.102439880371,,,,,,,,,,,,,,,,,,,,,,,,,,,,,,,,,
,3874591764.66449,209.15843963623,1000.37194824219,0.000842143603978102,1.24586275936531E-7,1,2,13.0063810348511,5.0011551588158,33.9899994432926,1.08902724547525,0.162954870836174,1,2.76272033917732E-6,,,,,,,,,,,,,,,,,,,,,209.099838256836,209.217041015625,1000.37194824219,1000.37194824219,55.2494118818328,5.52825679269339,7.17434024810791,26,1,0,0,1,0.292587280273438,33.2355842590332,2,1,1,209.217041015625,0,4232058848,209.15843963623,,,,,,,,,,,,,,,,,,,,,,,,,,,,,,,,,
,3874591800.6396,212.100311279297,1000.37194824219,0.00083782381868711,9.28808545897091E-8,1,2,13.0063810348511,5.00109877609494,34.000001847744,1.08347422133145,0.16177332206485,1,2.48333747182183E-6,,,,,,,,,,,,,,,,,,,,,212.017044067383,212.183578491211,1000.37194824219,1000.37194824219,55.3908866438135,5.5285577186356,7.18089866638184,26,1,0,0,1,0.292129516601562,33.7243423461914,2,1,1,212.183578491211,0,4232058688,212.100311279297,,,,,,,,,,,,,,,,,,,,,,,,,,,,,,,,,
,3874591836.57664,215.100006103516,1000.37194824219,0.000833446145107742,1.24684604603935E-7,1,2,13.0063810348511,5.00121543132125,34.000001847744,1.07784672719117,0.160942539027332,1,2.47751512463169E-6,,,,,,,,,,,,,,,,,,,,,215.019775390625,215.180236816406,1000.37194824219,1000.37194824219,55.3893233867751,5.52756566149381,7.23100423812866,26,1,0,0,1,0.29327392578125,33.7243423461914,2,1,1,215.180236816406,0,4232058688,215.100006103516,,,,,,,,,,,,,,,,,,,,,,,,,,,,,,,,,
,3874591872.57008,218.065406799316,1000.37194824219,0.00082917656236019,1.20948829313708E-7,1,2,13.0063810348511,5.00115626279936,34.0100005269051,1.07230427726937,0.160136981052554,1,2.48148900222557E-6,,,,,,,,,,,,,,,,,,,,,217.995147705078,218.135665893555,1000.37194824219,1000.37194824219,55.4115997995732,5.52793381027122,7.21181154251099,26,1,0,0,1,0.293121337890625,33.2355842590332,2,1,1,218.135665893555,0,4232058688,218.065406799316,,,,,,,,,,,,,,,,,,,,,,,,,,,,,,,,,
,3874591908.60791,221.091728210449,1000.37194824219,0.000824871751268423,1.12285422829544E-7,1,2,13.0063810348511,5.00148264221538,34.0300016105175,1.06682197683614,0.159404578955342,1,2.53389262826559E-6,,,,,,,,,,,,,,,,,,,,,221.014938354492,221.168518066406,1000.37194824219,1000.37194824219,55.2646536379578,5.5264753728915,7.23127698898315,26,1,0,0,1,0.290603637695313,33.2355842590332,2,1,1,221.168518066406,0,4232058688,221.091728210449,,,,,,,,,,,,,,,,,,,,,,,,,,,,,,,,,
,3874591944.53573,224.06063079834,1000.37194824219,0.000820619403781053,1.24774882877989E-7,1,2,13.0063810348511,5.00126350591041,34.0300016105175,1.06127514784722,0.158452317246207,1,2.42745258604156E-6,,,,,,,,,,,,,,,,,,,,,223.969284057617,224.151977539062,1000.37194824219,1000.37194824219,55.4092549140155,5.52803923855529,7.28947067260742,26,1,0,0,1,0.290603637695313,33.2355842590332,2,1,1,224.151977539062,0,4232058720,224.06063079834,,,,,,,,,,,,,,,,,,,,,,,,,,,,,,,,,
,3874591980.54387,227.063171386719,1000.37194824219,0.000816296009675653,1.10904697018767E-7,1,2,13.0063810348511,5.00103423251413,34.0300016105175,1.05563882987667,0.157453854016332,1,2.29594901180111E-6,,,,,,,,,,,,,,,,,,,,,226.996078491211,227.130264282227,1000.37194824219,1000.37194824219,55.3322645048712,5.52851643437251,7.26843929290771,26,1,0,0,1,0.292816162109375,33.7243423461914,2,1,1,227.130264282227,0,4232058720,227.063171386719,,,,,,,,,,,,,,,,,,,,,,,,,,,,,,,,,
,3874592016.50806,230.094711303711,1000.37194824219,0.000812019587578901,1.23147771217371E-7,1,2,13.0063810348511,5.00097161638883,34.0400002896786,1.05007539376882,0.156727428911611,1,2.36213119870323E-6,,,,,,,,,,,,,,,,,,,,,230.027954101562,230.161468505859,1000.37194824219,1000.37194824219,55.3092064635539,5.5286465892893,7.31418228149414,26,1,0,0,1,0.295257568359375,34.2131004333496,2,1,1,230.161468505859,0,4232058656,230.094711303711,,,,,,,,,,,,,,,,,,,,,,,,,,,,,,,,,
,3874592052.48012,233.02507019043,1000.37194824219,0.000807826783131003,1.05918184162794E-7,1,2,13.0063810348511,5.00143831611134,34.0499989688396,1.04478026548107,0.156000885287342,1,2.39816928550851E-6,,,,,,,,,,,,,,,,,,,,,232.941528320313,233.108612060547,1000.37194824219,1000.37194824219,55.3990937432655,5.52729626786775,7.36625099182129,26,1,0,0,1,0.293045043945313,34.7018585205078,2,1,1,233.108612060547,0,4232058688,233.02507019043,,,,,,,,,,,,,,,,,,,,,,,,,,,,,,,,,
,3874592088.48914,236.000885009766,1000.37194824219,0.00080364909685503,1.03690726981638E-7,1,2,13.0063810348511,5.00108190515129,34.060001373291,1.03926145564678,0.155263475279561,1,2.45129485714132E-6,,,,,,,,,,,,,,,,,,,,,235.92643737793,236.075332641602,1000.37194824219,1000.37194824219,55.3850244299193,5.52860215444152,7.36908864974976,26,1,0,0,1,0.2911376953125,33.2355842590332,2,1,1,236.075332641602,0,4232058720,236.000885009766,,,,,,,,,,,,,,,,,,,,,,,,,,,,,,,,,
,3874592124.45135,239.058876037598,1000.37194824219,0.000799385441098185,9.0185330531039E-8,1,2,13.0063810348511,5.00108755402013,34.060001373291,1.03376877516985,0.154307659465467,1,2.33600715250233E-6,,,,,,,,,,,,,,,,,,,,,238.97590637207,239.141845703125,1000.37194824219,1000.37194824219,55.2943555216885,5.52921403226422,7.42226505279541,26,1,0,0,1,0.29144287109375,33.2355842590332,2,1,1,239.141845703125,0,4232058688,239.058876037598,,,,,,,,,,,,,,,,,,,,,,,,,,,,,,,,,
,3874592160.43397,242.021133422852,1000.37194824219,0.000795211153691907,6.81115725745137E-8,1,2,13.0063810348511,5.00098441088688,34.0700000524521,1.02830778170729,0.153724436406866,1,2.49924685676856E-6,,,,,,,,,,,,,,,,,,,,,241.94091796875,242.101348876953,1000.37194824219,1000.37194824219,55.3912774580732,5.52942378992329,7.46585941314697,26,1,0,0,1,0.291213989257812,33.7243423461914,2,1,1,242.101348876953,0,4232058752,242.021133422852,,,,,,,,,,,,,,,,,,,,,,,,,,,,,,,,,
,3874592196.40519,244.942405700684,1000.37194824219,0.000790817530597789,7.70651448915946E-8,1,2,13.0063810348511,5.00090842922421,34.0799987316132,1.02263924703071,0.152635015902257,1,2.30236760103753E-6,,,,,,,,,,,,,,,,,,,,,244.867523193359,245.017288208008,1000.37194824219,1000.37194824219,55.346724632477,5.52887926463961,7.47216749191284,26,1,0,0,1,0.29449462890625,33.7243423461914,2,1,1,245.017288208008,0,4232058816,244.942405700684,,,,,,,,,,,,,,,,,,,,,,,,,,,,,,,,,
,3874592232.3949,247.917411804199,1000.37194824219,0.000786480056843651,7.44414208199344E-8,1,2,13.0063810348511,5.00083394697064,34.0900011360645,1.01701426781802,0.151759689520289,1,2.26268432803179E-6,,,,,,,,,,,,,,,,,,,,,247.841796875,247.993026733398,1000.37194824219,1000.37194824219,55.3185860057847,5.52947609806353,7.54927349090576,26,1,0,0,1,0.29296875,33.2355842590332,2,1,1,247.993026733398,0,4232058688,247.917411804199,,,,,,,,,,,,,,,,,,,,,,,,,,,,,,,,,
,3874592268.41952,251.04370880127,1000.37194824219,0.000782173059587145,1.00812921839665E-7,1,2,13.0063810348511,5.00091837497502,34.1099984943867,1.01145992770043,0.150991570398507,1,2.29621374197521E-6,,,,,,,,,,,,,,,,,,,,,250.97151184082,251.115905761719,1000.37194824219,1000.37194824219,55.3893233867751,5.52954608730139,7.59628582000732,26,1,0,0,1,0.292892456054687,33.2355842590332,2,1,1,251.115905761719,0,4232058688,251.04370880127,,,,,,,,,,,,,,,,,,,,,,,,,,,,,,,,,
,3874592304.35992,253.941474914551,1000.37194824219,0.00077779596678703,8.42972967804765E-8,1,2,13.0063810348511,5.0009661775912,34.0999998152256,1.00582343662242,0.15007823604941,1,2.22896438595017E-6,,,,,,,,,,,,,,,,,,,,,253.840438842773,254.042510986328,1000.37194824219,1000.37194824219,55.3893233867751,5.52919359383926,7.64824867248535,26,1,0,0,1,0.2935791015625,33.2355842590332,2,1,1,254.042510986328,0,4232058688,253.941474914551,,,,,,,,,,,,,,,,,,,,,,,,,,,,,,,,,
,3874592340.33748,256.892349243164,1000.37194824219,0.000773691531058555,9.85809922824049E-8,1,2,13.0063810348511,5.00096984491907,34.120000898838,1.00050954924265,0.149335455612101,1,2.25510145838692E-6,,,,,,,,,,,,,,,,,,,,,256.809906005859,256.974792480469,1000.37194824219,1000.37194824219,55.4213701560636,5.52900394228192,7.75632667541504,26,1,0,0,1,0.292587280273438,33.2355842590332,2,1,1,256.974792480469,0,4232058656,256.892349243164,,,,,,,,,,,,,,,,,,,,,,,,,,,,,,,,,
,3874592376.33307,259.867004394531,1000.37194824219,0.000769447049491723,1.08249024541802E-7,1,2,13.0063810348511,5.0010179291731,34.1299995779991,0.995041737869724,0.148465887584153,1,2.20230134180658E-6,,,,,,,,,,,,,,,,,,,,,259.781097412109,259.952911376953,1000.37194824219,1000.37194824219,55.3537592891501,5.52760728892101,7.82852745056152,26,1,0,0,1,0.291900634765625,33.2355842590332,2,1,1,259.952911376953,0,4232058656,259.867004394531,,,,,,,,,,,,,,,,,,,,,,,,,,,,,,,,,
,3874592412.29927,262.857894897461,1000.37194824219,0.000765088834735979,1.21684078800841E-7,1,2,13.0063810348511,5.00119905502875,34.1299995779991,0.989464949325876,0.147569338322929,1,2.14106867137628E-6,,,,,,,,,,,,,,,,,,,,,262.789031982422,262.9267578125,1000.37194824219,1000.37194824219,55.4069100284578,5.5274418063606,7.94688272476196,26,1,0,0,1,0.291824340820313,33.7243423461914,2,1,1,262.9267578125,0,4232058752,262.857894897461,,,,,,,,,,,,,,,,,,,,,,,,,,,,,,,,,
,3874592448.30616,265.889282226562,1000.37194824219,0.000760850455588979,1.03024777562398E-7,1,2,13.0063810348511,5.00123786393764,34.1399982571602,0.983994185798774,0.146753803483772,1,2.12949351458051E-6,,,,,,,,,,,,,,,,,,,,,265.814056396484,265.964508056641,1000.37194824219,1000.37194824219,55.4166803849482,5.5279527580001,8.09099864959717,26,1,0,0,1,0.29205322265625,33.2355842590332,2,1,1,265.964508056641,0,4232058880,265.889282226562,,,,,,,,,,,,,,,,,,,,,,,,,,,,,,,,,
,3874592484.29955,269.006683349609,1000.37194824219,0.000756602735833341,7.61115077767691E-8,1,2,13.0063810348511,5.0009583268984,34.1500006616116,0.978436430674155,0.145840850155556,1,2.05401278564212E-6,,,,,,,,,,,,,,,,,,,,,268.904357910156,269.109008789062,1000.37194824219,1000.37194824219,55.3588398745251,5.5290582239942,8.0165376663208,26,1,0,0,1,0.291671752929687,33.7243423461914,2,1,1,269.109008789062,0,4232058976,269.006683349609,,,,,,,,,,,,,,,,,,,,,,,,,,,,,,,,,
,3874592520.26356,271.910125732422,1000.37194824219,0.000752364532919054,1.07073750579867E-7,1,2,13.0063810348511,5.0008879824508,34.1599993407726,0.972917426552695,0.145151502623375,1,2.14333790170279E-6,,,,,,,,,,,,,,,,,,,,,271.829986572266,271.990264892578,1000.37194824219,1000.37194824219,55.3904958295539,5.52895408340673,7.9638147354126,26,1,0,0,1,0.292587280273438,33.7243423461914,2,1,1,271.990264892578,0,4232058752,271.910125732422,,,,,,,,,,,,,,,,,,,,,,,,,,,,,,,,,
,3874592556.34478,274.783584594727,1000.37194824219,0.000748260189572113,1.07382118273571E-7,1,2,13.0063810348511,5.00090068678945,34.170001745224,0.967600609640056,0.144447195732008,1,2.19891082316062E-6,,,,,,,,,,,,,,,,,,,,,274.704681396484,274.862487792969,1000.37194824219,1000.37194824219,55.3908866438135,5.52921031249625,7.93840074539185,25,1,64,0,0,0.293426513671875,33.7243423461914,2,1,1,274.862487792969,0,4232058688,274.783584594727,,,,,,,,,,,,,,,,,,,,,,,,,,,,,,,,,
,3874592592.22636,277.824340820313,1000.37194824219,0.000744201869889982,8.86370891589375E-8,1,2,13.0063810348511,5.00087850206536,34.1800004243851,0.962372505868128,0.143486483658956,1,2.05063856768447E-6,,,,,,,,,,,,,,,,,,,,,277.742126464844,277.906555175781,1000.37194824219,1000.37194824219,55.3779897732462,5.52873921673061,7.87273740768433,26,1,0,0,1,0.291366577148438,33.7243423461914,2,1,1,277.906555175781,0,4232058624,277.824340820313,,,,,,,,,,,,,,,,,,,,,,,,,,,,,,,,,
,3874592628.22208,280.751983642578,1000.37194824219,0.000740103634213858,8.55268419970155E-8,1,2,13.0063810348511,5.00098708113241,34.2000015079975,0.957087430489154,0.142798987420898,1,2.11536362089821E-6,,,,,,,,,,,,,,,,,,,,,280.676971435547,280.826995849609,1000.37194824219,1000.37194824219,55.3775989589866,5.52820887538928,7.85538768768311,26,1,0,0,1,0.290756225585937,32.7468223571777,2,1,1,280.826995849609,0,4232058784,280.751983642578,,,,,,,,,,,,,,,,,,,,,,,,,,,,,,,,,
,3874592664.21266,283.760482788086,1000.37194824219,0.00073649079115676,9.99915099394851E-8,1,2,13.0063810348511,5.00092300225514,34.2000015079975,0.952412987192359,0.141999304578392,1,2.02768980797759E-6,,,,,,,,,,,,,,,,,,,,,283.682189941406,283.838775634766,1000.37194824219,1000.37194824219,55.3643112741597,5.52861954290674,7.85225486755371,26,1,0,0,1,0.290069580078125,33.2355842590332,2,1,1,283.838775634766,0,4232058720,283.760482788086,,,,,,,,,,,,,,,,,,,,,,,,,,,,,,,,,
,3874592700.19334,286.802368164062,1000.37194824219,0.000733035090062361,8.88281218011307E-8,1,2,13.0063810348511,5.00094809211381,34.2100001871586,0.947935920053,0.141435656938568,1,2.09674103762361E-6,,,,,,,,,,,,,,,,,,,,,286.727355957031,286.877380371094,1000.37194824219,1000.37194824219,55.4088640997559,5.52761988649386,7.81915473937988,26,1,0,0,1,0.291519165039063,33.7243423461914,2,1,1,286.877380371094,0,4232058720,286.802368164062,,,,,,,,,,,,,,,,,,,,,,,,,,,,,,,,,
,3874592736.1939,289.699966430664,1000.37194824219,0.00072869854251164,1.02160817405107E-7,1,2,13.0063810348511,5.00090157985297,34.2199988663197,0.942324052811064,0.14054082954588,1,2.04082819334489E-6,,,,,,,,,,,,,,,,,,,,,289.630615234375,289.769317626953,1000.37194824219,1000.37194824219,55.504222779102,5.52891910685527,7.79309892654419,25,1,64,0,0,0.293502807617188,33.7243423461914,2,1,1,289.769317626953,0,4232058720,289.699966430664,,,,,,,,,,,,,,,,,,,,,,,,,,,,,,,,,
,3874592772.19319,292.718704223633,1000.37194824219,0.000722693553271394,7.27862330888799E-8,1,2,13.0063810348511,5.00092367614774,34.230001270771,0.934593236279333,0.139186398289216,1,1.87162941347718E-6,,,,,,,,,,,,,,,,,,,,,292.644256591797,292.793151855469,1000.37194824219,1000.37194824219,55.3744724449097,5.52875601245819,7.79489850997925,24,1,64,0,0,0.293731689453125,34.2131004333496,2,1,1,292.793151855469,0,4232058688,292.718704223633,,,,,,,,,,,,,,,,,,,,,,,,,,,,,,,,,
,3874592808.10719,295.698364257812,1000.37194824219,0.00071800917197167,1.21509861130478E-7,1,2,13.0063810348511,5.00081778902546,34.2399999499321,0.92849681993731,0.138356081914364,1,1.9182083787267E-6,,,,,,,,,,,,,,,,,,,,,295.600708007812,295.796020507812,1000.37194824219,1000.37194824219,55.3815071015828,5.52875440465399,7.78418207168579,26,1,0,0,1,0.293655395507812,33.7243423461914,2,1,1,295.796020507812,0,4232058656,295.698364257812,,,,,,,,,,,,,,,,,,,,,,,,,,,,,,,,,
,3874592844.08832,298.683807373047,1000.37194824219,0.000713637591648964,8.44005192495277E-8,1,2,13.0063810348511,5.00086744312152,34.2499986290932,0.922860375300268,0.137488935475652,1,1.88591089739249E-6,,,,,,,,,,,,,,,,,,,,,298.608947753906,298.758666992188,1000.37194824219,1000.37194824219,55.4342670266309,5.52867772619961,7.84513664245606,26,1,0,0,1,0.292205810546875,33.7243423461914,2,1,1,298.758666992188,0,4232058656,298.683807373047,,,,,,,,,,,,,,,,,,,,,,,,,,,,,,,,,
,3874592880.06474,301.65412902832,1000.37194824219,0.0007094344835977,1.1500178119609E-7,1,2,13.0063810348511,5.00076039372657,34.2600010335445,0.917395516934015,0.136689416438437,1,1.88588099951519E-6,,,,,,,,,,,,,,,,,,,,,301.582366943359,301.725891113281,1000.37194824219,1000.37194824219,55.4471638971982,5.52927569108972,7.88938856124878,26,1,0,0,1,0.290451049804687,33.7243423461914,2,1,1,301.725891113281,0,4232058688,301.65412902832,,,,,,,,,,,,,,,,,,,,,,,,,,,,,,,,,
,3874592916.09405,304.62434387207,1000.37194824219,0.000705288516343002,7.84809037126571E-8,1,2,13.0063810348511,5.00079709277937,34.2799983918667,0.912011142657992,0.136113550371419,1,2.04612828205553E-6,,,,,,,,,,,,,,,,,,,,,304.558654785156,304.690032958984,1000.37194824219,1000.37194824219,55.2939647074289,5.52896980877986,7.93186569213867,26,1,0,0,1,0.290756225585937,33.7243423461914,2,1,1,304.703186035156,0,4232058720,304.62434387207,,,,,,,,,,,,,,,,,,,,,,,,,,,,,,,,,
,3874592952.06331,307.625213623047,1000.37194824219,0.000701088387011995,6.57027237225194E-8,1,2,13.0063810348511,5.00090401899515,34.2799983918667,0.906640002311576,0.135081266013411,1,1.85945207498347E-6,,,,,,,,,,,,,,,,,,,,,307.549377441406,307.701049804687,1000.37194824219,1000.37194824219,55.3240574054193,5.52835724086634,8.06665897369385,26,1,0,0,1,0.29205322265625,33.7243423461914,2,1,1,307.701049804687,0,4232058688,307.625213623047,,,,,,,,,,,,,,,,,,,,,,,,,,,,,,,,,
,3874592988.03311,309.461181640625,1000.37194824219,0.000698228629656171,1.00084761534219E-7,1,2,13.0063810348511,5.00078622269358,34.2799983918667,0.902901648639472,0.134597464379681,1,1.90722917400806E-6,,,,,,,,,,,,,,,,,,,,,309.44287109375,309.4794921875,1000.37194824219,1000.37194824219,55.3506327750732,5.52859044245303,8.16015338897705,26,1,0,0,1,0.29449462890625,33.7243423461914,6,1,1,309.4794921875,0,4232058816,309.461181640625,,,,,,,,,,,,,,,,,,,,,,,,,,,,,,,,,
,3874593024.01363,309.826873779297,1000.37194824219,0.0006975191639417,9.99800438245493E-8,1,2,13.0063810348511,5.00077537397517,34.2799983918667,0.901989208798948,0.134407501348787,1,1.86448215570694E-6,,,,,,,,,,,,,,,,,,,,,309.822143554687,309.831604003906,1000.37194824219,1000.37194824219,55.295918778727,5.52889406811418,8.27794551849365,26,1,0,0,1,0.291900634765625,33.7243423461914,5,1,1,309.831604003906,0,4232058720,309.826873779297,,,,,,,,,,,,,,,,,,,,,,,,,,,,,,,,,
,3874593052.02956,309.918334960937,1000.37194824219,0.000697311348201721,7.93377397961006E-8,1,2,13.0063810348511,5.00075391444809,34.2799983918667,0.901704733366967,0.134437357357928,1,1.91858275130529E-6,,,,,,,,,,,,,,,,,,,,,309.916534423828,309.920135498047,1000.37194824219,1000.37194824219,55.3693918595347,5.52879231020888,8.4265604019165,26,1,0,0,1,0.294723510742188,33.2355842590332,1,1,1,309.920135498047,0,4232058688,309.918334960937,,,,,,,,,,,,,,,,,,,,,,,,,,,,,,,,,