File: example_report_creation/example_dir/sample_ID/qd_files/101022_00002.dat
[Header]
; MPMS3 Data File (default extension .dat)
; Copyright (c) 2007, Quantum Design, Inc. All rights reserved.
TITLE,
FILEOPENTIME,3874585280.96031,10/10/2022,5:41 pm
BYAPP,MPMS3 w/ AC,1.0,1.1
INFO,MPMS3 Measurement Release 1.1.16 Build 424, MultiVu Release 2.3.4.19,APPNAME
INFO,Linear Motor Servo Controller,MOTOR_MODULE_NAME
INFO,3101-100 J0,MOTOR_HW_VERSION
INFO,MMC721,MOTOR_SERIAL_NUMBER
INFO,01.04.28,MOTOR_SOFTWARE_VERSION
INFO,Quantum Design Squid Module,SQUID_MODULE_NAME
INFO,3101-501 B0,SQUID_HW_VERSION
INFO,SQM195,SQUID_SERIAL_NUMBER
INFO,01.03.04,SQUID_SOFTWARE_VERSION
INFO,SQUID AC,AC_MODULE_NAME
INFO,3101-401 f1,AC_HW_VERSION
INFO,SAC107,AC_SERIAL_NUMBER
INFO,SQUID AC 00.95.07,AC_SOFTWARE_VERSION
INFO,TCI166,COIL_SERIAL_NUMBER
INFO,0,MOMENT_UNITS
INFO,Quidel - 101022,SAMPLE_MATERIAL
INFO,,SAMPLE_COMMENT
INFO,1.38,SAMPLE_MASS
INFO,,SAMPLE_VOLUME
INFO,,SAMPLE_MOLECULAR_WEIGHT
INFO,,SAMPLE_SIZE
INFO,,SAMPLE_SHAPE
INFO,Brass,SAMPLE_HOLDER
INFO,Standard,SAMPLE_HOLDER_DETAIL
INFO,64.25,SAMPLE_OFFSET
DATATYPE,COMMENT,1
DATATYPE,TIME,2
STARTUPAXIS,X,2
STARTUPAXIS,Y1,5
FIELDGROUP, VSM,2,3,4,5,6,8,9,10,11,14,15
FIELDGROUP, DC, 2,3,4,14,56,57,58,59,60,61,62,63,64,65,66,67,68,69
FIELDGROUP, AC, 2,3,4,11,16,17,18,19,20,21,22,23,24,25,26,27,28,29,30
STARTUPGROUP, All
[Data]
Comment,Time Stamp (sec),Temperature (K),Magnetic Field (Oe),Moment (emu),M. Std. Err. (emu),Transport Action,Averaging Time (sec),Frequency (Hz),Peak Amplitude (mm),Center Position (mm),Lockin Signal' (V),Lockin Signal (V),Range,M. Quad. Signal (emu),AC Moment (emu),AC M. Std Err. (emu),AC Phase (deg),AC Phase Std. Err. (deg),AC Susceptibility (emu/Oe),AC Suscept. Std Err. (emu/Oe),AC X' (emu/Oe),AC X' Std Err. (emu/Oe),AC X'' (emu/Oe),AC X'' Std Err. (emu/Oe),AC Drive (Oe),AC Frequency (Hz),AC Averaging Time (sec),AC Cycles,AC Range,AC Measure Type,AC Signal' (V),AC Signal'' (V),AC Trim Coil Ratio,AC Trim Coil Phase,Min. Temperature (K),Max. Temperature (K),Min. Field (Oe),Max. Field (Oe),Mass (grams),Motor Lag (deg),Pressure (Torr),Measure Count,Measurement Number,SQUID Status (code),Motor Status (code),Measure Status (code),Motor Current (amps),Motor Temp. (C),Temp. Status (code),Field Status (code),Chamber Status (code),Chamber Temp (K),Redirection State,Evercool Status,Average Temp (K),Rotation Angle (deg),Rotator state,DC Moment Fixed Ctr (emu),DC Moment Err Fixed Ctr (emu),DC Moment Free Ctr (emu),DC Moment Err Free Ctr (emu),DC Fixed Fit,DC Free Fit,DC Calculated Center (mm),DC Calculated Center Err (mm),DC Scan Length (mm),DC Scan Time (s),DC Number of Points,DC Squid Drift,DC Min V (V),DC Max V (V),DC Scans per Measure,Map 01,Map 02,Map 03,Map 04,Map 05,Map 06,Map 07,Map 08,Map 09,Map 10,Map 11,Map 12,Map 13,Map 14,Map 15,Map 16
"FC, 100",3874585281.0761
,3874585399.74373,308.970550537109,99.8893203735352,0.000194858743678522,2.41968457585585E-8,1,2,13.0063810348511,5.00190436395249,34.2799983918667,0.252084124188093,0.0373866605428274,1,3.87015494465071E-7,,,,,,,,,,,,,,,,,,,,,308.907928466797,309.033172607422,99.8893203735352,99.8893203735352,55.497188122429,5.52649259476014,9.28255844116211,26,1,0,0,1,0.292587280273438,33.2355842590332,2,1,1,308.907928466797,0,4232058176,308.970550537109,,,,,,,,,,,,,,,,,,,,,,,,,,,,,,,,,
,3874585435.75483,306.180725097656,99.8893203735352,0.000195746788433814,2.14233942875494E-8,1,2,13.0063810348511,5.00197067127879,34.2799983918667,0.253240612877195,0.0375374756362797,1,3.73119911139019E-7,,,,,,,,,,,,,,,,,,,,,306.102142333984,306.259307861328,99.8893203735352,99.8893203735352,55.3967488577078,5.52634571082829,9.51325702667236,26,1,0,0,1,0.290069580078125,33.2355842590332,2,1,1,306.102142333984,0,4232058496,306.180725097656,,,,,,,,,,,,,,,,,,,,,,,,,,,,,,,,,
,3874585471.71796,302.765914916992,99.8893203735352,0.000197252780039989,1.98655843470187E-8,1,2,13.0063810348511,5.00195143100978,34.2600010335445,0.255185407465165,0.0378408410873215,1,3.87405061679099E-7,,,,,,,,,,,,,,,,,,,,,302.671020507812,302.860809326172,99.8893203735352,99.8893203735352,55.4393476120059,5.52633651001356,9.70686435699463,26,1,0,0,1,0.290145874023438,33.7243423461914,2,1,1,302.671020507812,0,4232058528,302.765914916992,,,,,,,,,,,,,,,,,,,,,,,,,,,,,,,,,
,3874585507.69818,299.644134521484,99.8893203735352,0.000198854277512518,2.60701361054756E-8,1,2,13.0063810348511,5.00199462511449,34.2600010335445,0.257266398934687,0.0381072404782791,1,3.58643485127948E-7,,,,,,,,,,,,,,,,,,,,,299.553833007812,299.734436035156,99.8893203735352,99.8893203735352,55.4069100284578,5.52594875893607,9.92588424682617,26,1,0,0,1,0.29144287109375,33.2355842590332,2,1,1,299.553833007812,0,4232058656,299.644134521484,,,,,,,,,,,,,,,,,,,,,,,,,,,,,,,,,
,3874585543.72123,296.693496704102,99.8893203735352,0.000200205720530875,2.76259871290131E-8,1,2,13.0063810348511,5.00195396929101,34.2499986290932,0.259013922464433,0.0383518469636735,1,3.50307872911764E-7,,,,,,,,,,,,,,,,,,,,,296.615692138672,296.771301269531,99.8893203735352,99.8893203735352,55.5104758072559,5.52567279376809,9.96419906616211,26,1,0,0,1,0.290374755859375,34.2131004333496,2,1,1,296.615692138672,0,4232058624,296.693496704102,,,,,,,,,,,,,,,,,,,,,,,,,,,,,,,,,
,3874585579.70827,293.884643554687,99.8893203735352,0.000201208464592091,3.23280000174939E-8,1,2,13.0063810348511,5.0020252227643,34.230001270771,0.260311145038469,0.0385805096112707,1,3.79733484481261E-7,,,,,,,,,,,,,,,,,,,,,293.805450439453,293.963836669922,99.8893203735352,99.8893203735352,55.346724632477,5.52560103829698,9.87038230895996,26,1,0,0,1,0.290679931640625,34.2131004333496,2,1,1,293.805450439453,0,4232058752,293.884643554687,,,,,,,,,,,,,,,,,,,,,,,,,,,,,,,,,
,3874585615.65466,291.050048828125,99.8893203735352,0.000202264621734257,2.89344460487183E-8,1,2,13.0063810348511,5.00203693524529,34.230001270771,0.261677989446993,0.0387858917704634,1,3.83846924919864E-7,,,,,,,,,,,,,,,,,,,,,290.962982177734,291.137115478516,99.8893203735352,99.8893203735352,55.4030018858616,5.52477557835,9.7795991897583,26,1,0,0,1,0.292282104492188,33.2355842590332,2,1,1,290.962982177734,0,4232058720,291.050048828125,,,,,,,,,,,,,,,,,,,,,,,,,,,,,,,,,
,3874585651.64453,288.116744995117,99.8893203735352,0.000203322515059731,2.48740796008151E-8,1,2,13.0063810348511,5.00209798149944,34.230001270771,0.263058082172851,0.0389417284307233,1,3.49005889746813E-7,,,,,,,,,,,,,,,,,,,,,288.026336669922,288.207153320313,99.8893203735352,99.8893203735352,55.4065192141982,5.52451622928057,9.71485233306885,26,1,0,0,1,0.289993286132812,33.7243423461914,2,1,1,288.026336669922,0,4232058688,288.116744995117,,,,,,,,,,,,,,,,,,,,,,,,,,,,,,,,,
,3874585687.67274,285.114456176758,99.8893203735352,0.000204391488241502,2.27044084425574E-8,1,2,13.0063810348511,5.0020941863578,34.2100001871586,0.264433084811236,0.0391994176920987,1,3.91790283838389E-7,,,,,,,,,,,,,,,,,,,,,285.056091308594,285.172821044922,99.8893203735352,99.8893203735352,55.3166319344866,5.52554176809255,9.59538173675537,26,1,0,0,1,0.290145874023438,33.7243423461914,2,1,1,285.056091308594,0,4232058784,285.114456176758,,,,,,,,,,,,,,,,,,,,,,,,,,,,,,,,,
,3874585723.66325,282.105087280273,99.8893203735352,0.000205599036152143,2.64273560169976E-8,1,2,13.0063810348511,5.00210783908092,34.2100001871586,0.265999452926197,0.0394100961286462,1,3.77829598275441E-7,,,,,,,,,,,,,,,,,,,,,282.041595458984,282.168579101562,99.8893203735352,99.8893203735352,55.3658745311982,5.52562678386165,9.54745197296143,24,1,64,0,0,0.291290283203125,33.2355842590332,2,1,1,282.041595458984,0,4232058464,282.105087280273,,,,,,,,,,,,,,,,,,,,,,,,,,,,,,,,,
,3874585759.58036,279.115798950195,99.8893203735352,0.000206690318036215,2.74751352333741E-8,1,2,13.0063810348511,5.00204602743395,34.1899991035461,0.267412670226961,0.0395779217124287,1,3.4840544241476E-7,,,,,,,,,,,,,,,,,,,,,279.023803710938,279.207794189453,99.8893203735352,99.8893203735352,55.3690010452751,5.52534168278107,9.48370742797852,26,1,0,0,1,0.290145874023438,33.2355842590332,2,1,1,279.023803710938,0,4232058752,279.115798950195,,,,,,,,,,,,,,,,,,,,,,,,,,,,,,,,,
,3874585795.64499,276.099334716797,99.8893203735352,0.00020796370983209,2.15472381179057E-8,1,2,13.0063810348511,5.00204995583748,34.1899991035461,0.269052192027061,0.0398783149433567,1,3.9422323810143E-7,,,,,,,,,,,,,,,,,,,,,276.031066894531,276.167602539062,99.8893203735352,99.8893203735352,55.3783805875059,5.52523958545592,9.39379119873047,26,1,0,0,1,0.291519165039063,34.7018585205078,2,1,1,276.031066894531,0,4232058784,276.099334716797,,,,,,,,,,,,,,,,,,,,,,,,,,,,,,,,,
,3874585831.54175,273.119400024414,99.8893203735352,0.000209111610275895,2.36867661442049E-8,1,2,13.0063810348511,5.00199108845173,34.1899991035461,0.270530844484945,0.0401114359310912,1,4.06956676542935E-7,,,,,,,,,,,,,,,,,,,,,273.042114257813,273.196685791016,99.8893203735352,99.8893203735352,55.4080824712366,5.52558673212481,9.37020969390869,26,1,0,0,1,0.29205322265625,33.7243423461914,2,1,1,273.042114257813,0,4232058688,273.119400024414,,,,,,,,,,,,,,,,,,,,,,,,,,,,,,,,,
,3874585867.55467,270.102798461914,99.8893203735352,0.000210170696057331,2.51566363176385E-8,1,2,13.0063810348511,5.00200518588976,34.170001745224,0.271908311847624,0.0402720660425268,1,3.76036735145409E-7,,,,,,,,,,,,,,,,,,,,,270.033386230469,270.172210693359,99.8893203735352,99.8893203735352,55.4143354993905,5.52515715051806,9.31251430511475,26,1,0,0,1,0.290679931640625,33.7243423461914,2,1,1,270.033386230469,0,4232058688,270.102798461914,,,,,,,,,,,,,,,,,,,,,,,,,,,,,,,,,
,3874585903.5249,267.111694335938,99.8893203735352,0.000211413793768703,2.83298457489868E-8,1,2,13.0063810348511,5.00197304658673,34.170001745224,0.273515661396758,0.0404993514817138,1,3.70109176113071E-7,,,,,,,,,,,,,,,,,,,,,267.027404785156,267.195983886719,99.8893203735352,99.8893203735352,55.549948047477,5.5249252467738,9.23180198669434,26,1,0,0,1,0.290603637695313,34.2131004333496,2,1,1,267.027404785156,0,4232058720,267.111694335938,,,,,,,,,,,,,,,,,,,,,,,,,,,,,,,,,
,3874585939.53838,264.109497070313,99.8893203735352,0.000212629386656802,2.96076782834265E-8,1,2,13.0063810348511,5.00201173199006,34.1500006616116,0.275087037609082,0.0407617702907125,1,3.94735776537814E-7,,,,,,,,,,,,,,,,,,,,,264.026092529297,264.192901611328,99.8893203735352,99.8893203735352,55.4983605652078,5.52491119333296,9.23371315002441,26,1,0,0,1,0.292129516601562,33.7243423461914,2,1,1,264.026092529297,0,4232058560,264.109497070313,,,,,,,,,,,,,,,,,,,,,,,,,,,,,,,,,
,3874585975.46361,261.137924194336,99.8893203735352,0.000213876169116497,2.69247681720182E-8,1,2,13.0063810348511,5.00203570175517,34.1500006616116,0.276697572125537,0.0410306333567765,1,4.1990536156628E-7,,,,,,,,,,,,,,,,,,,,,261.043304443359,261.232543945313,99.8893203735352,99.8893203735352,55.4444281973809,5.5250266225792,9.15522480010986,26,1,0,0,1,0.291061401367188,33.7243423461914,2,1,1,261.043304443359,0,4232058656,261.137924194336,,,,,,,,,,,,,,,,,,,,,,,,,,,,,,,,,
,3874586011.47131,258.115463256836,99.8893203735352,0.000215107041836857,3.30349718174792E-8,1,2,13.0063810348511,5.00198155120642,34.1500006616116,0.278294026816955,0.0412098006329,1,3.7878221323021E-7,,,,,,,,,,,,,,,,,,,,,258.036499023438,258.194427490234,99.8893203735352,99.8893203735352,55.4119906138328,5.52525158902317,9.0994119644165,26,1,0,0,1,0.292587280273438,33.2355842590332,2,1,1,258.036499023438,0,4232058688,258.115463256836,,,,,,,,,,,,,,,,,,,,,,,,,,,,,,,,,
,3874586047.46757,255.049934387207,99.8893203735352,0.000216280106059698,2.75211132903275E-8,1,2,13.0063810348511,5.00190870225955,34.1299995779991,0.279799184476474,0.0414802236590182,1,4.16805595196365E-7,,,,,,,,,,,,,,,,,,,,,254.960433959961,255.139434814453,99.8893203735352,99.8893203735352,55.4018294430828,5.5251344152326,9.09672164916992,26,1,0,0,1,0.290145874023438,33.7243423461914,2,1,1,254.960433959961,0,4232058624,255.049934387207,,,,,,,,,,,,,,,,,,,,,,,,,,,,,,,,,
,3874586083.39956,252.113014221191,99.8893203735352,0.000217567578678832,3.09737790190292E-8,1,2,13.0063810348511,5.00197745186413,34.1299995779991,0.281474097868846,0.0417010903295693,1,3.98533157992731E-7,,,,,,,,,,,,,,,,,,,,,252.030212402344,252.195816040039,99.8893203735352,99.8893203735352,55.2701250375924,5.52499307495869,9.02755832672119,26,1,0,0,1,0.2899169921875,33.7243423461914,2,1,1,252.030212402344,0,4232058688,252.113014221191,,,,,,,,,,,,,,,,,,,,,,,,,,,,,,,,,
,3874586119.39832,249.113342285156,99.8893203735352,0.000218748884069177,3.29159671419036E-8,1,2,13.0063810348511,5.00199222895408,34.120000898838,0.28299889577294,0.0419595433995176,1,4.25316757566648E-7,,,,,,,,,,,,,,,,,,,,,249.044708251953,249.181976318359,99.8893203735352,99.8893203735352,55.2978728500251,5.52481413579995,8.97459983825684,26,1,0,0,1,0.291748046875,33.7243423461914,2,1,1,249.044708251953,0,4232058848,249.113342285156,,,,,,,,,,,,,,,,,,,,,,,,,,,,,,,,,
,3874586155.38978,246.14330291748,99.8893203735352,0.00022004175130823,3.75118120939407E-8,1,2,13.0063810348511,5.00196686723896,34.120000898838,0.284670703910833,0.0421989084851185,1,4.21394157295621E-7,,,,,,,,,,,,,,,,,,,,,246.074157714844,246.212448120117,99.8893203735352,99.8893203735352,55.5003146365059,5.52510117688767,8.97364234924316,26,1,0,0,1,0.291671752929687,33.7243423461914,2,1,1,246.074157714844,0,4232058688,246.14330291748,,,,,,,,,,,,,,,,,,,,,,,,,,,,,,,,,
,3874586191.37144,243.133750915527,99.8893203735352,0.000221237494961721,3.28148034951186E-8,1,2,13.0063810348511,5.00193823903224,34.0999998152256,0.286217623931463,0.0424124595748042,1,4.11763385607352E-7,,,,,,,,,,,,,,,,,,,,,243.060852050781,243.206649780273,99.8893203735352,99.8893203735352,55.3424256756212,5.52562540367028,8.91202831268311,26,1,0,0,1,0.290374755859375,33.7243423461914,2,1,1,243.060852050781,0,4232058656,243.133750915527,,,,,,,,,,,,,,,,,,,,,,,,,,,,,,,,,
,3874586227.35073,240.141654968262,99.8893203735352,0.000222530925387018,2.09790045033086E-8,1,2,13.0063810348511,5.0019206452562,34.0999998152256,0.287891003268101,0.0426501926790913,1,4.06431144850487E-7,,,,,,,,,,,,,,,,,,,,,240.069595336914,240.213714599609,99.8893203735352,99.8893203735352,55.3439889326597,5.52541407986559,8.85841083526611,26,1,0,0,1,0.289688110351562,33.7243423461914,2,1,1,240.069595336914,0,4232058688,240.141654968262,,,,,,,,,,,,,,,,,,,,,,,,,,,,,,,,,
,3874586263.33042,237.129577636719,99.8893203735352,0.000223822865087931,2.78095455401211E-8,1,2,13.0063810348511,5.00201001951209,34.0999998152256,0.2895690350013,0.0429028576538414,1,4.11868787046574E-7,,,,,,,,,,,,,,,,,,,,,237.046157836914,237.212997436523,99.8893203735352,99.8893203735352,55.2978728500251,5.52482186189985,8.85813331604004,26,1,0,0,1,0.29052734375,33.7243423461914,2,1,1,237.046157836914,0,4232058688,237.129577636719,,,,,,,,,,,,,,,,,,,,,,,,,,,,,,,,,
,3874586299.41776,234.135139465332,99.8893203735352,0.000225032338288697,2.92697264625425E-8,1,2,13.0063810348511,5.00204145933886,34.0799987316132,0.291135241879423,0.0431425320274813,1,4.19860388884194E-7,,,,,,,,,,,,,,,,,,,,,234.063690185547,234.206588745117,99.8893203735352,99.8893203735352,55.392449900852,5.52480074669272,8.80057525634766,26,1,0,0,1,0.2911376953125,33.7243423461914,2,1,1,234.063690185547,0,4232058592,234.135139465332,,,,,,,,,,,,,,,,,,,,,,,,,,,,,,,,,
,3874586335.30209,231.152786254883,99.8893203735352,0.000226334790598293,3.45792273802274E-8,1,2,13.0063810348511,5.00206276146899,34.0799987316132,0.292816805469583,0.0434281856417105,1,4.49872066190025E-7,,,,,,,,,,,,,,,,,,,,,231.077117919922,231.228454589844,99.8893203735352,99.8893203735352,55.3056891352174,5.52511084712744,8.74221801757812,26,1,0,0,1,0.291366577148438,33.2355842590332,2,1,1,231.077117919922,0,4232058656,231.152786254883,,,,,,,,,,,,,,,,,,,,,,,,,,,,,,,,,
,3874586371.28216,228.132774353027,99.8893203735352,0.000227618310921038,2.86832330345658E-8,1,2,13.0063810348511,5.00208621265561,34.0799987316132,0.294484549410513,0.0436386135728223,1,4.24501344865198E-7,,,,,,,,,,,,,,,,,,,,,228.054092407227,228.211456298828,99.8893203735352,99.8893203735352,55.4651413531405,5.5243138888503,8.7515172958374,26,1,0,0,1,0.291366577148438,33.7243423461914,2,1,1,228.054092407227,0,4232058720,228.132774353027,,,,,,,,,,,,,,,,,,,,,,,,,,,,,,,,,
,3874586407.26522,225.124542236328,99.8893203735352,0.000228834975415436,2.58952261011148E-8,1,2,13.0063810348511,5.00204359091538,34.060001373291,0.296052113958359,0.0438918221694886,1,4.42590630404986E-7,,,,,,,,,,,,,,,,,,,,,225.042419433594,225.206665039062,99.8893203735352,99.8893203735352,55.3435981184001,5.52425890426934,8.66903686523437,26,1,0,0,1,0.290069580078125,33.7243423461914,2,1,1,225.042419433594,0,4232058752,225.124542236328,,,,,,,,,,,,,,,,,,,,,,,,,,,,,,,,,
,3874586443.2452,222.107795715332,99.8893203735352,0.000230219204447694,3.70678146332229E-8,1,2,13.0063810348511,5.00206340338409,34.060001373291,0.297839388900782,0.0441931014617431,1,4.72724996220651E-7,,,,,,,,,,,,,,,,,,,,,222.024627685547,222.190963745117,99.8893203735352,99.8893203735352,55.402611071602,5.52467628917587,8.64410495758057,26,1,0,0,1,0.291824340820313,33.2355842590332,2,1,1,222.024627685547,0,4232058752,222.107795715332,,,,,,,,,,,,,,,,,,,,,,,,,,,,,,,,,
,3874586479.20704,219.144325256348,99.8893203735352,0.000231567140743783,2.92866926168747E-8,1,2,13.0063810348511,5.00202390050906,34.060001373291,0.299584148318876,0.0444226116008134,1,4.53275421720476E-7,,,,,,,,,,,,,,,,,,,,,219.070785522461,219.217864990234,99.8893203735352,99.8893203735352,55.321321705602,5.52499065435879,8.63926219940186,26,1,0,0,1,0.290069580078125,33.2355842590332,2,1,1,219.051513671875,0,4232058656,219.144325256348,,,,,,,,,,,,,,,,,,,,,,,,,,,,,,,,,
,3874586515.20152,216.163208007813,99.8893203735352,0.000232830614822592,3.51286035303578E-8,1,2,13.0063810348511,5.00206534064654,34.0400002896786,0.301218654223104,0.0446898580049293,1,4.74566262065553E-7,,,,,,,,,,,,,,,,,,,,,216.07258605957,216.253829956055,99.8893203735352,99.8893203735352,55.3181951915251,5.52501916228868,8.56501293182373,26,1,0,0,1,0.291595458984375,33.7243423461914,2,1,1,216.07258605957,0,4232058656,216.163208007813,,,,,,,,,,,,,,,,,,,,,,,,,,,,,,,,,
,3874586551.19568,213.130844116211,99.8893203735352,0.000234233721415837,3.00853441298877E-8,1,2,13.0063810348511,5.00212489120703,34.0400002896786,0.303040640553346,0.0449481503142365,1,4.68332340458957E-7,,,,,,,,,,,,,,,,,,,,,213.060699462891,213.200988769531,99.8893203735352,99.8893203735352,55.4209793418039,5.52475289478101,8.53423500061035,26,1,0,0,1,0.2899169921875,33.7243423461914,2,1,1,213.060699462891,0,4232058752,213.130844116211,,,,,,,,,,,,,,,,,,,,,,,,,,,,,,,,,
,3874586587.17168,210.145431518555,99.8893203735352,0.000235466018655193,2.84540508175848E-8,1,2,13.0063810348511,5.00207780593415,34.0400002896786,0.304627743123865,0.045205813104467,1,4.8763011024063E-7,,,,,,,,,,,,,,,,,,,,,210.06982421875,210.221038818359,99.8893203735352,99.8893203735352,55.2838035366789,5.52439625273592,8.53573226928711,26,1,0,0,1,0.291290283203125,33.7243423461914,2,1,1,210.06982421875,0,4232058560,210.145431518555,,,,,,,,,,,,,,,,,,,,,,,,,,,,,,,,,
,3874586623.17097,207.151962280273,99.8893203735352,0.000236869165652097,3.45563321924809E-8,1,2,13.0063810348511,5.00210485093166,34.0400002896786,0.306447610134802,0.0454599994853761,1,4.7852861694834E-7,,,,,,,,,,,,,,,,,,,,,207.068939208984,207.234985351562,99.8893203735352,99.8893203735352,55.4084732854962,5.52396811605806,8.46751976013184,26,1,0,0,1,0.289459228515625,33.7243423461914,2,1,1,207.068939208984,0,4232058624,207.151962280273,,,,,,,,,,,,,,,,,,,,,,,,,,,,,,,,,
,3874586659.13122,204.157623291016,99.8893203735352,0.000238169645121747,3.73614655228457E-8,1,2,13.0063810348511,5.00207171863977,34.0199992060661,0.308126489836129,0.0457143534026676,1,4.85164627110612E-7,,,,,,,,,,,,,,,,,,,,,204.075988769531,204.2392578125,99.8893203735352,99.8893203735352,55.3904958295539,5.52429942238288,8.44214153289795,26,1,0,0,1,0.290756225585937,33.7243423461914,2,1,1,204.075988769531,0,4232058560,204.157623291016,,,,,,,,,,,,,,,,,,,,,,,,,,,,,,,,,
,3874586695.11307,201.128318786621,99.8893203735352,0.00023966731125151,3.01045680733694E-8,1,2,13.0063810348511,5.00212475302149,34.0199992060661,0.310065244630756,0.0460257470106268,1,5.06181857627235E-7,,,,,,,,,,,,,,,,,,,,,201.047103881836,201.209533691406,99.8893203735352,99.8893203735352,55.4373935407078,5.52462306698692,8.43002891540527,26,1,0,0,1,0.290145874023438,34.2131004333496,2,1,1,201.047103881836,0,4232058656,201.128318786621,,,,,,,,,,,,,,,,,,,,,,,,,,,,,,,,,
,3874586731.08861,198.065528869629,99.8893203735352,0.000241090837753635,3.74134847758047E-8,1,2,13.0063810348511,5.00211822761212,34.0199992060661,0.311918412568094,0.0462164988061382,1,4.45409419378621E-7,,,,,,,,,,,,,,,,,,,,,197.983688354492,198.147369384766,99.8893203735352,99.8893203735352,55.3350002046886,5.52470128873031,8.36212635040283,26,1,0,0,1,0.290908813476562,33.2355842590332,2,1,1,197.983688354492,0,4232058720,198.065528869629,,,,,,,,,,,,,,,,,,,,,,,,,,,,,,,,,
,3874586767.08619,195.103256225586,99.8893203735352,0.000242392838156491,2.93633171162943E-8,1,2,13.0063810348511,5.00209563164735,34.000001847744,0.31359304356509,0.0465197667235089,1,4.8951919678298E-7,,,,,,,,,,,,,,,,,,,,,195.026580810547,195.179931640625,99.8893203735352,99.8893203735352,55.3478970752559,5.52372728286333,8.36737442016602,26,1,0,0,1,0.290756225585937,33.7243423461914,2,1,1,195.026580810547,0,4232058592,195.103256225586,,,,,,,,,,,,,,,,,,,,,,,,,,,,,,,,,
,3874586803.08912,192.149085998535,99.8893203735352,0.000243790442442157,3.40495820737515E-8,1,2,13.0063810348511,5.00211589635215,34.0100005269051,0.31539703536361,0.046828763991889,1,5.23641706308322E-7,,,,,,,,,,,,,,,,,,,,,192.064422607422,192.233749389648,99.8893203735352,99.8893203735352,55.4276231842174,5.52397131347141,8.34403991699219,26,1,0,0,1,0.288772583007812,33.7243423461914,2,1,1,192.064422607422,0,4232058752,192.149085998535,,,,,,,,,,,,,,,,,,,,,,,,,,,,,,,,,
,3874586839.06237,189.137763977051,99.8893203735352,0.000245263559180351,3.4697408076219E-8,1,2,13.0063810348511,5.00199595956818,34.000001847744,0.317295494042808,0.047087826822805,1,5.09552697893247E-7,,,,,,,,,,,,,,,,,,,,,189.047790527344,189.227737426758,99.8893203735352,99.8893203735352,55.3928407151116,5.52389428285497,8.29024505615234,26,1,0,0,1,0.292129516601562,33.7243423461914,2,1,1,189.047790527344,0,4232058656,189.137763977051,,,,,,,,,,,,,,,,,,,,,,,,,,,,,,,,,
,3874586875.11108,186.115852355957,99.8893203735352,0.00024667946947826,4.24102167387846E-8,1,2,13.0063810348511,5.00206732582296,33.9899994432926,0.319136540410774,0.0473404799823531,1,4.96940826148043E-7,,,,,,,,,,,,,,,,,,,,,186.033309936523,186.198394775391,99.8893203735352,99.8893203735352,55.3041258781789,5.52355217544785,8.28820419311523,26,1,0,0,1,0.289535522460937,33.2355842590332,2,1,1,186.033309936523,0,4232058528,186.115852355957,,,,,,,,,,,,,,,,,,,,,,,,,,,,,,,,,
,3874586911.015,183.131706237793,99.8893203735352,0.000248067345635038,4.02461299816509E-8,1,2,13.0063810348511,5.00189514653919,33.9800007641315,0.320920417770982,0.0475789211891374,1,4.79936956493349E-7,,,,,,,,,,,,,,,,,,,,,183.03450012207,183.228912353516,99.8893203735352,99.8893203735352,55.3088156492943,5.52523106328099,8.25110626220703,26,1,0,0,1,0.289993286132812,33.7243423461914,2,1,1,183.03450012207,0,4232058592,183.131706237793,,,,,,,,,,,,,,,,,,,,,,,,,,,,,,,,,
,3874586947.02537,180.15518951416,99.8893203735352,0.000249594449712816,2.85032591786715E-8,1,2,13.0063810348511,5.00194588304026,33.9800007641315,0.322895314826122,0.0479084463871051,1,5.10673484125506E-7,,,,,,,,,,,,,,,,,,,,,180.07942199707,180.23095703125,99.8893203735352,99.8893203735352,55.4932799798328,5.52431810598775,8.19993019104004,26,1,0,0,1,0.291824340820313,33.2355842590332,2,1,1,180.07942199707,0,4232058784,180.15518951416,,,,,,,,,,,,,,,,,,,,,,,,,,,,,,,,,
,3874586982.97596,177.139533996582,99.8893203735352,0.000251024581501415,3.1675159790173E-8,1,2,13.0063810348511,5.00189811421458,33.9699983596802,0.32474550964602,0.0481523172619347,1,4.90420985625169E-7,,,,,,,,,,,,,,,,,,,,,177.063720703125,177.215347290039,99.8893203735352,99.8893203735352,55.3123329776308,5.52541229459912,8.1921443939209,26,1,0,0,1,0.289535522460937,33.2355842590332,2,1,1,177.063720703125,0,4232058656,177.139533996582,,,,,,,,,,,,,,,,,,,,,,,,,,,,,,,,,
,3874587018.95721,174.122032165527,99.8893203735352,0.000252502622232064,2.97340739310386E-8,1,2,13.0063810348511,5.00193845705018,33.9699983596802,0.326659828116087,0.048446420248546,1,5.01063815553672E-7,,,,,,,,,,,,,,,,,,,,,174.038696289062,174.205368041992,99.8893203735352,99.8893203735352,55.3564949889674,5.52536759105089,8.14458179473877,26,1,0,0,1,0.290145874023438,33.7243423461914,2,1,1,174.038696289062,0,4232058624,174.122032165527,,,,,,,,,,,,,,,,,,,,,,,,,,,,,,,,,
,3874587054.94635,171.148048400879,99.8893203735352,0.000253897675084587,3.7087092702945E-8,1,2,13.0063810348511,5.00194741225107,33.950001001358,0.328462364906488,0.0487350383992114,1,5.19932283875321E-7,,,,,,,,,,,,,,,,,,,,,171.063873291016,171.232223510742,99.8893203735352,99.8893203735352,55.3615755743424,5.52449921456458,8.11241912841797,26,1,0,0,1,0.29144287109375,33.7243423461914,2,1,1,171.063873291016,0,4232058656,171.148048400879,,,,,,,,,,,,,,,,,,,,,,,,,,,,,,,,,
,3874587090.91148,168.145767211914,99.8893203735352,0.00025543868990196,3.53486929633677E-8,1,2,13.0063810348511,5.00201570517943,33.9599996805191,0.330468622712141,0.0489881172075502,1,4.89358639900515E-7,,,,,,,,,,,,,,,,,,,,,168.062026977539,168.229507446289,99.8893203735352,99.8893203735352,55.3025626211405,5.52487112277608,8.09635734558105,26,1,0,0,1,0.291519165039063,33.7243423461914,2,1,1,168.062026977539,0,4232058656,168.145767211914,,,,,,,,,,,,,,,,,,,,,,,,,,,,,,,,,
,3874587126.92714,165.128807067871,99.8893203735352,0.000256972534543267,3.95213520078566E-8,1,2,13.0063810348511,5.00198390324448,33.950001001358,0.332445916958096,0.0493101308827825,1,5.14157753078819E-7,,,,,,,,,,,,,,,,,,,,,165.053115844727,165.204498291016,99.8893203735352,99.8893203735352,55.4096457282751,5.52433874785407,8.04793548583984,26,1,0,0,1,0.289993286132812,33.2355842590332,2,1,1,165.053115844727,0,4232058592,165.128807067871,,,,,,,,,,,,,,,,,,,,,,,,,,,,,,,,,
,3874587162.89683,162.144683837891,99.8893203735352,0.000258496508890831,3.51913143788379E-8,1,2,13.0063810348511,5.00202419949948,33.950001001358,0.334420775597871,0.0496063186950306,1,5.19677416499484E-7,,,,,,,,,,,,,,,,,,,,,162.074584960938,162.214782714844,99.8893203735352,99.8893203735352,55.4147263136501,5.52406157575766,8.02123069763184,26,1,0,0,1,0.291061401367188,33.7243423461914,2,1,1,162.074584960938,0,4232058656,162.144683837891,,,,,,,,,,,,,,,,,,,,,,,,,,,,,,,,,
,3874587198.85809,159.143898010254,99.8893203735352,0.000259980252982981,3.60528019374191E-8,1,2,13.0063810348511,5.00199660988669,33.9299999177456,0.336340823245087,0.0498695244578769,1,5.06320011954309E-7,,,,,,,,,,,,,,,,,,,,,159.059494018555,159.228302001953,99.8893203735352,99.8893203735352,55.3701734880539,5.52414152679375,8.02628803253174,26,1,0,0,1,0.289382934570313,33.7243423461914,2,1,1,159.059494018555,0,4232058688,159.143898010254,,,,,,,,,,,,,,,,,,,,,,,,,,,,,,,,,
,3874587234.9183,156.154296875,99.8893203735352,0.000261522488622506,4.181076843191E-8,1,2,13.0063810348511,5.00202434067553,33.9299999177456,0.338334906292061,0.050191374581085,1,5.29128853255586E-7,,,,,,,,,,,,,,,,,,,,,156.074584960938,156.234008789062,99.8893203735352,99.8893203735352,55.4006570003039,5.52379459341455,7.9962306022644,26,1,0,0,1,0.290756225585937,33.7243423461914,2,1,1,156.074584960938,0,4232058752,156.154296875,,,,,,,,,,,,,,,,,,,,,,,,,,,,,,,,,
,3874587270.84346,152.988662719727,99.8893203735352,0.000263048258946287,4.23144271965467E-8,1,2,13.0063810348511,5.00205407689823,33.9299999177456,0.340312948972734,0.0504756429064105,1,5.25279854816462E-7,,,,,,,,,,,,,,,,,,,,,152.913024902344,153.064300537109,99.8893203735352,99.8893203735352,55.3643112741597,5.52459299343834,7.96690320968628,26,1,0,0,1,0.289382934570313,33.7243423461914,2,1,1,152.913024902344,0,4232058624,152.988662719727,,,,,,,,,,,,,,,,,,,,,,,,,,,,,,,,,
,3874587307.10819,150.03263092041,99.8893203735352,0.000264626690816717,3.46768740655461E-8,1,2,13.0063810348511,5.00194064747567,33.9099988341331,0.342343996928667,0.0507781914998315,1,5.29415839666827E-7,,,,,,,,,,,,,,,,,,,,,149.980224609375,150.085037231445,99.8893203735352,99.8893203735352,55.3850244299193,5.5246058276478,7.98965835571289,24,1,64,0,0,0.291748046875,33.2355842590332,2,1,1,149.980224609375,0,4232058304,150.03263092041,,,,,,,,,,,,,,,,,,,,,,,,,,,,,,,,,
,3874587342.80467,146.905982971191,99.8893203735352,0.000266314754133662,3.80114474997021E-8,1,2,13.0063810348511,5.00201663948389,33.9099988341331,0.344496836663205,0.0513649147727098,1,7.35038583622514E-7,,,,,,,,,,,,,,,,,,,,,146.824661254883,146.9873046875,99.8893203735352,99.8893203735352,55.3471154467366,5.52435769808533,7.93767929077148,26,1,0,0,1,0.290374755859375,35.190616607666,2,1,1,146.824661254883,0,4232058752,146.905982971191,,,,,,,,,,,,,,,,,,,,,,,,,,,,,,,,,
,3874587378.77539,143.884185791016,99.8893203735352,0.000267990829597581,3.30196748263855E-8,1,2,13.0063810348511,5.00199873591918,33.9099988341331,0.346685829624218,0.0515334142855642,1,6.20266006282354E-7,,,,,,,,,,,,,,,,,,,,,143.799072265625,143.969299316406,99.8893203735352,99.8893203735352,55.4092549140155,5.52399615479859,7.9083251953125,26,1,0,0,1,0.289535522460937,33.7243423461914,2,1,1,143.799072265625,0,4232058688,143.884185791016,,,,,,,,,,,,,,,,,,,,,,,,,,,,,,,,,
,3874587414.76762,140.933128356934,99.8893203735352,0.000269565473995301,3.93030819388171E-8,1,2,13.0063810348511,5.00195652230469,33.9099988341331,0.348724857852511,0.051793920553174,1,5.91701678665456E-7,,,,,,,,,,,,,,,,,,,,,140.859176635742,141.007080078125,99.8893203735352,99.8893203735352,55.4608423962847,5.52421646127981,7.92273235321045,26,1,0,0,1,0.289993286132812,33.7243423461914,2,1,1,140.859176635742,0,4232058592,140.933128356934,,,,,,,,,,,,,,,,,,,,,,,,,,,,,,,,,
,3874587450.76584,137.895629882812,99.8893203735352,0.000271147187279331,3.46840484759802E-8,1,2,13.0063810348511,5.00197670481068,33.890001475811,0.35078017329724,0.0520492475353438,1,5.57405915343883E-7,,,,,,,,,,,,,,,,,,,,,137.804534912109,137.986724853516,99.8893203735352,99.8893203735352,55.3451613754386,5.52428053004182,7.86420154571533,26,1,0,0,1,0.2923583984375,33.7243423461914,2,1,1,137.804534912109,0,4232058688,137.895629882812,,,,,,,,,,,,,,,,,,,,,,,,,,,,,,,,,
,3874587486.7293,134.840843200684,99.8893203735352,0.000272745271502083,4.00581067923311E-8,1,2,13.0063810348511,5.00198895406112,33.890001475811,0.352816412441991,0.0525776181256485,1,7.31796520382622E-7,,,,,,,,,,,,,,,,,,,,,134.760894775391,134.920791625977,99.8893203735352,99.8893203735352,55.3783805875059,5.52408587336783,7.84049034118652,26,1,0,0,1,0.29144287109375,33.2355842590332,2,1,1,134.760894775391,0,4232058560,134.840843200684,,,,,,,,,,,,,,,,,,,,,,,,,,,,,,,,,
,3874587522.71909,131.889434814453,99.8893203735352,0.000274150126566047,3.72467168182375E-8,1,2,13.0063810348511,5.00196648937802,33.890001475811,0.354654266523377,0.0526923054723668,1,6.15172355870992E-7,,,,,,,,,,,,,,,,,,,,,131.806915283203,131.971954345703,99.8893203735352,99.8893203735352,55.2986544785443,5.52420541931853,7.81124591827393,26,1,0,0,1,0.290756225585937,33.7243423461914,2,1,1,131.806915283203,0,4232058752,131.889434814453,,,,,,,,,,,,,,,,,,,,,,,,,,,,,,,,,
,3874587558.69191,128.930145263672,99.8893203735352,0.000275867483570411,3.01715392204682E-8,1,2,13.0063810348511,5.00190715301142,33.890001475811,0.356871836892117,0.0530090923070803,1,6.09431307589596E-7,,,,,,,,,,,,,,,,,,,,,128.852325439453,129.007965087891,99.8893203735352,99.8893203735352,55.4158987564289,5.52466728839912,7.78918600082397,26,1,0,0,1,0.29022216796875,33.2355842590332,2,1,1,128.852325439453,0,4232058624,128.930145263672,,,,,,,,,,,,,,,,,,,,,,,,,,,,,,,,,
,3874587594.68738,125.940052032471,99.8893203735352,0.000277428180229364,3.77532713954923E-8,1,2,13.0063810348511,5.00208210094867,33.8700003921986,0.35887639521006,0.0535298027435678,1,7.8150038469388E-7,,,,,,,,,,,,,,,,,,,,,125.862159729004,126.017944335938,99.8893203735352,99.8893203735352,55.5085217359578,5.52359994275198,7.78007459640503,26,1,0,0,1,0.291061401367188,33.7243423461914,2,1,1,125.862159729004,0,4232058624,125.940052032471,,,,,,,,,,,,,,,,,,,,,,,,,,,,,,,,,
,3874587630.65779,122.945659637451,99.8893203735352,0.000279113055865216,3.56084449245209E-8,1,2,13.0063810348511,5.00207980207489,33.8700003921986,0.361087612181634,0.0536366427018745,1,6.17619838659014E-7,,,,,,,,,,,,,,,,,,,,,122.86727142334,123.024047851562,99.8893203735352,99.8893203735352,55.4792106664866,5.52400855392478,7.72165775299072,26,1,0,0,1,0.29052734375,33.7243423461914,2,1,1,122.86727142334,0,4232058656,122.945659637451,,,,,,,,,,,,,,,,,,,,,,,,,,,,,,,,,
,3874587666.64982,119.927024841309,99.8893203735352,0.000280736842737971,3.50302315474442E-8,1,2,13.0063810348511,5.00200550435269,33.8700003921986,0.363182617091356,0.0539349795687955,1,6.1148742486558E-7,,,,,,,,,,,,,,,,,,,,,119.857353210449,119.996696472168,99.8893203735352,99.8893203735352,55.3736908163905,5.52411692581529,7.70672416687012,26,1,0,0,1,0.290069580078125,34.2131004333496,2,1,1,119.857353210449,0,4232058624,119.927024841309,,,,,,,,,,,,,,,,,,,,,,,,,,,,,,,,,
,3874587702.62641,116.958499908447,99.8893203735352,0.000282343374197369,3.5519377371824E-8,1,2,13.0063810348511,5.00196924108454,33.8700003921986,0.365254214440748,0.0542638669872674,1,6.31052299157835E-7,,,,,,,,,,,,,,,,,,,,,116.874252319336,117.042747497559,99.8893203735352,99.8893203735352,55.367046973977,5.52373696363389,7.71973037719727,26,1,0,0,1,0.2899169921875,33.7243423461914,2,1,1,116.874252319336,0,4232058624,116.958499908447,,,,,,,,,,,,,,,,,,,,,,,,,,,,,,,,,
,3874587738.59561,113.937076568604,99.8893203735352,0.000283998872442391,4.47466223919809E-8,1,2,13.0063810348511,5.00190881581336,33.8499993085861,0.367385820544114,0.0546073926536246,1,6.5505556811096E-7,,,,,,,,,,,,,,,,,,,,,113.842163085938,114.03199005127,99.8893203735352,99.8893203735352,55.4143354993905,5.52412663687606,7.69362735748291,26,1,0,0,1,0.29144287109375,35.190616607666,2,1,1,113.842163085938,0,4232058624,113.937076568604,,,,,,,,,,,,,,,,,,,,,,,,,,,,,,,,,
,3874587774.58785,110.954212188721,99.8893203735352,0.000285633432652157,3.32365362514875E-8,1,2,13.0063810348511,5.00186950172323,33.8499993085861,0.369472498291194,0.0550835583530847,1,7.84381423055307E-7,,,,,,,,,,,,,,,,,,,,,110.868553161621,111.03987121582,99.8893203735352,99.8893203735352,55.2517567673905,5.52474707461226,7.64015054702759,26,1,0,0,1,0.289154052734375,34.2131004333496,2,1,1,110.868553161621,0,4232058656,110.954212188721,,,,,,,,,,,,,,,,,,,,,,,,,,,,,,,,,
,3874587810.63799,107.941352844238,99.8893203735352,0.000287220274977521,3.04038021763544E-8,1,2,13.0063810348511,5.00181980049164,33.8499993085861,0.371533607520774,0.0552955212186709,1,7.16648062401257E-7,,,,,,,,,,,,,,,,,,,,,107.870697021484,108.012008666992,99.8893203735352,99.8893203735352,55.428013998477,5.52527202345447,7.64034366607666,24,1,64,0,0,0.290298461914063,33.2355842590332,2,1,1,107.870697021484,0,4232058720,107.941352844238,,,,,,,,,,,,,,,,,,,,,,,,,,,,,,,,,
,3874587846.57243,104.973175048828,99.8893203735352,0.000288848662183564,3.05574435199753E-8,1,2,13.0063810348511,5.00176600374153,33.8499993085861,0.37364302890701,0.0555492069481835,1,6.75134292105174E-7,,,,,,,,,,,,,,,,,,,,,104.902450561523,105.043899536133,99.8893203735352,99.8893203735352,55.3830703586212,5.52480138504534,7.59727430343628,26,1,0,0,1,0.291671752929687,33.2355842590332,2,1,1,104.902450561523,0,4232058688,104.973175048828,,,,,,,,,,,,,,,,,,,,,,,,,,,,,,,,,
,3874587882.54055,101.97066116333,99.8893203735352,0.000290353963656922,3.94580004563342E-8,1,2,13.0063810348511,5.00177726675262,33.8499993085861,0.375582336122479,0.0559008741187499,1,7.26568605007457E-7,,,,,,,,,,,,,,,,,,,,,101.891418457031,102.049903869629,99.8893203735352,99.8893203735352,55.2783321370443,5.52471687949965,7.54669761657715,26,1,0,0,1,0.29144287109375,33.2355842590332,2,1,1,101.891418457031,0,4232058656,101.97066116333,,,,,,,,,,,,,,,,,,,,,,,,,,,,,,,,,
,3874587918.53423,98.9454460144043,99.8893203735352,0.000292049722075503,4.16857545080988E-8,1,2,13.0063810348511,5.0017336785191,33.8299982249737,0.377780030539931,0.0561667350826724,1,6.84494587625858E-7,,,,,,,,,,,,,,,,,,,,,98.8740844726563,99.0168075561523,99.8893203735352,99.8893203735352,55.4080824712366,5.52466090787365,7.55703115463257,26,1,0,0,1,0.290374755859375,32.7468223571777,2,1,1,98.8740844726563,0,4232058560,98.9454460144043,,,,,,,,,,,,,,,,,,,,,,,,,,,,,,,,,
,3874587954.53638,95.9756240844727,99.8893203735352,0.000293325667545012,3.70239389578484E-8,1,2,13.0063810348511,5.00222303428074,33.8299982249737,0.379493994888209,0.0563398844114932,1,6.25717866365237E-7,,,,,,,,,,,,,,,,,,,,,95.9080505371094,96.0431976318359,99.8893203735352,99.8893203735352,55.336563461727,5.52361050992344,7.51065063476563,26,1,0,0,1,0.29022216796875,33.7243423461914,2,1,1,95.9080505371094,0,4232058592,95.9756240844727,,,,,,,,,,,,,,,,,,,,,,,,,,,,,,,,,
,3874587990.52607,92.9443321228027,99.8893203735352,0.000294833139576892,3.44983017698667E-8,1,2,13.0063810348511,5.0016706889078,33.8299982249737,0.381390442705872,0.0565873588565478,1,6.03160927253966E-7,,,,,,,,,,,,,,,,,,,,,92.8791351318359,93.0095291137695,99.8893203735352,99.8893203735352,55.3084248350347,5.52616508061726,7.45018434524536,26,1,0,0,1,0.291213989257812,33.2355842590332,2,1,1,92.8791351318359,0,4232058624,92.9443321228027,,,,,,,,,,,,,,,,,,,,,,,,,,,,,,,,,
,3874588026.45796,89.9891662597656,99.8893203735352,0.000296338559129277,5.15277578434366E-8,1,2,13.0063810348511,5.00155184352705,33.8299982249737,0.383325690038156,0.0568705111371373,1,6.03228060566206E-7,,,,,,,,,,,,,,,,,,,,,89.9023590087891,90.0759735107422,99.8893203735352,99.8893203735352,55.3392991615443,5.52616063033554,7.47125101089478,26,1,0,0,1,0.2899169921875,33.7243423461914,2,1,1,89.9023590087891,0,4232058464,89.9891662597656,,,,,,,,,,,,,,,,,,,,,,,,,,,,,,,,,
,3874588062.43759,86.9795227050781,99.8893203735352,0.000297669028136241,3.58452448553197E-8,1,2,13.0063810348511,5.00145237715651,33.8100008666515,0.385001553859722,0.0573598992811901,1,7.88055255578036E-7,,,,,,,,,,,,,,,,,,,,,86.8935317993164,87.0655136108398,99.8893203735352,99.8893203735352,55.3987029290059,5.52674902240736,7.40788745880127,26,1,0,0,1,0.290985107421875,33.7243423461914,2,1,1,86.8935317993164,0,4232058560,86.9795227050781,,,,,,,,,,,,,,,,,,,,,,,,,,,,,,,,,
,3874588098.46638,83.997013092041,99.8893203735352,0.000299064284524483,3.35221695765933E-8,1,2,13.0063810348511,5.00147955732374,33.8199995458126,0.386821462468199,0.0575446435619217,1,7.26400753877596E-7,,,,,,,,,,,,,,,,,,,,,83.9101104736328,84.0839157104492,99.8893203735352,99.8893203735352,55.341644047102,5.52639372752608,7.36379051208496,26,1,0,0,1,0.291290283203125,34.2131004333496,2,1,1,83.9101104736328,0,4232058592,83.997013092041,,,,,,,,,,,,,,,,,,,,,,,,,,,,,,,,,
,3874588134.39855,80.9703102111816,99.8893203735352,0.000300231515576459,3.42364307826619E-8,1,2,13.0063810348511,5.00144884473866,33.8100008666515,0.388343845809273,0.0576595885694594,1,6.44874842268489E-7,,,,,,,,,,,,,,,,,,,,,80.8850402832031,81.0555801391602,99.8893203735352,99.8893203735352,55.3475062609962,5.52644423352698,7.37205123901367,26,1,0,0,1,0.290374755859375,34.2131004333496,2,1,1,80.8850402832031,0,4232058688,80.9703102111816,,,,,,,,,,,,,,,,,,,,,,,,,,,,,,,,,
,3874588170.38215,77.9384269714355,99.8893203735352,0.000301369228855043,2.61860974073527E-8,1,2,13.0063810348511,5.00167143792246,33.8100008666515,0.389815672664781,0.058045629475422,1,7.74021583241082E-7,,,,,,,,,,,,,,,,,,,,,77.8525009155273,78.0243530273437,99.8893203735352,99.8893203735352,55.4170711992078,5.52551634378991,7.29981708526611,26,1,0,0,1,0.291366577148438,33.7243423461914,2,1,1,77.8525009155273,0,4232058560,77.9384269714355,,,,,,,,,,,,,,,,,,,,,,,,,,,,,,,,,
,3874588206.38397,74.8901252746582,99.8893203735352,0.000302643025103575,3.08737365569999E-8,1,2,13.0063810348511,5.00162141587751,33.7999984622002,0.391464889706811,0.0582419957561477,1,7.40072338516065E-7,,,,,,,,,,,,,,,,,,,,,74.8074951171875,74.9727554321289,99.8893203735352,99.8893203735352,55.3166319344866,5.52600326210799,7.25881767272949,26,1,0,0,1,0.293807983398438,33.7243423461914,2,1,1,74.8074951171875,0,4232058688,74.8901252746582,,,,,,,,,,,,,,,,,,,,,,,,,,,,,,,,,
,3874588242.44268,71.7923622131348,99.8893203735352,0.00030350433736253,3.82582748289512E-8,1,2,13.0063810348511,5.00171134399137,33.7999984622002,0.392589892863502,0.0584019575831558,1,7.36569709747078E-7,,,,,,,,,,,,,,,,,,,,,71.7093124389648,71.8754119873047,99.8893203735352,99.8893203735352,55.4401292405251,5.52530645901361,7.26206302642822,26,1,0,0,1,0.291519165039063,33.7243423461914,2,1,1,71.7093124389648,0,4232058720,71.7923622131348,,,,,,,,,,,,,,,,,,,,,,,,,,,,,,,,,
,3874588278.33682,68.822452545166,99.8893203735352,0.000304406656531681,3.65217458543332E-8,1,2,13.0063810348511,5.00170029226528,33.7999984622002,0.393760435909321,0.0585440569862494,1,7.14532513938742E-7,,,,,,,,,,,,,,,,,,,,,68.7449645996094,68.8999404907227,99.8893203735352,99.8893203735352,55.2892749363135,5.52518905662361,7.18024349212647,26,1,0,0,1,0.290145874023438,33.7243423461914,2,1,1,68.7449645996094,0,4232058624,68.822452545166,,,,,,,,,,,,,,,,,,,,,,,,,,,,,,,,,
,3874588314.35378,65.7693710327148,99.8893203735352,0.000305010605118958,4.29237702749759E-8,1,2,13.0063810348511,5.0017535203939,33.7899997830391,0.39454074318236,0.0587074097986336,1,7.51753615105843E-7,,,,,,,,,,,,,,,,,,,,,65.6846694946289,65.8540725708008,99.8893203735352,99.8893203735352,55.4155079421693,5.52451442066978,7.16438341140747,26,1,0,0,1,0.290908813476562,33.7243423461914,2,1,1,65.6846694946289,0,4232058528,65.7693710327148,,,,,,,,,,,,,,,,,,,,,,,,,,,,,,,,,
,3874588350.44058,62.7382316589356,99.8893203735352,0.000305549635646191,4.54834856208974E-8,1,2,13.0063810348511,5.00179428504953,33.7899997830391,0.39520918437547,0.0590395034412927,1,9.29026625982801E-7,,,,,,,,,,,,,,,,,,,,,62.6845283508301,62.791934967041,99.8893203735352,99.8893203735352,55.3424256756212,5.52451967385737,7.14542531967163,25,1,64,0,0,0.289459228515625,33.2355842590332,2,1,1,62.6845283508301,0,4232058688,62.7382316589356,,,,,,,,,,,,,,,,,,,,,,,,,,,,,,,,,
,3874588386.29048,59.6784801483154,99.8893203735352,0.000306059929998677,4.27844419148838E-8,1,2,13.0063810348511,5.00172058399457,33.7899997830391,0.39586821169775,0.059088150806988,1,8.92912903670088E-7,,,,,,,,,,,,,,,,,,,,,59.6064796447754,59.7504806518555,99.8893203735352,99.8893203735352,55.3643112741597,5.52498238828852,7.05994272232056,26,1,0,0,1,0.291366577148438,33.7243423461914,2,1,1,59.6064796447754,0,4232058688,59.6784801483154,,,,,,,,,,,,,,,,,,,,,,,,,,,,,,,,,
,3874588422.27224,56.6426982879639,99.8893203735352,0.000306415328954655,4.68172673411858E-8,1,2,13.0063810348511,5.00181547840028,33.780001103878,0.396346639457773,0.0591018958305112,1,8.50338418822225E-7,,,,,,,,,,,,,,,,,,,,,56.5614547729492,56.7239418029785,99.8893203735352,99.8893203735352,55.3604031315636,5.52521404756016,7.04495859146118,26,1,0,0,1,0.290908813476562,32.7468223571777,2,1,1,56.5614547729492,0,4232058752,56.6426982879639,,,,,,,,,,,,,,,,,,,,,,,,,,,,,,,,,
,3874588458.29379,53.6307582855225,99.8893203735352,0.000306564834046203,3.71359433375697E-8,1,2,13.0063810348511,5.00162262054049,33.780001103878,0.396520313299073,0.0591165118050938,1,8.42220638380282E-7,,,,,,,,,,,,,,,,,,,,,53.5612983703613,53.7002182006836,99.8893203735352,99.8893203735352,55.3963580434482,5.52603245335359,7.00253295898438,26,1,0,0,1,0.291748046875,33.7243423461914,2,1,1,53.5612983703613,0,4232058624,53.6307582855225,,,,,,,,,,,,,,,,,,,,,,,,,,,,,,,,,
,3874588494.2696,50.5776786804199,99.8893203735352,0.000306761830792607,4.21404620308909E-8,1,2,13.0063810348511,5.00168621717318,33.780001103878,0.396781179592152,0.0591621943485399,1,8.47897590131586E-7,,,,,,,,,,,,,,,,,,,,,50.4925689697266,50.6627883911133,99.8893203735352,99.8893203735352,55.4287956269962,5.52522420357384,6.92611122131348,26,1,0,0,1,0.292129516601562,33.7243423461914,2,1,1,50.4925689697266,0,4232058688,50.5776786804199,,,,,,,,,,,,,,,,,,,,,,,,,,,,,,,,,
,3874588530.52395,47.5339832305908,99.8893203735352,0.000306882994189599,4.99273249950388E-8,1,2,13.0063810348511,5.00182266638876,33.7600000202656,0.396947589727714,0.0592248127397615,1,8.7682453742639E-7,,,,,,,,,,,,,,,,,,,,,47.4860687255859,47.5818977355957,99.8893203735352,99.8893203735352,55.3205400770828,5.52719947718258,6.91587209701538,25,1,64,0,0,0.29296875,33.2355842590332,2,1,1,47.4860687255859,0,4232058560,47.5339832305908,,,,,,,,,,,,,,,,,,,,,,,,,,,,,,,,,
,3874588566.19114,44.5110969543457,99.8893203735352,0.000306852745798462,3.91160232326691E-8,1,2,13.0063810348511,5.00173302003353,33.7600000202656,0.396905452188276,0.0591702570058531,1,8.40232575069753E-7,,,,,,,,,,,,,,,,,,,,,44.4276809692383,44.5945129394531,99.8893203735352,99.8893203735352,55.331482876352,5.52492333457837,6.83329391479492,26,1,0,0,1,0.291671752929687,34.2131004333496,2,1,1,44.4276809692383,0,4232058784,44.5110969543457,,,,,,,,,,,,,,,,,,,,,,,,,,,,,,,,,
,3874588602.17158,41.4928703308105,99.8893203735352,0.00030668959797331,3.97831675135039E-8,1,2,13.0063810348511,5.00175481247413,33.7600000202656,0.396703190713782,0.0590957129835974,1,8.06212613754784E-7,,,,,,,,,,,,,,,,,,,,,41.4068717956543,41.5788688659668,99.8893203735352,99.8893203735352,55.4370027264482,5.52489438606434,6.76104021072388,26,1,0,0,1,0.290756225585937,33.7243423461914,2,1,1,41.4068717956543,0,4232058784,41.4928703308105,,,,,,,,,,,,,,,,,,,,,,,,,,,,,,,,,
,3874588638.15565,38.4619560241699,99.8893203735352,0.000306513537880228,5.6840567180899E-8,1,2,13.0063810348511,5.00176222447469,33.7600000202656,0.396473072533944,0.0590838118712542,1,8.22675330499206E-7,,,,,,,,,,,,,,,,,,,,,38.3907012939453,38.5332107543945,99.8893203735352,99.8893203735352,55.3760357019482,5.5249211575886,6.7396559715271,26,1,0,0,1,0.291290283203125,33.2355842590332,2,1,1,38.3907012939453,0,4232058528,38.4619560241699,,,,,,,,,,,,,,,,,,,,,,,,,,,,,,,,,
,3874588674.14022,35.4285182952881,99.8893203735352,0.000306345761302177,3.33820745373879E-8,1,2,13.0063810348511,5.0017734788625,33.7600000202656,0.39622098619615,0.0592998916894655,1,1.01405987551855E-6,,,,,,,,,,,,,,,,,,,,,35.3363494873047,35.5206871032715,99.8893203735352,99.8893203735352,55.3561041747078,5.52483563230194,6.63486099243164,26,1,0,0,1,0.291366577148438,33.7243423461914,2,1,1,35.3363494873047,0,4232058752,35.4285182952881,,,,,,,,,,,,,,,,,,,,,,,,,,,,,,,,,
,3874588710.13054,32.3900661468506,99.8893203735352,0.000306158443016856,5.22362592242053E-8,1,2,13.0063810348511,5.00173622525606,33.7600000202656,0.395977405506983,0.0592438324960247,1,9.98614361026792E-7,,,,,,,,,,,,,,,,,,,,,32.3119735717773,32.4681587219238,99.8893203735352,99.8893203735352,55.4799922950059,5.52501924851924,6.562171459198,26,1,0,0,1,0.291595458984375,34.7018585205078,2,1,1,32.3119735717773,0,4232058624,32.3900661468506,,,,,,,,,,,,,,,,,,,,,,,,,,,,,,,,,
,3874588746.11941,29.3501958847046,99.8893203735352,0.000306071257594553,5.17532968625375E-8,1,2,13.0063810348511,5.00174371985231,33.7600000202656,0.39586007355027,0.059263972557129,1,1.02683650963552E-6,,,,,,,,,,,,,,,,,,,,,29.2714309692383,29.4289608001709,99.8893203735352,99.8893203735352,55.3498511465539,5.52522599498221,6.49390602111816,26,1,0,0,1,0.291748046875,33.7243423461914,2,1,1,29.2714309692383,0,4232058528,29.3501958847046,,,,,,,,,,,,,,,,,,,,,,,,,,,,,,,,,
,3874588782.0846,26.3608236312866,99.8893203735352,0.000306029982957286,5.05804087852124E-8,1,2,13.0063810348511,5.00171223878668,33.7600000202656,0.395824642343891,0.0591089863763616,1,9.13501742686439E-7,,,,,,,,,,,,,,,,,,,,,26.2676200866699,26.4540271759033,99.8893203735352,99.8893203735352,55.336563461727,5.52501530126782,6.33718490600586,26,1,0,0,1,0.29266357421875,33.7243423461914,2,1,1,26.2676200866699,0,4232713920,26.3608236312866,,,,,,,,,,,,,,,,,,,,,,,,,,,,,,,,,
,3874588818.1198,23.3400259017944,99.8893203735352,0.000305979600213832,3.999229425026E-8,1,2,13.0063810348511,5.00162821174279,33.7600000202656,0.395742189906609,0.059152649547479,1,9.55686194136255E-7,,,,,,,,,,,,,,,,,,,,,23.2630081176758,23.4170436859131,99.8893203735352,99.8893203735352,55.422933413102,5.52533306963005,6.20803117752075,26,1,0,0,1,0.2911376953125,33.7243423461914,2,1,1,23.2630081176758,0,4232058720,23.3400259017944,,,,,,,,,,,,,,,,,,,,,,,,,,,,,,,,,
,3874588854.08385,20.3638305664062,99.8893203735352,0.000305945037582019,4.92234323833493E-8,1,2,13.0063810348511,5.00160479948966,33.7399989366531,0.395704549804563,0.059079644575089,1,9.04620021363791E-7,,,,,,,,,,,,,,,,,,,,,20.2732810974121,20.4543800354004,99.8893203735352,99.8893203735352,55.290838193352,5.52596439781242,6.00747060775757,26,1,0,0,1,0.29083251953125,33.7243423461914,2,1,1,20.2732810974121,0,4232058688,20.3638305664062,,,,,,,,,,,,,,,,,,,,,,,,,,,,,,,,,
,3874588890.03472,17.3914461135864,99.8893203735352,0.000305836552839686,5.03183864985657E-8,1,2,13.0063810348511,5.0016628920135,33.7399989366531,0.395571371421123,0.0590546901294086,1,9.00464361133014E-7,,,,,,,,,,,,,,,,,,,,,17.3165645599365,17.4663276672363,99.8893203735352,99.8893203735352,55.3647020884193,5.52580912366111,5.74362373352051,26,1,0,0,1,0.292129516601562,34.2131004333496,2,1,1,17.3165645599365,0,4232058752,17.3914461135864,,,,,,,,,,,,,,,,,,,,,,,,,,,,,,,,,
,3874588926.067,14.4552721977234,99.8893203735352,0.000305762785669801,3.92720322037548E-8,1,2,13.0063810348511,5.00161895959145,33.7399989366531,0.395471801273486,0.0590350338386848,1,8.96623302303668E-7,,,,,,,,,,,,,,,,,,,,,14.3827438354492,14.5278005599976,99.8893203735352,99.8893203735352,55.3963580434482,5.52644981740054,4.86127662658691,26,1,0,0,1,0.29022216796875,33.7243423461914,2,1,1,14.3827438354492,0,4232058816,14.4552721977234,,,,,,,,,,,,,,,,,,,,,,,,,,,,,,,,,
,3874588962.01315,11.5733451843262,99.8893203735352,0.000305816622487183,5.45373738650006E-8,1,2,13.0063810348511,5.00161691760263,33.7399989366531,0.395536652254121,0.0590765403026477,1,9.20851347549719E-7,,,,,,,,,,,,,,,,,,,,,11.4960594177246,11.6506309509277,99.8893203735352,99.8893203735352,55.3740816306501,5.52643493101697,4.50228977203369,26,1,0,0,1,0.290985107421875,33.7243423461914,2,1,1,11.4960594177246,0,4232058656,11.5733451843262,,,,,,,,,,,,,,,,,,,,,,,,,,,,,,,,,
,3874588998.02364,9.12125158309937,99.8893203735352,0.00030592197712332,3.61777222016051E-8,1,2,13.0063810348511,5.00162925622903,33.7399989366531,0.395680479617292,0.059054694491367,1,8.88399864587041E-7,,,,,,,,,,,,,,,,,,,,,9.04556369781494,9.19693946838379,99.8893203735352,99.8893203735352,55.4139446851308,5.52681809773034,4.19140863418579,26,1,0,0,1,0.290451049804687,33.2355842590332,6,1,1,9.04556369781494,0,4232059296,9.12125158309937,,,,,,,,,,,,,,,,,,,,,,,,,,,,,,,,,
,3874589034.01717,6.04255747795105,99.8893203735352,0.000306014818112025,3.68707932558386E-8,1,2,13.0063810348511,5.00158231864366,33.7399989366531,0.395786444413652,0.0591329259688588,1,9.35876465822986E-7,,,,,,,,,,,,,,,,,,,,,5.95730590820312,6.12780904769897,99.8893203735352,99.8893203735352,55.4596699535059,5.5261954532238,3.83811926841736,26,1,0,0,1,0.291213989257812,34.2131004333496,6,1,1,5.95730590820312,0,4232058880,6.04255747795105,,,,,,,,,,,,,,,,,,,,,,,,,,,,,,,,,
,3874589069.97893,5.00044083595276,99.8893203735352,0.000306088226199375,4.38810023018872E-8,1,2,13.0063810348511,5.00153125417771,33.7399989366531,0.395883495699139,0.0590933161646769,1,8.95176746134169E-7,,,,,,,,,,,,,,,,,,,,,5.00007629394531,5.0008053779602,99.8893203735352,99.8893203735352,55.3475062609962,5.52661562915968,3.52936029434204,26,1,0,0,1,0.291976928710937,33.7243423461914,5,1,1,5.0008053779602,0,4232058816,5.00044083595276,,,,,,,,,,,,,,,,,,,,,,,,,,,,,,,,,
,3874589105.97503,5.00017952919006,99.8893203735352,0.000306076860546713,4.35728417359735E-8,1,2,13.0063810348511,5.00171953182121,33.7399989366531,0.395888469214809,0.0591018263210783,1,9.01018205558332E-7,,,,,,,,,,,,,,,,,,,,,5.00016832351685,5.00019073486328,99.8893203735352,99.8893203735352,55.3525868463712,5.52610580362607,3.4673810005188,26,1,0,0,1,0.290451049804687,33.7243423461914,5,1,1,5.00019073486328,0,4232058784,5.00017952919006,,,,,,,,,,,,,,,,,,,,,,,,,,,,,,,,,
,3874589109.92623,4.9999213218689,99.8893203735352,0.000306073169604522,3.96422981925462E-8,1,2,13.0063810348511,5.00167010937499,33.7399989366531,0.395869623601632,0.0591591969251066,1,9.46524573589181E-7,,,,,,,,,,,,,,,,,,,,,4.9998779296875,4.99996471405029,99.8893203735352,99.8893203735352,55.3299196193135,5.52564266411405,3.46130728721619,26,1,0,0,1,0.291900634765625,33.7243423461914,1,1,1,4.99996471405029,0,4232058784,4.9999213218689,,,,,,,,,,,,,,,,,,,,,,,,,,,,,,,,,